[30/Sep/2015 14:34:23] ERROR [django.request:231] Internal Server Error: /rest/get_next_wizard_stage/
Traceback (most recent call last):
  File "/Users/fshaw/Documents/dev/environments/copo_python3.4/lib/python3.4/site-packages/django/core/handlers/base.py", line 111, in get_response
    response = wrapped_callback(request, *callback_args, **callback_kwargs)
  File "/Users/fshaw/Dropbox/tgac_dev/prototypes/COPO/web/apps/web_copo/wizard_views.py", line 44, in get_next_wizard_stage
    out = generate_wizard_html(field_track[1])
  File "/Users/fshaw/Dropbox/tgac_dev/prototypes/COPO/web/apps/web_copo/wizard_views.py", line 76, in generate_wizard_html
    element = do_tag(field)
NameError: name 'do_tag' is not defined
[30/Sep/2015 14:34:35] DEBUG [web_copo.views:22] ['/Users/fshaw/Dropbox/tgac_dev/prototypes/COPO/web', '/Applications/PyCharm.app/Contents/helpers/pydev', '/Users/fshaw/Dropbox/tgac_dev/prototypes/COPO/web/project_copo/settings', '/Users/fshaw/Dropbox/tgac_dev/prototypes/COPO', '/Users/fshaw/Dropbox/tgac_dev/prototypes/COPO/dal', '/Users/fshaw/Dropbox/tgac_dev/prototypes/COPO/web/apps', '/Users/fshaw/Dropbox/tgac_dev/prototypes/COPO/api', '/Users/fshaw/Dropbox/tgac_dev/prototypes/COPO/web/project_copo', '/Users/fshaw/Documents/dev/environments/copo_python3.4/lib/python34.zip', '/Users/fshaw/Documents/dev/environments/copo_python3.4/lib/python3.4', '/Users/fshaw/Documents/dev/environments/copo_python3.4/lib/python3.4/plat-darwin', '/Users/fshaw/Documents/dev/environments/copo_python3.4/lib/python3.4/lib-dynload', '/Library/Frameworks/Python.framework/Versions/3.4/lib/python3.4', '/Library/Frameworks/Python.framework/Versions/3.4/lib/python3.4/plat-darwin', '/Users/fshaw/Documents/dev/environments/copo_python3.4/lib/python3.4/site-packages', '/Users/fshaw/Dropbox/tgac_dev/prototypes/COPO', '/Users/fshaw/Dropbox/tgac_dev/prototypes/COPO/api', '/Users/fshaw/Dropbox/tgac_dev/prototypes/COPO/dal', '/Users/fshaw/Dropbox/tgac_dev/prototypes/COPO/web/project_copo', '/Users/fshaw/Dropbox/tgac_dev/prototypes/COPO/web/project_copo/settings', '/Users/fshaw/Dropbox/tgac_dev/prototypes/COPO/web/apps', '/var/www/copo_www/COPO/', '/var/www/copo_www/COPO/api', '/var/www/copo_www/COPO/dal', '/var/www/copo_www/COPO/web/project_copo', '/var/www/copo_www/COPO/web/project_copo/settings', '/var/www/copo_www/COPO/web/apps']
[30/Sep/2015 14:34:35] INFO [rdflib:81] RDFLib Version: 4.2.1
[30/Sep/2015 14:37:43] DEBUG [web_copo.views:22] ['/Users/fshaw/Dropbox/tgac_dev/prototypes/COPO/web', '/Applications/PyCharm.app/Contents/helpers/pydev', '/Users/fshaw/Dropbox/tgac_dev/prototypes/COPO/web/project_copo/settings', '/Users/fshaw/Dropbox/tgac_dev/prototypes/COPO', '/Users/fshaw/Dropbox/tgac_dev/prototypes/COPO/dal', '/Users/fshaw/Dropbox/tgac_dev/prototypes/COPO/web/apps', '/Users/fshaw/Dropbox/tgac_dev/prototypes/COPO/api', '/Users/fshaw/Dropbox/tgac_dev/prototypes/COPO/web/project_copo', '/Users/fshaw/Documents/dev/environments/copo_python3.4/lib/python34.zip', '/Users/fshaw/Documents/dev/environments/copo_python3.4/lib/python3.4', '/Users/fshaw/Documents/dev/environments/copo_python3.4/lib/python3.4/plat-darwin', '/Users/fshaw/Documents/dev/environments/copo_python3.4/lib/python3.4/lib-dynload', '/Library/Frameworks/Python.framework/Versions/3.4/lib/python3.4', '/Library/Frameworks/Python.framework/Versions/3.4/lib/python3.4/plat-darwin', '/Users/fshaw/Documents/dev/environments/copo_python3.4/lib/python3.4/site-packages', '/Users/fshaw/Dropbox/tgac_dev/prototypes/COPO', '/Users/fshaw/Dropbox/tgac_dev/prototypes/COPO/api', '/Users/fshaw/Dropbox/tgac_dev/prototypes/COPO/dal', '/Users/fshaw/Dropbox/tgac_dev/prototypes/COPO/web/project_copo', '/Users/fshaw/Dropbox/tgac_dev/prototypes/COPO/web/project_copo/settings', '/Users/fshaw/Dropbox/tgac_dev/prototypes/COPO/web/apps', '/var/www/copo_www/COPO/', '/var/www/copo_www/COPO/api', '/var/www/copo_www/COPO/dal', '/var/www/copo_www/COPO/web/project_copo', '/var/www/copo_www/COPO/web/project_copo/settings', '/var/www/copo_www/COPO/web/apps']
[30/Sep/2015 14:37:43] INFO [rdflib:81] RDFLib Version: 4.2.1
[30/Sep/2015 14:43:10] DEBUG [web_copo.views:22] ['/Users/fshaw/Dropbox/tgac_dev/prototypes/COPO/web', '/Applications/PyCharm.app/Contents/helpers/pydev', '/Users/fshaw/Dropbox/tgac_dev/prototypes/COPO/web/project_copo/settings', '/Users/fshaw/Dropbox/tgac_dev/prototypes/COPO', '/Users/fshaw/Dropbox/tgac_dev/prototypes/COPO/dal', '/Users/fshaw/Dropbox/tgac_dev/prototypes/COPO/web/apps', '/Users/fshaw/Dropbox/tgac_dev/prototypes/COPO/api', '/Users/fshaw/Dropbox/tgac_dev/prototypes/COPO/web/project_copo', '/Users/fshaw/Documents/dev/environments/copo_python3.4/lib/python34.zip', '/Users/fshaw/Documents/dev/environments/copo_python3.4/lib/python3.4', '/Users/fshaw/Documents/dev/environments/copo_python3.4/lib/python3.4/plat-darwin', '/Users/fshaw/Documents/dev/environments/copo_python3.4/lib/python3.4/lib-dynload', '/Library/Frameworks/Python.framework/Versions/3.4/lib/python3.4', '/Library/Frameworks/Python.framework/Versions/3.4/lib/python3.4/plat-darwin', '/Users/fshaw/Documents/dev/environments/copo_python3.4/lib/python3.4/site-packages', '/Users/fshaw/Dropbox/tgac_dev/prototypes/COPO', '/Users/fshaw/Dropbox/tgac_dev/prototypes/COPO/api', '/Users/fshaw/Dropbox/tgac_dev/prototypes/COPO/dal', '/Users/fshaw/Dropbox/tgac_dev/prototypes/COPO/web/project_copo', '/Users/fshaw/Dropbox/tgac_dev/prototypes/COPO/web/project_copo/settings', '/Users/fshaw/Dropbox/tgac_dev/prototypes/COPO/web/apps', '/var/www/copo_www/COPO/', '/var/www/copo_www/COPO/api', '/var/www/copo_www/COPO/dal', '/var/www/copo_www/COPO/web/project_copo', '/var/www/copo_www/COPO/web/project_copo/settings', '/var/www/copo_www/COPO/web/apps']
[30/Sep/2015 14:43:10] INFO [rdflib:81] RDFLib Version: 4.2.1
[30/Sep/2015 14:58:08] ERROR [django.request:231] Internal Server Error: /rest/receive_data_file/
Traceback (most recent call last):
  File "/Users/fshaw/Documents/dev/environments/copo_python3.4/lib/python3.4/site-packages/django/core/handlers/base.py", line 111, in get_response
    response = wrapped_callback(request, *callback_args, **callback_kwargs)
  File "/Users/fshaw/Dropbox/tgac_dev/prototypes/COPO/web/apps/web_copo/rest/EnaRest.py", line 229, in receive_data_file
    chunked_upload.file.save(name='', content=ContentFile(''), save=True)
  File "/Users/fshaw/Documents/dev/environments/copo_python3.4/lib/python3.4/site-packages/django/db/models/fields/files.py", line 89, in save
    self.name = self.storage.save(name, content)
  File "/Users/fshaw/Documents/dev/environments/copo_python3.4/lib/python3.4/site-packages/django/core/files/storage.py", line 51, in save
    name = self._save(name, content)
  File "/Users/fshaw/Documents/dev/environments/copo_python3.4/lib/python3.4/site-packages/django/core/files/storage.py", line 193, in _save
    os.makedirs(directory)
  File "/Users/fshaw/Documents/dev/environments/copo_python3.4/bin/../lib/python3.4/os.py", line 227, in makedirs
    makedirs(head, mode, exist_ok)
  File "/Users/fshaw/Documents/dev/environments/copo_python3.4/bin/../lib/python3.4/os.py", line 227, in makedirs
    makedirs(head, mode, exist_ok)
  File "/Users/fshaw/Documents/dev/environments/copo_python3.4/bin/../lib/python3.4/os.py", line 227, in makedirs
    makedirs(head, mode, exist_ok)
  File "/Users/fshaw/Documents/dev/environments/copo_python3.4/bin/../lib/python3.4/os.py", line 227, in makedirs
    makedirs(head, mode, exist_ok)
  File "/Users/fshaw/Documents/dev/environments/copo_python3.4/bin/../lib/python3.4/os.py", line 237, in makedirs
    mkdir(name, mode)
PermissionError: [Errno 13] Permission denied: '/Users/etuka/Desktop/copo_uploads'
[30/Sep/2015 15:00:43] DEBUG [web_copo.views:22] ['/Users/fshaw/Dropbox/tgac_dev/prototypes/COPO/web', '/Applications/PyCharm.app/Contents/helpers/pydev', '/Users/fshaw/Dropbox/tgac_dev/prototypes/COPO/web/project_copo/settings', '/Users/fshaw/Dropbox/tgac_dev/prototypes/COPO', '/Users/fshaw/Dropbox/tgac_dev/prototypes/COPO/dal', '/Users/fshaw/Dropbox/tgac_dev/prototypes/COPO/web/apps', '/Users/fshaw/Dropbox/tgac_dev/prototypes/COPO/api', '/Users/fshaw/Dropbox/tgac_dev/prototypes/COPO/web/project_copo', '/Users/fshaw/Documents/dev/environments/copo_python3.4/lib/python34.zip', '/Users/fshaw/Documents/dev/environments/copo_python3.4/lib/python3.4', '/Users/fshaw/Documents/dev/environments/copo_python3.4/lib/python3.4/plat-darwin', '/Users/fshaw/Documents/dev/environments/copo_python3.4/lib/python3.4/lib-dynload', '/Library/Frameworks/Python.framework/Versions/3.4/lib/python3.4', '/Library/Frameworks/Python.framework/Versions/3.4/lib/python3.4/plat-darwin', '/Users/fshaw/Documents/dev/environments/copo_python3.4/lib/python3.4/site-packages', '/Users/fshaw/Dropbox/tgac_dev/prototypes/COPO', '/Users/fshaw/Dropbox/tgac_dev/prototypes/COPO/api', '/Users/fshaw/Dropbox/tgac_dev/prototypes/COPO/dal', '/Users/fshaw/Dropbox/tgac_dev/prototypes/COPO/web/project_copo', '/Users/fshaw/Dropbox/tgac_dev/prototypes/COPO/web/project_copo/settings', '/Users/fshaw/Dropbox/tgac_dev/prototypes/COPO/web/apps', '/var/www/copo_www/COPO/', '/var/www/copo_www/COPO/api', '/var/www/copo_www/COPO/dal', '/var/www/copo_www/COPO/web/project_copo', '/var/www/copo_www/COPO/web/project_copo/settings', '/var/www/copo_www/COPO/web/apps']
[30/Sep/2015 15:00:43] INFO [rdflib:81] RDFLib Version: 4.2.1
[30/Sep/2015 15:00:43] ERROR [django.request:231] Internal Server Error: /rest/get_next_wizard_stage/
Traceback (most recent call last):
  File "/Users/fshaw/Documents/dev/environments/copo_python3.4/lib/python3.4/site-packages/django/core/handlers/base.py", line 98, in get_response
    resolver_match = resolver.resolve(request.path_info)
  File "/Users/fshaw/Documents/dev/environments/copo_python3.4/lib/python3.4/site-packages/django/core/urlresolvers.py", line 343, in resolve
    for pattern in self.url_patterns:
  File "/Users/fshaw/Documents/dev/environments/copo_python3.4/lib/python3.4/site-packages/django/core/urlresolvers.py", line 372, in url_patterns
    patterns = getattr(self.urlconf_module, "urlpatterns", self.urlconf_module)
  File "/Users/fshaw/Documents/dev/environments/copo_python3.4/lib/python3.4/site-packages/django/core/urlresolvers.py", line 366, in urlconf_module
    self._urlconf_module = import_module(self.urlconf_name)
  File "/Users/fshaw/Documents/dev/environments/copo_python3.4/lib/python3.4/importlib/__init__.py", line 109, in import_module
    return _bootstrap._gcd_import(name[level:], package, level)
  File "<frozen importlib._bootstrap>", line 2254, in _gcd_import
  File "<frozen importlib._bootstrap>", line 2237, in _find_and_load
  File "<frozen importlib._bootstrap>", line 2226, in _find_and_load_unlocked
  File "<frozen importlib._bootstrap>", line 1200, in _load_unlocked
  File "<frozen importlib._bootstrap>", line 1129, in _exec
  File "<frozen importlib._bootstrap>", line 1471, in exec_module
  File "<frozen importlib._bootstrap>", line 321, in _call_with_frames_removed
  File "/Users/fshaw/Dropbox/tgac_dev/prototypes/COPO/web/project_copo/urls.py", line 12, in <module>
    url(r'^rest/', include('web_copo.rest_urls', namespace='rest')),
  File "/Users/fshaw/Documents/dev/environments/copo_python3.4/lib/python3.4/site-packages/django/conf/urls/__init__.py", line 28, in include
    urlconf_module = import_module(urlconf_module)
  File "/Users/fshaw/Documents/dev/environments/copo_python3.4/lib/python3.4/importlib/__init__.py", line 109, in import_module
    return _bootstrap._gcd_import(name[level:], package, level)
  File "<frozen importlib._bootstrap>", line 2254, in _gcd_import
  File "<frozen importlib._bootstrap>", line 2237, in _find_and_load
  File "<frozen importlib._bootstrap>", line 2226, in _find_and_load_unlocked
  File "<frozen importlib._bootstrap>", line 1200, in _load_unlocked
  File "<frozen importlib._bootstrap>", line 1129, in _exec
  File "<frozen importlib._bootstrap>", line 1471, in exec_module
  File "<frozen importlib._bootstrap>", line 321, in _call_with_frames_removed
  File "/Users/fshaw/Dropbox/tgac_dev/prototypes/COPO/web/apps/web_copo/rest_urls.py", line 5, in <module>
    import web.apps.web_copo.wizard_views as wizard
  File "/Users/fshaw/Dropbox/tgac_dev/prototypes/COPO/web/apps/web_copo/wizard_views.py", line 65
    element =  generate_ena_tags_2(field['id'])
                                              ^
IndentationError: unindent does not match any outer indentation level
[30/Sep/2015 15:00:44] ERROR [django.request:231] Internal Server Error: /rest/get_next_wizard_stage/
Traceback (most recent call last):
  File "/Users/fshaw/Documents/dev/environments/copo_python3.4/lib/python3.4/site-packages/django/core/urlresolvers.py", line 364, in urlconf_module
    return self._urlconf_module
AttributeError: 'RegexURLResolver' object has no attribute '_urlconf_module'

During handling of the above exception, another exception occurred:

Traceback (most recent call last):
  File "/Users/fshaw/Documents/dev/environments/copo_python3.4/lib/python3.4/site-packages/django/core/handlers/base.py", line 98, in get_response
    resolver_match = resolver.resolve(request.path_info)
  File "/Users/fshaw/Documents/dev/environments/copo_python3.4/lib/python3.4/site-packages/django/core/urlresolvers.py", line 343, in resolve
    for pattern in self.url_patterns:
  File "/Users/fshaw/Documents/dev/environments/copo_python3.4/lib/python3.4/site-packages/django/core/urlresolvers.py", line 372, in url_patterns
    patterns = getattr(self.urlconf_module, "urlpatterns", self.urlconf_module)
  File "/Users/fshaw/Documents/dev/environments/copo_python3.4/lib/python3.4/site-packages/django/core/urlresolvers.py", line 366, in urlconf_module
    self._urlconf_module = import_module(self.urlconf_name)
  File "/Users/fshaw/Documents/dev/environments/copo_python3.4/lib/python3.4/importlib/__init__.py", line 109, in import_module
    return _bootstrap._gcd_import(name[level:], package, level)
  File "<frozen importlib._bootstrap>", line 2254, in _gcd_import
  File "<frozen importlib._bootstrap>", line 2237, in _find_and_load
  File "<frozen importlib._bootstrap>", line 2226, in _find_and_load_unlocked
  File "<frozen importlib._bootstrap>", line 1200, in _load_unlocked
  File "<frozen importlib._bootstrap>", line 1129, in _exec
  File "<frozen importlib._bootstrap>", line 1471, in exec_module
  File "<frozen importlib._bootstrap>", line 321, in _call_with_frames_removed
  File "/Users/fshaw/Dropbox/tgac_dev/prototypes/COPO/web/project_copo/urls.py", line 12, in <module>
    url(r'^rest/', include('web_copo.rest_urls', namespace='rest')),
  File "/Users/fshaw/Documents/dev/environments/copo_python3.4/lib/python3.4/site-packages/django/conf/urls/__init__.py", line 28, in include
    urlconf_module = import_module(urlconf_module)
  File "/Users/fshaw/Documents/dev/environments/copo_python3.4/lib/python3.4/importlib/__init__.py", line 109, in import_module
    return _bootstrap._gcd_import(name[level:], package, level)
  File "<frozen importlib._bootstrap>", line 2254, in _gcd_import
  File "<frozen importlib._bootstrap>", line 2237, in _find_and_load
  File "<frozen importlib._bootstrap>", line 2226, in _find_and_load_unlocked
  File "<frozen importlib._bootstrap>", line 1200, in _load_unlocked
  File "<frozen importlib._bootstrap>", line 1129, in _exec
  File "<frozen importlib._bootstrap>", line 1471, in exec_module
  File "<frozen importlib._bootstrap>", line 321, in _call_with_frames_removed
  File "/Users/fshaw/Dropbox/tgac_dev/prototypes/COPO/web/apps/web_copo/rest_urls.py", line 5, in <module>
    import web.apps.web_copo.wizard_views as wizard
  File "/Users/fshaw/Dropbox/tgac_dev/prototypes/COPO/web/apps/web_copo/wizard_views.py", line 65
    element =  generate_ena_tags_2(field['id'])
                                              ^
IndentationError: unindent does not match any outer indentation level
[30/Sep/2015 15:00:46] ERROR [django.request:231] Internal Server Error: /rest/get_next_wizard_stage/
Traceback (most recent call last):
  File "/Users/fshaw/Documents/dev/environments/copo_python3.4/lib/python3.4/site-packages/django/core/urlresolvers.py", line 364, in urlconf_module
    return self._urlconf_module
AttributeError: 'RegexURLResolver' object has no attribute '_urlconf_module'

During handling of the above exception, another exception occurred:

Traceback (most recent call last):
  File "/Users/fshaw/Documents/dev/environments/copo_python3.4/lib/python3.4/site-packages/django/core/handlers/base.py", line 98, in get_response
    resolver_match = resolver.resolve(request.path_info)
  File "/Users/fshaw/Documents/dev/environments/copo_python3.4/lib/python3.4/site-packages/django/core/urlresolvers.py", line 343, in resolve
    for pattern in self.url_patterns:
  File "/Users/fshaw/Documents/dev/environments/copo_python3.4/lib/python3.4/site-packages/django/core/urlresolvers.py", line 372, in url_patterns
    patterns = getattr(self.urlconf_module, "urlpatterns", self.urlconf_module)
  File "/Users/fshaw/Documents/dev/environments/copo_python3.4/lib/python3.4/site-packages/django/core/urlresolvers.py", line 366, in urlconf_module
    self._urlconf_module = import_module(self.urlconf_name)
  File "/Users/fshaw/Documents/dev/environments/copo_python3.4/lib/python3.4/importlib/__init__.py", line 109, in import_module
    return _bootstrap._gcd_import(name[level:], package, level)
  File "<frozen importlib._bootstrap>", line 2254, in _gcd_import
  File "<frozen importlib._bootstrap>", line 2237, in _find_and_load
  File "<frozen importlib._bootstrap>", line 2226, in _find_and_load_unlocked
  File "<frozen importlib._bootstrap>", line 1200, in _load_unlocked
  File "<frozen importlib._bootstrap>", line 1129, in _exec
  File "<frozen importlib._bootstrap>", line 1471, in exec_module
  File "<frozen importlib._bootstrap>", line 321, in _call_with_frames_removed
  File "/Users/fshaw/Dropbox/tgac_dev/prototypes/COPO/web/project_copo/urls.py", line 12, in <module>
    url(r'^rest/', include('web_copo.rest_urls', namespace='rest')),
  File "/Users/fshaw/Documents/dev/environments/copo_python3.4/lib/python3.4/site-packages/django/conf/urls/__init__.py", line 28, in include
    urlconf_module = import_module(urlconf_module)
  File "/Users/fshaw/Documents/dev/environments/copo_python3.4/lib/python3.4/importlib/__init__.py", line 109, in import_module
    return _bootstrap._gcd_import(name[level:], package, level)
  File "<frozen importlib._bootstrap>", line 2254, in _gcd_import
  File "<frozen importlib._bootstrap>", line 2237, in _find_and_load
  File "<frozen importlib._bootstrap>", line 2226, in _find_and_load_unlocked
  File "<frozen importlib._bootstrap>", line 1200, in _load_unlocked
  File "<frozen importlib._bootstrap>", line 1129, in _exec
  File "<frozen importlib._bootstrap>", line 1471, in exec_module
  File "<frozen importlib._bootstrap>", line 321, in _call_with_frames_removed
  File "/Users/fshaw/Dropbox/tgac_dev/prototypes/COPO/web/apps/web_copo/rest_urls.py", line 5, in <module>
    import web.apps.web_copo.wizard_views as wizard
  File "/Users/fshaw/Dropbox/tgac_dev/prototypes/COPO/web/apps/web_copo/wizard_views.py", line 65
    element =  generate_ena_tags_2(field['id'])
                                              ^
IndentationError: unindent does not match any outer indentation level
[30/Sep/2015 15:00:46] ERROR [django.request:231] Internal Server Error: /rest/get_next_wizard_stage/
Traceback (most recent call last):
  File "/Users/fshaw/Documents/dev/environments/copo_python3.4/lib/python3.4/site-packages/django/core/urlresolvers.py", line 364, in urlconf_module
    return self._urlconf_module
AttributeError: 'RegexURLResolver' object has no attribute '_urlconf_module'

During handling of the above exception, another exception occurred:

Traceback (most recent call last):
  File "/Users/fshaw/Documents/dev/environments/copo_python3.4/lib/python3.4/site-packages/django/core/handlers/base.py", line 98, in get_response
    resolver_match = resolver.resolve(request.path_info)
  File "/Users/fshaw/Documents/dev/environments/copo_python3.4/lib/python3.4/site-packages/django/core/urlresolvers.py", line 343, in resolve
    for pattern in self.url_patterns:
  File "/Users/fshaw/Documents/dev/environments/copo_python3.4/lib/python3.4/site-packages/django/core/urlresolvers.py", line 372, in url_patterns
    patterns = getattr(self.urlconf_module, "urlpatterns", self.urlconf_module)
  File "/Users/fshaw/Documents/dev/environments/copo_python3.4/lib/python3.4/site-packages/django/core/urlresolvers.py", line 366, in urlconf_module
    self._urlconf_module = import_module(self.urlconf_name)
  File "/Users/fshaw/Documents/dev/environments/copo_python3.4/lib/python3.4/importlib/__init__.py", line 109, in import_module
    return _bootstrap._gcd_import(name[level:], package, level)
  File "<frozen importlib._bootstrap>", line 2254, in _gcd_import
  File "<frozen importlib._bootstrap>", line 2237, in _find_and_load
  File "<frozen importlib._bootstrap>", line 2226, in _find_and_load_unlocked
  File "<frozen importlib._bootstrap>", line 1200, in _load_unlocked
  File "<frozen importlib._bootstrap>", line 1129, in _exec
  File "<frozen importlib._bootstrap>", line 1471, in exec_module
  File "<frozen importlib._bootstrap>", line 321, in _call_with_frames_removed
  File "/Users/fshaw/Dropbox/tgac_dev/prototypes/COPO/web/project_copo/urls.py", line 12, in <module>
    url(r'^rest/', include('web_copo.rest_urls', namespace='rest')),
  File "/Users/fshaw/Documents/dev/environments/copo_python3.4/lib/python3.4/site-packages/django/conf/urls/__init__.py", line 28, in include
    urlconf_module = import_module(urlconf_module)
  File "/Users/fshaw/Documents/dev/environments/copo_python3.4/lib/python3.4/importlib/__init__.py", line 109, in import_module
    return _bootstrap._gcd_import(name[level:], package, level)
  File "<frozen importlib._bootstrap>", line 2254, in _gcd_import
  File "<frozen importlib._bootstrap>", line 2237, in _find_and_load
  File "<frozen importlib._bootstrap>", line 2226, in _find_and_load_unlocked
  File "<frozen importlib._bootstrap>", line 1200, in _load_unlocked
  File "<frozen importlib._bootstrap>", line 1129, in _exec
  File "<frozen importlib._bootstrap>", line 1471, in exec_module
  File "<frozen importlib._bootstrap>", line 321, in _call_with_frames_removed
  File "/Users/fshaw/Dropbox/tgac_dev/prototypes/COPO/web/apps/web_copo/rest_urls.py", line 5, in <module>
    import web.apps.web_copo.wizard_views as wizard
  File "/Users/fshaw/Dropbox/tgac_dev/prototypes/COPO/web/apps/web_copo/wizard_views.py", line 65
    element =  generate_ena_tags_2(field['id'])
                                              ^
IndentationError: unindent does not match any outer indentation level
[30/Sep/2015 15:00:47] ERROR [django.request:231] Internal Server Error: /rest/get_next_wizard_stage/
Traceback (most recent call last):
  File "/Users/fshaw/Documents/dev/environments/copo_python3.4/lib/python3.4/site-packages/django/core/urlresolvers.py", line 364, in urlconf_module
    return self._urlconf_module
AttributeError: 'RegexURLResolver' object has no attribute '_urlconf_module'

During handling of the above exception, another exception occurred:

Traceback (most recent call last):
  File "/Users/fshaw/Documents/dev/environments/copo_python3.4/lib/python3.4/site-packages/django/core/handlers/base.py", line 98, in get_response
    resolver_match = resolver.resolve(request.path_info)
  File "/Users/fshaw/Documents/dev/environments/copo_python3.4/lib/python3.4/site-packages/django/core/urlresolvers.py", line 343, in resolve
    for pattern in self.url_patterns:
  File "/Users/fshaw/Documents/dev/environments/copo_python3.4/lib/python3.4/site-packages/django/core/urlresolvers.py", line 372, in url_patterns
    patterns = getattr(self.urlconf_module, "urlpatterns", self.urlconf_module)
  File "/Users/fshaw/Documents/dev/environments/copo_python3.4/lib/python3.4/site-packages/django/core/urlresolvers.py", line 366, in urlconf_module
    self._urlconf_module = import_module(self.urlconf_name)
  File "/Users/fshaw/Documents/dev/environments/copo_python3.4/lib/python3.4/importlib/__init__.py", line 109, in import_module
    return _bootstrap._gcd_import(name[level:], package, level)
  File "<frozen importlib._bootstrap>", line 2254, in _gcd_import
  File "<frozen importlib._bootstrap>", line 2237, in _find_and_load
  File "<frozen importlib._bootstrap>", line 2226, in _find_and_load_unlocked
  File "<frozen importlib._bootstrap>", line 1200, in _load_unlocked
  File "<frozen importlib._bootstrap>", line 1129, in _exec
  File "<frozen importlib._bootstrap>", line 1471, in exec_module
  File "<frozen importlib._bootstrap>", line 321, in _call_with_frames_removed
  File "/Users/fshaw/Dropbox/tgac_dev/prototypes/COPO/web/project_copo/urls.py", line 12, in <module>
    url(r'^rest/', include('web_copo.rest_urls', namespace='rest')),
  File "/Users/fshaw/Documents/dev/environments/copo_python3.4/lib/python3.4/site-packages/django/conf/urls/__init__.py", line 28, in include
    urlconf_module = import_module(urlconf_module)
  File "/Users/fshaw/Documents/dev/environments/copo_python3.4/lib/python3.4/importlib/__init__.py", line 109, in import_module
    return _bootstrap._gcd_import(name[level:], package, level)
  File "<frozen importlib._bootstrap>", line 2254, in _gcd_import
  File "<frozen importlib._bootstrap>", line 2237, in _find_and_load
  File "<frozen importlib._bootstrap>", line 2226, in _find_and_load_unlocked
  File "<frozen importlib._bootstrap>", line 1200, in _load_unlocked
  File "<frozen importlib._bootstrap>", line 1129, in _exec
  File "<frozen importlib._bootstrap>", line 1471, in exec_module
  File "<frozen importlib._bootstrap>", line 321, in _call_with_frames_removed
  File "/Users/fshaw/Dropbox/tgac_dev/prototypes/COPO/web/apps/web_copo/rest_urls.py", line 5, in <module>
    import web.apps.web_copo.wizard_views as wizard
  File "/Users/fshaw/Dropbox/tgac_dev/prototypes/COPO/web/apps/web_copo/wizard_views.py", line 65
    element =  generate_ena_tags_2(field['id'])
                                              ^
IndentationError: unindent does not match any outer indentation level
[30/Sep/2015 15:00:47] ERROR [django.request:231] Internal Server Error: /rest/get_next_wizard_stage/
Traceback (most recent call last):
  File "/Users/fshaw/Documents/dev/environments/copo_python3.4/lib/python3.4/site-packages/django/core/urlresolvers.py", line 364, in urlconf_module
    return self._urlconf_module
AttributeError: 'RegexURLResolver' object has no attribute '_urlconf_module'

During handling of the above exception, another exception occurred:

Traceback (most recent call last):
  File "/Users/fshaw/Documents/dev/environments/copo_python3.4/lib/python3.4/site-packages/django/core/handlers/base.py", line 98, in get_response
    resolver_match = resolver.resolve(request.path_info)
  File "/Users/fshaw/Documents/dev/environments/copo_python3.4/lib/python3.4/site-packages/django/core/urlresolvers.py", line 343, in resolve
    for pattern in self.url_patterns:
  File "/Users/fshaw/Documents/dev/environments/copo_python3.4/lib/python3.4/site-packages/django/core/urlresolvers.py", line 372, in url_patterns
    patterns = getattr(self.urlconf_module, "urlpatterns", self.urlconf_module)
  File "/Users/fshaw/Documents/dev/environments/copo_python3.4/lib/python3.4/site-packages/django/core/urlresolvers.py", line 366, in urlconf_module
    self._urlconf_module = import_module(self.urlconf_name)
  File "/Users/fshaw/Documents/dev/environments/copo_python3.4/lib/python3.4/importlib/__init__.py", line 109, in import_module
    return _bootstrap._gcd_import(name[level:], package, level)
  File "<frozen importlib._bootstrap>", line 2254, in _gcd_import
  File "<frozen importlib._bootstrap>", line 2237, in _find_and_load
  File "<frozen importlib._bootstrap>", line 2226, in _find_and_load_unlocked
  File "<frozen importlib._bootstrap>", line 1200, in _load_unlocked
  File "<frozen importlib._bootstrap>", line 1129, in _exec
  File "<frozen importlib._bootstrap>", line 1471, in exec_module
  File "<frozen importlib._bootstrap>", line 321, in _call_with_frames_removed
  File "/Users/fshaw/Dropbox/tgac_dev/prototypes/COPO/web/project_copo/urls.py", line 12, in <module>
    url(r'^rest/', include('web_copo.rest_urls', namespace='rest')),
  File "/Users/fshaw/Documents/dev/environments/copo_python3.4/lib/python3.4/site-packages/django/conf/urls/__init__.py", line 28, in include
    urlconf_module = import_module(urlconf_module)
  File "/Users/fshaw/Documents/dev/environments/copo_python3.4/lib/python3.4/importlib/__init__.py", line 109, in import_module
    return _bootstrap._gcd_import(name[level:], package, level)
  File "<frozen importlib._bootstrap>", line 2254, in _gcd_import
  File "<frozen importlib._bootstrap>", line 2237, in _find_and_load
  File "<frozen importlib._bootstrap>", line 2226, in _find_and_load_unlocked
  File "<frozen importlib._bootstrap>", line 1200, in _load_unlocked
  File "<frozen importlib._bootstrap>", line 1129, in _exec
  File "<frozen importlib._bootstrap>", line 1471, in exec_module
  File "<frozen importlib._bootstrap>", line 321, in _call_with_frames_removed
  File "/Users/fshaw/Dropbox/tgac_dev/prototypes/COPO/web/apps/web_copo/rest_urls.py", line 5, in <module>
    import web.apps.web_copo.wizard_views as wizard
  File "/Users/fshaw/Dropbox/tgac_dev/prototypes/COPO/web/apps/web_copo/wizard_views.py", line 65
    element =  generate_ena_tags_2(field['id'])
                                              ^
IndentationError: unindent does not match any outer indentation level
[30/Sep/2015 15:00:47] ERROR [django.request:231] Internal Server Error: /rest/get_next_wizard_stage/
Traceback (most recent call last):
  File "/Users/fshaw/Documents/dev/environments/copo_python3.4/lib/python3.4/site-packages/django/core/urlresolvers.py", line 364, in urlconf_module
    return self._urlconf_module
AttributeError: 'RegexURLResolver' object has no attribute '_urlconf_module'

During handling of the above exception, another exception occurred:

Traceback (most recent call last):
  File "/Users/fshaw/Documents/dev/environments/copo_python3.4/lib/python3.4/site-packages/django/core/handlers/base.py", line 98, in get_response
    resolver_match = resolver.resolve(request.path_info)
  File "/Users/fshaw/Documents/dev/environments/copo_python3.4/lib/python3.4/site-packages/django/core/urlresolvers.py", line 343, in resolve
    for pattern in self.url_patterns:
  File "/Users/fshaw/Documents/dev/environments/copo_python3.4/lib/python3.4/site-packages/django/core/urlresolvers.py", line 372, in url_patterns
    patterns = getattr(self.urlconf_module, "urlpatterns", self.urlconf_module)
  File "/Users/fshaw/Documents/dev/environments/copo_python3.4/lib/python3.4/site-packages/django/core/urlresolvers.py", line 366, in urlconf_module
    self._urlconf_module = import_module(self.urlconf_name)
  File "/Users/fshaw/Documents/dev/environments/copo_python3.4/lib/python3.4/importlib/__init__.py", line 109, in import_module
    return _bootstrap._gcd_import(name[level:], package, level)
  File "<frozen importlib._bootstrap>", line 2254, in _gcd_import
  File "<frozen importlib._bootstrap>", line 2237, in _find_and_load
  File "<frozen importlib._bootstrap>", line 2226, in _find_and_load_unlocked
  File "<frozen importlib._bootstrap>", line 1200, in _load_unlocked
  File "<frozen importlib._bootstrap>", line 1129, in _exec
  File "<frozen importlib._bootstrap>", line 1471, in exec_module
  File "<frozen importlib._bootstrap>", line 321, in _call_with_frames_removed
  File "/Users/fshaw/Dropbox/tgac_dev/prototypes/COPO/web/project_copo/urls.py", line 12, in <module>
    url(r'^rest/', include('web_copo.rest_urls', namespace='rest')),
  File "/Users/fshaw/Documents/dev/environments/copo_python3.4/lib/python3.4/site-packages/django/conf/urls/__init__.py", line 28, in include
    urlconf_module = import_module(urlconf_module)
  File "/Users/fshaw/Documents/dev/environments/copo_python3.4/lib/python3.4/importlib/__init__.py", line 109, in import_module
    return _bootstrap._gcd_import(name[level:], package, level)
  File "<frozen importlib._bootstrap>", line 2254, in _gcd_import
  File "<frozen importlib._bootstrap>", line 2237, in _find_and_load
  File "<frozen importlib._bootstrap>", line 2226, in _find_and_load_unlocked
  File "<frozen importlib._bootstrap>", line 1200, in _load_unlocked
  File "<frozen importlib._bootstrap>", line 1129, in _exec
  File "<frozen importlib._bootstrap>", line 1471, in exec_module
  File "<frozen importlib._bootstrap>", line 321, in _call_with_frames_removed
  File "/Users/fshaw/Dropbox/tgac_dev/prototypes/COPO/web/apps/web_copo/rest_urls.py", line 5, in <module>
    import web.apps.web_copo.wizard_views as wizard
  File "/Users/fshaw/Dropbox/tgac_dev/prototypes/COPO/web/apps/web_copo/wizard_views.py", line 65
    element =  generate_ena_tags_2(field['id'])
                                              ^
IndentationError: unindent does not match any outer indentation level
[30/Sep/2015 15:00:51] ERROR [django.request:231] Internal Server Error: /rest/get_next_wizard_stage/
Traceback (most recent call last):
  File "/Users/fshaw/Documents/dev/environments/copo_python3.4/lib/python3.4/site-packages/django/core/urlresolvers.py", line 364, in urlconf_module
    return self._urlconf_module
AttributeError: 'RegexURLResolver' object has no attribute '_urlconf_module'

During handling of the above exception, another exception occurred:

Traceback (most recent call last):
  File "/Users/fshaw/Documents/dev/environments/copo_python3.4/lib/python3.4/site-packages/django/core/handlers/base.py", line 98, in get_response
    resolver_match = resolver.resolve(request.path_info)
  File "/Users/fshaw/Documents/dev/environments/copo_python3.4/lib/python3.4/site-packages/django/core/urlresolvers.py", line 343, in resolve
    for pattern in self.url_patterns:
  File "/Users/fshaw/Documents/dev/environments/copo_python3.4/lib/python3.4/site-packages/django/core/urlresolvers.py", line 372, in url_patterns
    patterns = getattr(self.urlconf_module, "urlpatterns", self.urlconf_module)
  File "/Users/fshaw/Documents/dev/environments/copo_python3.4/lib/python3.4/site-packages/django/core/urlresolvers.py", line 366, in urlconf_module
    self._urlconf_module = import_module(self.urlconf_name)
  File "/Users/fshaw/Documents/dev/environments/copo_python3.4/lib/python3.4/importlib/__init__.py", line 109, in import_module
    return _bootstrap._gcd_import(name[level:], package, level)
  File "<frozen importlib._bootstrap>", line 2254, in _gcd_import
  File "<frozen importlib._bootstrap>", line 2237, in _find_and_load
  File "<frozen importlib._bootstrap>", line 2226, in _find_and_load_unlocked
  File "<frozen importlib._bootstrap>", line 1200, in _load_unlocked
  File "<frozen importlib._bootstrap>", line 1129, in _exec
  File "<frozen importlib._bootstrap>", line 1471, in exec_module
  File "<frozen importlib._bootstrap>", line 321, in _call_with_frames_removed
  File "/Users/fshaw/Dropbox/tgac_dev/prototypes/COPO/web/project_copo/urls.py", line 12, in <module>
    url(r'^rest/', include('web_copo.rest_urls', namespace='rest')),
  File "/Users/fshaw/Documents/dev/environments/copo_python3.4/lib/python3.4/site-packages/django/conf/urls/__init__.py", line 28, in include
    urlconf_module = import_module(urlconf_module)
  File "/Users/fshaw/Documents/dev/environments/copo_python3.4/lib/python3.4/importlib/__init__.py", line 109, in import_module
    return _bootstrap._gcd_import(name[level:], package, level)
  File "<frozen importlib._bootstrap>", line 2254, in _gcd_import
  File "<frozen importlib._bootstrap>", line 2237, in _find_and_load
  File "<frozen importlib._bootstrap>", line 2226, in _find_and_load_unlocked
  File "<frozen importlib._bootstrap>", line 1200, in _load_unlocked
  File "<frozen importlib._bootstrap>", line 1129, in _exec
  File "<frozen importlib._bootstrap>", line 1471, in exec_module
  File "<frozen importlib._bootstrap>", line 321, in _call_with_frames_removed
  File "/Users/fshaw/Dropbox/tgac_dev/prototypes/COPO/web/apps/web_copo/rest_urls.py", line 5, in <module>
    import web.apps.web_copo.wizard_views as wizard
  File "/Users/fshaw/Dropbox/tgac_dev/prototypes/COPO/web/apps/web_copo/wizard_views.py", line 65
    element =  generate_ena_tags_2(field['id'])
                                              ^
IndentationError: unindent does not match any outer indentation level
[30/Sep/2015 15:00:51] ERROR [django.request:231] Internal Server Error: /rest/get_next_wizard_stage/
Traceback (most recent call last):
  File "/Users/fshaw/Documents/dev/environments/copo_python3.4/lib/python3.4/site-packages/django/core/urlresolvers.py", line 364, in urlconf_module
    return self._urlconf_module
AttributeError: 'RegexURLResolver' object has no attribute '_urlconf_module'

During handling of the above exception, another exception occurred:

Traceback (most recent call last):
  File "/Users/fshaw/Documents/dev/environments/copo_python3.4/lib/python3.4/site-packages/django/core/handlers/base.py", line 98, in get_response
    resolver_match = resolver.resolve(request.path_info)
  File "/Users/fshaw/Documents/dev/environments/copo_python3.4/lib/python3.4/site-packages/django/core/urlresolvers.py", line 343, in resolve
    for pattern in self.url_patterns:
  File "/Users/fshaw/Documents/dev/environments/copo_python3.4/lib/python3.4/site-packages/django/core/urlresolvers.py", line 372, in url_patterns
    patterns = getattr(self.urlconf_module, "urlpatterns", self.urlconf_module)
  File "/Users/fshaw/Documents/dev/environments/copo_python3.4/lib/python3.4/site-packages/django/core/urlresolvers.py", line 366, in urlconf_module
    self._urlconf_module = import_module(self.urlconf_name)
  File "/Users/fshaw/Documents/dev/environments/copo_python3.4/lib/python3.4/importlib/__init__.py", line 109, in import_module
    return _bootstrap._gcd_import(name[level:], package, level)
  File "<frozen importlib._bootstrap>", line 2254, in _gcd_import
  File "<frozen importlib._bootstrap>", line 2237, in _find_and_load
  File "<frozen importlib._bootstrap>", line 2226, in _find_and_load_unlocked
  File "<frozen importlib._bootstrap>", line 1200, in _load_unlocked
  File "<frozen importlib._bootstrap>", line 1129, in _exec
  File "<frozen importlib._bootstrap>", line 1471, in exec_module
  File "<frozen importlib._bootstrap>", line 321, in _call_with_frames_removed
  File "/Users/fshaw/Dropbox/tgac_dev/prototypes/COPO/web/project_copo/urls.py", line 12, in <module>
    url(r'^rest/', include('web_copo.rest_urls', namespace='rest')),
  File "/Users/fshaw/Documents/dev/environments/copo_python3.4/lib/python3.4/site-packages/django/conf/urls/__init__.py", line 28, in include
    urlconf_module = import_module(urlconf_module)
  File "/Users/fshaw/Documents/dev/environments/copo_python3.4/lib/python3.4/importlib/__init__.py", line 109, in import_module
    return _bootstrap._gcd_import(name[level:], package, level)
  File "<frozen importlib._bootstrap>", line 2254, in _gcd_import
  File "<frozen importlib._bootstrap>", line 2237, in _find_and_load
  File "<frozen importlib._bootstrap>", line 2226, in _find_and_load_unlocked
  File "<frozen importlib._bootstrap>", line 1200, in _load_unlocked
  File "<frozen importlib._bootstrap>", line 1129, in _exec
  File "<frozen importlib._bootstrap>", line 1471, in exec_module
  File "<frozen importlib._bootstrap>", line 321, in _call_with_frames_removed
  File "/Users/fshaw/Dropbox/tgac_dev/prototypes/COPO/web/apps/web_copo/rest_urls.py", line 5, in <module>
    import web.apps.web_copo.wizard_views as wizard
  File "/Users/fshaw/Dropbox/tgac_dev/prototypes/COPO/web/apps/web_copo/wizard_views.py", line 65
    element =  generate_ena_tags_2(field['id'])
                                              ^
IndentationError: unindent does not match any outer indentation level
[30/Sep/2015 15:00:51] ERROR [django.request:231] Internal Server Error: /rest/get_next_wizard_stage/
Traceback (most recent call last):
  File "/Users/fshaw/Documents/dev/environments/copo_python3.4/lib/python3.4/site-packages/django/core/urlresolvers.py", line 364, in urlconf_module
    return self._urlconf_module
AttributeError: 'RegexURLResolver' object has no attribute '_urlconf_module'

During handling of the above exception, another exception occurred:

Traceback (most recent call last):
  File "/Users/fshaw/Documents/dev/environments/copo_python3.4/lib/python3.4/site-packages/django/core/handlers/base.py", line 98, in get_response
    resolver_match = resolver.resolve(request.path_info)
  File "/Users/fshaw/Documents/dev/environments/copo_python3.4/lib/python3.4/site-packages/django/core/urlresolvers.py", line 343, in resolve
    for pattern in self.url_patterns:
  File "/Users/fshaw/Documents/dev/environments/copo_python3.4/lib/python3.4/site-packages/django/core/urlresolvers.py", line 372, in url_patterns
    patterns = getattr(self.urlconf_module, "urlpatterns", self.urlconf_module)
  File "/Users/fshaw/Documents/dev/environments/copo_python3.4/lib/python3.4/site-packages/django/core/urlresolvers.py", line 366, in urlconf_module
    self._urlconf_module = import_module(self.urlconf_name)
  File "/Users/fshaw/Documents/dev/environments/copo_python3.4/lib/python3.4/importlib/__init__.py", line 109, in import_module
    return _bootstrap._gcd_import(name[level:], package, level)
  File "<frozen importlib._bootstrap>", line 2254, in _gcd_import
  File "<frozen importlib._bootstrap>", line 2237, in _find_and_load
  File "<frozen importlib._bootstrap>", line 2226, in _find_and_load_unlocked
  File "<frozen importlib._bootstrap>", line 1200, in _load_unlocked
  File "<frozen importlib._bootstrap>", line 1129, in _exec
  File "<frozen importlib._bootstrap>", line 1471, in exec_module
  File "<frozen importlib._bootstrap>", line 321, in _call_with_frames_removed
  File "/Users/fshaw/Dropbox/tgac_dev/prototypes/COPO/web/project_copo/urls.py", line 12, in <module>
    url(r'^rest/', include('web_copo.rest_urls', namespace='rest')),
  File "/Users/fshaw/Documents/dev/environments/copo_python3.4/lib/python3.4/site-packages/django/conf/urls/__init__.py", line 28, in include
    urlconf_module = import_module(urlconf_module)
  File "/Users/fshaw/Documents/dev/environments/copo_python3.4/lib/python3.4/importlib/__init__.py", line 109, in import_module
    return _bootstrap._gcd_import(name[level:], package, level)
  File "<frozen importlib._bootstrap>", line 2254, in _gcd_import
  File "<frozen importlib._bootstrap>", line 2237, in _find_and_load
  File "<frozen importlib._bootstrap>", line 2226, in _find_and_load_unlocked
  File "<frozen importlib._bootstrap>", line 1200, in _load_unlocked
  File "<frozen importlib._bootstrap>", line 1129, in _exec
  File "<frozen importlib._bootstrap>", line 1471, in exec_module
  File "<frozen importlib._bootstrap>", line 321, in _call_with_frames_removed
  File "/Users/fshaw/Dropbox/tgac_dev/prototypes/COPO/web/apps/web_copo/rest_urls.py", line 5, in <module>
    import web.apps.web_copo.wizard_views as wizard
  File "/Users/fshaw/Dropbox/tgac_dev/prototypes/COPO/web/apps/web_copo/wizard_views.py", line 65
    element =  generate_ena_tags_2(field['id'])
                                              ^
IndentationError: unindent does not match any outer indentation level
[30/Sep/2015 15:00:55] ERROR [django.request:231] Internal Server Error: /copo/study/248b488dcba44bcf99c66e5ced545e2b/view
Traceback (most recent call last):
  File "/Users/fshaw/Documents/dev/environments/copo_python3.4/lib/python3.4/site-packages/django/core/urlresolvers.py", line 364, in urlconf_module
    return self._urlconf_module
AttributeError: 'RegexURLResolver' object has no attribute '_urlconf_module'

During handling of the above exception, another exception occurred:

Traceback (most recent call last):
  File "/Users/fshaw/Documents/dev/environments/copo_python3.4/lib/python3.4/site-packages/django/core/handlers/base.py", line 87, in get_response
    response = middleware_method(request)
  File "/Users/fshaw/Documents/dev/environments/copo_python3.4/lib/python3.4/site-packages/django/middleware/common.py", line 72, in process_request
    if (not urlresolvers.is_valid_path(request.path_info, urlconf) and
  File "/Users/fshaw/Documents/dev/environments/copo_python3.4/lib/python3.4/site-packages/django/core/urlresolvers.py", line 619, in is_valid_path
    resolve(path, urlconf)
  File "/Users/fshaw/Documents/dev/environments/copo_python3.4/lib/python3.4/site-packages/django/core/urlresolvers.py", line 494, in resolve
    return get_resolver(urlconf).resolve(path)
  File "/Users/fshaw/Documents/dev/environments/copo_python3.4/lib/python3.4/site-packages/django/core/urlresolvers.py", line 343, in resolve
    for pattern in self.url_patterns:
  File "/Users/fshaw/Documents/dev/environments/copo_python3.4/lib/python3.4/site-packages/django/core/urlresolvers.py", line 372, in url_patterns
    patterns = getattr(self.urlconf_module, "urlpatterns", self.urlconf_module)
  File "/Users/fshaw/Documents/dev/environments/copo_python3.4/lib/python3.4/site-packages/django/core/urlresolvers.py", line 366, in urlconf_module
    self._urlconf_module = import_module(self.urlconf_name)
  File "/Users/fshaw/Documents/dev/environments/copo_python3.4/lib/python3.4/importlib/__init__.py", line 109, in import_module
    return _bootstrap._gcd_import(name[level:], package, level)
  File "<frozen importlib._bootstrap>", line 2254, in _gcd_import
  File "<frozen importlib._bootstrap>", line 2237, in _find_and_load
  File "<frozen importlib._bootstrap>", line 2226, in _find_and_load_unlocked
  File "<frozen importlib._bootstrap>", line 1200, in _load_unlocked
  File "<frozen importlib._bootstrap>", line 1129, in _exec
  File "<frozen importlib._bootstrap>", line 1471, in exec_module
  File "<frozen importlib._bootstrap>", line 321, in _call_with_frames_removed
  File "/Users/fshaw/Dropbox/tgac_dev/prototypes/COPO/web/project_copo/urls.py", line 12, in <module>
    url(r'^rest/', include('web_copo.rest_urls', namespace='rest')),
  File "/Users/fshaw/Documents/dev/environments/copo_python3.4/lib/python3.4/site-packages/django/conf/urls/__init__.py", line 28, in include
    urlconf_module = import_module(urlconf_module)
  File "/Users/fshaw/Documents/dev/environments/copo_python3.4/lib/python3.4/importlib/__init__.py", line 109, in import_module
    return _bootstrap._gcd_import(name[level:], package, level)
  File "<frozen importlib._bootstrap>", line 2254, in _gcd_import
  File "<frozen importlib._bootstrap>", line 2237, in _find_and_load
  File "<frozen importlib._bootstrap>", line 2226, in _find_and_load_unlocked
  File "<frozen importlib._bootstrap>", line 1200, in _load_unlocked
  File "<frozen importlib._bootstrap>", line 1129, in _exec
  File "<frozen importlib._bootstrap>", line 1471, in exec_module
  File "<frozen importlib._bootstrap>", line 321, in _call_with_frames_removed
  File "/Users/fshaw/Dropbox/tgac_dev/prototypes/COPO/web/apps/web_copo/rest_urls.py", line 5, in <module>
    import web.apps.web_copo.wizard_views as wizard
  File "/Users/fshaw/Dropbox/tgac_dev/prototypes/COPO/web/apps/web_copo/wizard_views.py", line 65
    element =  generate_ena_tags_2(field['id'])
                                              ^
IndentationError: unindent does not match any outer indentation level
