[15/Sep/2015 11:16:48] ERROR [django.request:231] Internal Server Error: /copo/profile/55ca338591ccd63271f6e35e/view
Traceback (most recent call last):
  File "/Users/etuka/environments/venv3.4/lib/python3.4/site-packages/django/core/urlresolvers.py", line 364, in urlconf_module
    return self._urlconf_module
AttributeError: 'RegexURLResolver' object has no attribute '_urlconf_module'

During handling of the above exception, another exception occurred:

Traceback (most recent call last):
  File "/Users/etuka/environments/venv3.4/lib/python3.4/site-packages/django/core/handlers/base.py", line 87, in get_response
    response = middleware_method(request)
  File "/Users/etuka/environments/venv3.4/lib/python3.4/site-packages/django/middleware/common.py", line 72, in process_request
    if (not urlresolvers.is_valid_path(request.path_info, urlconf) and
  File "/Users/etuka/environments/venv3.4/lib/python3.4/site-packages/django/core/urlresolvers.py", line 619, in is_valid_path
    resolve(path, urlconf)
  File "/Users/etuka/environments/venv3.4/lib/python3.4/site-packages/django/core/urlresolvers.py", line 494, in resolve
    return get_resolver(urlconf).resolve(path)
  File "/Users/etuka/environments/venv3.4/lib/python3.4/site-packages/django/core/urlresolvers.py", line 343, in resolve
    for pattern in self.url_patterns:
  File "/Users/etuka/environments/venv3.4/lib/python3.4/site-packages/django/core/urlresolvers.py", line 372, in url_patterns
    patterns = getattr(self.urlconf_module, "urlpatterns", self.urlconf_module)
  File "/Users/etuka/environments/venv3.4/lib/python3.4/site-packages/django/core/urlresolvers.py", line 366, in urlconf_module
    self._urlconf_module = import_module(self.urlconf_name)
  File "/Users/etuka/environments/venv3.4/lib/python3.4/importlib/__init__.py", line 109, in import_module
    return _bootstrap._gcd_import(name[level:], package, level)
  File "<frozen importlib._bootstrap>", line 2254, in _gcd_import
  File "<frozen importlib._bootstrap>", line 2237, in _find_and_load
  File "<frozen importlib._bootstrap>", line 2226, in _find_and_load_unlocked
  File "<frozen importlib._bootstrap>", line 1200, in _load_unlocked
  File "<frozen importlib._bootstrap>", line 1129, in _exec
  File "<frozen importlib._bootstrap>", line 1471, in exec_module
  File "<frozen importlib._bootstrap>", line 321, in _call_with_frames_removed
  File "/Users/etuka/Dropbox/Dev/COPO/web/project_copo/urls.py", line 4, in <module>
    import web_copo.views as views
  File "/Users/etuka/Dropbox/Dev/COPO/web/apps/web_copo/views.py", line 19, in <module>
    from web.apps.web_copo.repos.aspera import do_aspera_transfer
  File "/Users/etuka/Dropbox/Dev/COPO/web/apps/web_copo/repos/aspera.py", line 10, in <module>
    from dal import ObjectId
  File "/Users/etuka/Dropbox/Dev/COPO/dal/__init__.py", line 11, in <module>
    from ena_da import EnaCollection
  File "/Users/etuka/Dropbox/Dev/COPO/dal/ena_da.py", line 15, in <module>
    import web.apps.web_copo.copo_maps.utils.data_utils as d_utils
  File "/Users/etuka/Dropbox/Dev/COPO/web/apps/web_copo/copo_maps/utils/data_utils.py", line 6, in <module>
    import web.apps.web_copo.uiconfigs.ena.uimodels.ena_copo_config as ecc
ImportError: No module named 'web.apps.web_copo.uiconfigs.ena.uimodels.ena_copo_config'
[15/Sep/2015 11:18:49] ERROR [django.request:231] Internal Server Error: /copo/profile/55ca338591ccd63271f6e35e/view
Traceback (most recent call last):
  File "/Users/etuka/environments/venv3.4/lib/python3.4/site-packages/django/core/urlresolvers.py", line 364, in urlconf_module
    return self._urlconf_module
AttributeError: 'RegexURLResolver' object has no attribute '_urlconf_module'

During handling of the above exception, another exception occurred:

Traceback (most recent call last):
  File "/Users/etuka/environments/venv3.4/lib/python3.4/site-packages/django/core/handlers/base.py", line 87, in get_response
    response = middleware_method(request)
  File "/Users/etuka/environments/venv3.4/lib/python3.4/site-packages/django/middleware/common.py", line 72, in process_request
    if (not urlresolvers.is_valid_path(request.path_info, urlconf) and
  File "/Users/etuka/environments/venv3.4/lib/python3.4/site-packages/django/core/urlresolvers.py", line 619, in is_valid_path
    resolve(path, urlconf)
  File "/Users/etuka/environments/venv3.4/lib/python3.4/site-packages/django/core/urlresolvers.py", line 494, in resolve
    return get_resolver(urlconf).resolve(path)
  File "/Users/etuka/environments/venv3.4/lib/python3.4/site-packages/django/core/urlresolvers.py", line 343, in resolve
    for pattern in self.url_patterns:
  File "/Users/etuka/environments/venv3.4/lib/python3.4/site-packages/django/core/urlresolvers.py", line 372, in url_patterns
    patterns = getattr(self.urlconf_module, "urlpatterns", self.urlconf_module)
  File "/Users/etuka/environments/venv3.4/lib/python3.4/site-packages/django/core/urlresolvers.py", line 366, in urlconf_module
    self._urlconf_module = import_module(self.urlconf_name)
  File "/Users/etuka/environments/venv3.4/lib/python3.4/importlib/__init__.py", line 109, in import_module
    return _bootstrap._gcd_import(name[level:], package, level)
  File "<frozen importlib._bootstrap>", line 2254, in _gcd_import
  File "<frozen importlib._bootstrap>", line 2237, in _find_and_load
  File "<frozen importlib._bootstrap>", line 2226, in _find_and_load_unlocked
  File "<frozen importlib._bootstrap>", line 1200, in _load_unlocked
  File "<frozen importlib._bootstrap>", line 1129, in _exec
  File "<frozen importlib._bootstrap>", line 1471, in exec_module
  File "<frozen importlib._bootstrap>", line 321, in _call_with_frames_removed
  File "/Users/etuka/Dropbox/Dev/COPO/web/project_copo/urls.py", line 4, in <module>
    import web_copo.views as views
  File "/Users/etuka/Dropbox/Dev/COPO/web/apps/web_copo/views.py", line 19, in <module>
    from web.apps.web_copo.repos.aspera import do_aspera_transfer
  File "/Users/etuka/Dropbox/Dev/COPO/web/apps/web_copo/repos/aspera.py", line 10, in <module>
    from dal import ObjectId
  File "/Users/etuka/Dropbox/Dev/COPO/dal/__init__.py", line 11, in <module>
    from ena_da import EnaCollection
  File "/Users/etuka/Dropbox/Dev/COPO/dal/ena_da.py", line 18, in <module>
    import web.apps.web_copo.uiconfigs.utils.data_utils as d_utils
ImportError: No module named 'web.apps.web_copo.uiconfigs.utils.data_utils'
[15/Sep/2015 11:19:38] DEBUG [web_copo.views:22] ['/Users/etuka/Dropbox/Dev/COPO/web', '/Applications/PyCharm.app/Contents/helpers/pydev', '/Users/etuka/environments/venv3.4/lib/python3.4/site-packages/setuptools-15.1-py3.4.egg', '/Users/etuka/Dropbox/Dev/COPO/web/project_copo', '/Users/etuka/Dropbox/Dev/COPO', '/Users/etuka/Dropbox/Dev/COPO/dal', '/Users/etuka/Dropbox/Dev/COPO/api', '/Users/etuka/Dropbox/Dev/COPO/web/project_copo/settings', '/Users/etuka/environments/venv3.4/lib/python34.zip', '/Users/etuka/environments/venv3.4/lib/python3.4', '/Users/etuka/environments/venv3.4/lib/python3.4/plat-darwin', '/Users/etuka/environments/venv3.4/lib/python3.4/lib-dynload', '/usr/local/Cellar/python3/3.4.3/Frameworks/Python.framework/Versions/3.4/lib/python3.4', '/usr/local/Cellar/python3/3.4.3/Frameworks/Python.framework/Versions/3.4/lib/python3.4/plat-darwin', '/Users/etuka/environments/venv3.4/lib/python3.4/site-packages', '/Users/etuka/Dropbox/Dev/COPO', '/Users/etuka/Dropbox/Dev/COPO/api', '/Users/etuka/Dropbox/Dev/COPO/dal', '/Users/etuka/Dropbox/Dev/COPO/web/project_copo', '/Users/etuka/Dropbox/Dev/COPO/web/project_copo/settings', '/Users/etuka/Dropbox/Dev/COPO/web/apps', '/var/www/copo_www/COPO/', '/var/www/copo_www/COPO/api', '/var/www/copo_www/COPO/dal', '/var/www/copo_www/COPO/web/project_copo', '/var/www/copo_www/COPO/web/project_copo/settings', '/var/www/copo_www/COPO/web/apps']
[15/Sep/2015 11:19:39] ERROR [django.request:231] Internal Server Error: /copo/profile/55ca338591ccd63271f6e35e/view
Traceback (most recent call last):
  File "/Users/etuka/environments/venv3.4/lib/python3.4/site-packages/django/core/urlresolvers.py", line 364, in urlconf_module
    return self._urlconf_module
AttributeError: 'RegexURLResolver' object has no attribute '_urlconf_module'

During handling of the above exception, another exception occurred:

Traceback (most recent call last):
  File "/Users/etuka/environments/venv3.4/lib/python3.4/site-packages/django/core/handlers/base.py", line 87, in get_response
    response = middleware_method(request)
  File "/Users/etuka/environments/venv3.4/lib/python3.4/site-packages/django/middleware/common.py", line 72, in process_request
    if (not urlresolvers.is_valid_path(request.path_info, urlconf) and
  File "/Users/etuka/environments/venv3.4/lib/python3.4/site-packages/django/core/urlresolvers.py", line 619, in is_valid_path
    resolve(path, urlconf)
  File "/Users/etuka/environments/venv3.4/lib/python3.4/site-packages/django/core/urlresolvers.py", line 494, in resolve
    return get_resolver(urlconf).resolve(path)
  File "/Users/etuka/environments/venv3.4/lib/python3.4/site-packages/django/core/urlresolvers.py", line 343, in resolve
    for pattern in self.url_patterns:
  File "/Users/etuka/environments/venv3.4/lib/python3.4/site-packages/django/core/urlresolvers.py", line 372, in url_patterns
    patterns = getattr(self.urlconf_module, "urlpatterns", self.urlconf_module)
  File "/Users/etuka/environments/venv3.4/lib/python3.4/site-packages/django/core/urlresolvers.py", line 366, in urlconf_module
    self._urlconf_module = import_module(self.urlconf_name)
  File "/Users/etuka/environments/venv3.4/lib/python3.4/importlib/__init__.py", line 109, in import_module
    return _bootstrap._gcd_import(name[level:], package, level)
  File "<frozen importlib._bootstrap>", line 2254, in _gcd_import
  File "<frozen importlib._bootstrap>", line 2237, in _find_and_load
  File "<frozen importlib._bootstrap>", line 2226, in _find_and_load_unlocked
  File "<frozen importlib._bootstrap>", line 1200, in _load_unlocked
  File "<frozen importlib._bootstrap>", line 1129, in _exec
  File "<frozen importlib._bootstrap>", line 1471, in exec_module
  File "<frozen importlib._bootstrap>", line 321, in _call_with_frames_removed
  File "/Users/etuka/Dropbox/Dev/COPO/web/project_copo/urls.py", line 4, in <module>
    import web_copo.views as views
  File "/Users/etuka/Dropbox/Dev/COPO/web/apps/web_copo/views.py", line 32, in <module>
    from web.apps.web_copo.api.views import *
  File "/Users/etuka/Dropbox/Dev/COPO/web/apps/web_copo/api/views.py", line 13, in <module>
    from web.apps.web_copo.uiconfigs.utils.data_formats import DataFormats
ImportError: No module named 'web.apps.web_copo.uiconfigs.utils.data_formats'
[15/Sep/2015 11:21:00] DEBUG [web_copo.views:22] ['/Users/etuka/Dropbox/Dev/COPO/web', '/Applications/PyCharm.app/Contents/helpers/pydev', '/Users/etuka/environments/venv3.4/lib/python3.4/site-packages/setuptools-15.1-py3.4.egg', '/Users/etuka/Dropbox/Dev/COPO/web/project_copo', '/Users/etuka/Dropbox/Dev/COPO', '/Users/etuka/Dropbox/Dev/COPO/dal', '/Users/etuka/Dropbox/Dev/COPO/api', '/Users/etuka/Dropbox/Dev/COPO/web/project_copo/settings', '/Users/etuka/environments/venv3.4/lib/python34.zip', '/Users/etuka/environments/venv3.4/lib/python3.4', '/Users/etuka/environments/venv3.4/lib/python3.4/plat-darwin', '/Users/etuka/environments/venv3.4/lib/python3.4/lib-dynload', '/usr/local/Cellar/python3/3.4.3/Frameworks/Python.framework/Versions/3.4/lib/python3.4', '/usr/local/Cellar/python3/3.4.3/Frameworks/Python.framework/Versions/3.4/lib/python3.4/plat-darwin', '/Users/etuka/environments/venv3.4/lib/python3.4/site-packages', '/Users/etuka/Dropbox/Dev/COPO', '/Users/etuka/Dropbox/Dev/COPO/api', '/Users/etuka/Dropbox/Dev/COPO/dal', '/Users/etuka/Dropbox/Dev/COPO/web/project_copo', '/Users/etuka/Dropbox/Dev/COPO/web/project_copo/settings', '/Users/etuka/Dropbox/Dev/COPO/web/apps', '/var/www/copo_www/COPO/', '/var/www/copo_www/COPO/api', '/var/www/copo_www/COPO/dal', '/var/www/copo_www/COPO/web/project_copo', '/var/www/copo_www/COPO/web/project_copo/settings', '/var/www/copo_www/COPO/web/apps']
[15/Sep/2015 11:21:00] ERROR [django.request:231] Internal Server Error: /copo/profile/55ca338591ccd63271f6e35e/view
Traceback (most recent call last):
  File "/Users/etuka/environments/venv3.4/lib/python3.4/site-packages/django/core/urlresolvers.py", line 364, in urlconf_module
    return self._urlconf_module
AttributeError: 'RegexURLResolver' object has no attribute '_urlconf_module'

During handling of the above exception, another exception occurred:

Traceback (most recent call last):
  File "/Users/etuka/environments/venv3.4/lib/python3.4/site-packages/django/core/handlers/base.py", line 87, in get_response
    response = middleware_method(request)
  File "/Users/etuka/environments/venv3.4/lib/python3.4/site-packages/django/middleware/common.py", line 72, in process_request
    if (not urlresolvers.is_valid_path(request.path_info, urlconf) and
  File "/Users/etuka/environments/venv3.4/lib/python3.4/site-packages/django/core/urlresolvers.py", line 619, in is_valid_path
    resolve(path, urlconf)
  File "/Users/etuka/environments/venv3.4/lib/python3.4/site-packages/django/core/urlresolvers.py", line 494, in resolve
    return get_resolver(urlconf).resolve(path)
  File "/Users/etuka/environments/venv3.4/lib/python3.4/site-packages/django/core/urlresolvers.py", line 343, in resolve
    for pattern in self.url_patterns:
  File "/Users/etuka/environments/venv3.4/lib/python3.4/site-packages/django/core/urlresolvers.py", line 372, in url_patterns
    patterns = getattr(self.urlconf_module, "urlpatterns", self.urlconf_module)
  File "/Users/etuka/environments/venv3.4/lib/python3.4/site-packages/django/core/urlresolvers.py", line 366, in urlconf_module
    self._urlconf_module = import_module(self.urlconf_name)
  File "/Users/etuka/environments/venv3.4/lib/python3.4/importlib/__init__.py", line 109, in import_module
    return _bootstrap._gcd_import(name[level:], package, level)
  File "<frozen importlib._bootstrap>", line 2254, in _gcd_import
  File "<frozen importlib._bootstrap>", line 2237, in _find_and_load
  File "<frozen importlib._bootstrap>", line 2226, in _find_and_load_unlocked
  File "<frozen importlib._bootstrap>", line 1200, in _load_unlocked
  File "<frozen importlib._bootstrap>", line 1129, in _exec
  File "<frozen importlib._bootstrap>", line 1471, in exec_module
  File "<frozen importlib._bootstrap>", line 321, in _call_with_frames_removed
  File "/Users/etuka/Dropbox/Dev/COPO/web/project_copo/urls.py", line 4, in <module>
    import web_copo.views as views
  File "/Users/etuka/Dropbox/Dev/COPO/web/apps/web_copo/views.py", line 32, in <module>
    from web.apps.web_copo.api.views import *
  File "/Users/etuka/Dropbox/Dev/COPO/web/apps/web_copo/api/views.py", line 13, in <module>
    from web.apps.web_copo.uiconfigs.utils.data_formats import DataFormats
ImportError: No module named 'web.apps.web_copo.uiconfigs.utils.data_formats'
[15/Sep/2015 11:21:36] DEBUG [web_copo.views:22] ['/Users/etuka/Dropbox/Dev/COPO/web', '/Applications/PyCharm.app/Contents/helpers/pydev', '/Users/etuka/environments/venv3.4/lib/python3.4/site-packages/setuptools-15.1-py3.4.egg', '/Users/etuka/Dropbox/Dev/COPO/web/project_copo', '/Users/etuka/Dropbox/Dev/COPO', '/Users/etuka/Dropbox/Dev/COPO/dal', '/Users/etuka/Dropbox/Dev/COPO/api', '/Users/etuka/Dropbox/Dev/COPO/web/project_copo/settings', '/Users/etuka/environments/venv3.4/lib/python34.zip', '/Users/etuka/environments/venv3.4/lib/python3.4', '/Users/etuka/environments/venv3.4/lib/python3.4/plat-darwin', '/Users/etuka/environments/venv3.4/lib/python3.4/lib-dynload', '/usr/local/Cellar/python3/3.4.3/Frameworks/Python.framework/Versions/3.4/lib/python3.4', '/usr/local/Cellar/python3/3.4.3/Frameworks/Python.framework/Versions/3.4/lib/python3.4/plat-darwin', '/Users/etuka/environments/venv3.4/lib/python3.4/site-packages', '/Users/etuka/Dropbox/Dev/COPO', '/Users/etuka/Dropbox/Dev/COPO/api', '/Users/etuka/Dropbox/Dev/COPO/dal', '/Users/etuka/Dropbox/Dev/COPO/web/project_copo', '/Users/etuka/Dropbox/Dev/COPO/web/project_copo/settings', '/Users/etuka/Dropbox/Dev/COPO/web/apps', '/var/www/copo_www/COPO/', '/var/www/copo_www/COPO/api', '/var/www/copo_www/COPO/dal', '/var/www/copo_www/COPO/web/project_copo', '/var/www/copo_www/COPO/web/project_copo/settings', '/var/www/copo_www/COPO/web/apps']
[15/Sep/2015 11:21:36] INFO [rdflib:81] RDFLib Version: 4.2.1
[15/Sep/2015 11:21:36] ERROR [django.request:231] Internal Server Error: /copo/profile/55ca338591ccd63271f6e35e/view
Traceback (most recent call last):
  File "/Users/etuka/environments/venv3.4/lib/python3.4/site-packages/django/core/urlresolvers.py", line 364, in urlconf_module
    return self._urlconf_module
AttributeError: 'RegexURLResolver' object has no attribute '_urlconf_module'

During handling of the above exception, another exception occurred:

Traceback (most recent call last):
  File "/Users/etuka/environments/venv3.4/lib/python3.4/site-packages/django/core/handlers/base.py", line 87, in get_response
    response = middleware_method(request)
  File "/Users/etuka/environments/venv3.4/lib/python3.4/site-packages/django/middleware/common.py", line 72, in process_request
    if (not urlresolvers.is_valid_path(request.path_info, urlconf) and
  File "/Users/etuka/environments/venv3.4/lib/python3.4/site-packages/django/core/urlresolvers.py", line 619, in is_valid_path
    resolve(path, urlconf)
  File "/Users/etuka/environments/venv3.4/lib/python3.4/site-packages/django/core/urlresolvers.py", line 494, in resolve
    return get_resolver(urlconf).resolve(path)
  File "/Users/etuka/environments/venv3.4/lib/python3.4/site-packages/django/core/urlresolvers.py", line 343, in resolve
    for pattern in self.url_patterns:
  File "/Users/etuka/environments/venv3.4/lib/python3.4/site-packages/django/core/urlresolvers.py", line 372, in url_patterns
    patterns = getattr(self.urlconf_module, "urlpatterns", self.urlconf_module)
  File "/Users/etuka/environments/venv3.4/lib/python3.4/site-packages/django/core/urlresolvers.py", line 366, in urlconf_module
    self._urlconf_module = import_module(self.urlconf_name)
  File "/Users/etuka/environments/venv3.4/lib/python3.4/importlib/__init__.py", line 109, in import_module
    return _bootstrap._gcd_import(name[level:], package, level)
  File "<frozen importlib._bootstrap>", line 2254, in _gcd_import
  File "<frozen importlib._bootstrap>", line 2237, in _find_and_load
  File "<frozen importlib._bootstrap>", line 2226, in _find_and_load_unlocked
  File "<frozen importlib._bootstrap>", line 1200, in _load_unlocked
  File "<frozen importlib._bootstrap>", line 1129, in _exec
  File "<frozen importlib._bootstrap>", line 1471, in exec_module
  File "<frozen importlib._bootstrap>", line 321, in _call_with_frames_removed
  File "/Users/etuka/Dropbox/Dev/COPO/web/project_copo/urls.py", line 4, in <module>
    import web_copo.views as views
  File "/Users/etuka/Dropbox/Dev/COPO/web/apps/web_copo/views.py", line 34, in <module>
    import web.apps.web_copo.templatetags.html_tags as htags
  File "/Users/etuka/Dropbox/Dev/COPO/web/apps/web_copo/templatetags/html_tags.py", line 6, in <module>
    import web.apps.web_copo.uiconfigs.utils.data_utils as d_utils
ImportError: No module named 'web.apps.web_copo.uiconfigs.utils.data_utils'
[15/Sep/2015 11:22:08] DEBUG [web_copo.views:22] ['/Users/etuka/Dropbox/Dev/COPO/web', '/Applications/PyCharm.app/Contents/helpers/pydev', '/Users/etuka/environments/venv3.4/lib/python3.4/site-packages/setuptools-15.1-py3.4.egg', '/Users/etuka/Dropbox/Dev/COPO/web/project_copo', '/Users/etuka/Dropbox/Dev/COPO', '/Users/etuka/Dropbox/Dev/COPO/dal', '/Users/etuka/Dropbox/Dev/COPO/api', '/Users/etuka/Dropbox/Dev/COPO/web/project_copo/settings', '/Users/etuka/environments/venv3.4/lib/python34.zip', '/Users/etuka/environments/venv3.4/lib/python3.4', '/Users/etuka/environments/venv3.4/lib/python3.4/plat-darwin', '/Users/etuka/environments/venv3.4/lib/python3.4/lib-dynload', '/usr/local/Cellar/python3/3.4.3/Frameworks/Python.framework/Versions/3.4/lib/python3.4', '/usr/local/Cellar/python3/3.4.3/Frameworks/Python.framework/Versions/3.4/lib/python3.4/plat-darwin', '/Users/etuka/environments/venv3.4/lib/python3.4/site-packages', '/Users/etuka/Dropbox/Dev/COPO', '/Users/etuka/Dropbox/Dev/COPO/api', '/Users/etuka/Dropbox/Dev/COPO/dal', '/Users/etuka/Dropbox/Dev/COPO/web/project_copo', '/Users/etuka/Dropbox/Dev/COPO/web/project_copo/settings', '/Users/etuka/Dropbox/Dev/COPO/web/apps', '/var/www/copo_www/COPO/', '/var/www/copo_www/COPO/api', '/var/www/copo_www/COPO/dal', '/var/www/copo_www/COPO/web/project_copo', '/var/www/copo_www/COPO/web/project_copo/settings', '/var/www/copo_www/COPO/web/apps']
[15/Sep/2015 13:33:27] DEBUG [web_copo.views:22] ['/Users/etuka/Dropbox/Dev/COPO/web', '/Applications/PyCharm.app/Contents/helpers/pydev', '/Users/etuka/environments/venv3.4/lib/python3.4/site-packages/setuptools-15.1-py3.4.egg', '/Users/etuka/Dropbox/Dev/COPO/web/project_copo', '/Users/etuka/Dropbox/Dev/COPO', '/Users/etuka/Dropbox/Dev/COPO/dal', '/Users/etuka/Dropbox/Dev/COPO/api', '/Users/etuka/Dropbox/Dev/COPO/web/project_copo/settings', '/Users/etuka/environments/venv3.4/lib/python34.zip', '/Users/etuka/environments/venv3.4/lib/python3.4', '/Users/etuka/environments/venv3.4/lib/python3.4/plat-darwin', '/Users/etuka/environments/venv3.4/lib/python3.4/lib-dynload', '/usr/local/Cellar/python3/3.4.3/Frameworks/Python.framework/Versions/3.4/lib/python3.4', '/usr/local/Cellar/python3/3.4.3/Frameworks/Python.framework/Versions/3.4/lib/python3.4/plat-darwin', '/Users/etuka/environments/venv3.4/lib/python3.4/site-packages', '/Users/etuka/Dropbox/Dev/COPO', '/Users/etuka/Dropbox/Dev/COPO/api', '/Users/etuka/Dropbox/Dev/COPO/dal', '/Users/etuka/Dropbox/Dev/COPO/web/project_copo', '/Users/etuka/Dropbox/Dev/COPO/web/project_copo/settings', '/Users/etuka/Dropbox/Dev/COPO/web/apps', '/var/www/copo_www/COPO/', '/var/www/copo_www/COPO/api', '/var/www/copo_www/COPO/dal', '/var/www/copo_www/COPO/web/project_copo', '/var/www/copo_www/COPO/web/project_copo/settings', '/var/www/copo_www/COPO/web/apps']
[15/Sep/2015 13:33:27] INFO [rdflib:81] RDFLib Version: 4.2.1
[15/Sep/2015 13:33:53] DEBUG [web_copo.views:22] ['/Users/etuka/Dropbox/Dev/COPO/web', '/Applications/PyCharm.app/Contents/helpers/pydev', '/Users/etuka/environments/venv3.4/lib/python3.4/site-packages/setuptools-15.1-py3.4.egg', '/Users/etuka/Dropbox/Dev/COPO/web/project_copo', '/Users/etuka/Dropbox/Dev/COPO', '/Users/etuka/Dropbox/Dev/COPO/dal', '/Users/etuka/Dropbox/Dev/COPO/api', '/Users/etuka/Dropbox/Dev/COPO/web/project_copo/settings', '/Users/etuka/environments/venv3.4/lib/python34.zip', '/Users/etuka/environments/venv3.4/lib/python3.4', '/Users/etuka/environments/venv3.4/lib/python3.4/plat-darwin', '/Users/etuka/environments/venv3.4/lib/python3.4/lib-dynload', '/usr/local/Cellar/python3/3.4.3/Frameworks/Python.framework/Versions/3.4/lib/python3.4', '/usr/local/Cellar/python3/3.4.3/Frameworks/Python.framework/Versions/3.4/lib/python3.4/plat-darwin', '/Users/etuka/environments/venv3.4/lib/python3.4/site-packages', '/Users/etuka/Dropbox/Dev/COPO', '/Users/etuka/Dropbox/Dev/COPO/api', '/Users/etuka/Dropbox/Dev/COPO/dal', '/Users/etuka/Dropbox/Dev/COPO/web/project_copo', '/Users/etuka/Dropbox/Dev/COPO/web/project_copo/settings', '/Users/etuka/Dropbox/Dev/COPO/web/apps', '/var/www/copo_www/COPO/', '/var/www/copo_www/COPO/api', '/var/www/copo_www/COPO/dal', '/var/www/copo_www/COPO/web/project_copo', '/var/www/copo_www/COPO/web/project_copo/settings', '/var/www/copo_www/COPO/web/apps']
[15/Sep/2015 13:33:53] INFO [rdflib:81] RDFLib Version: 4.2.1
[15/Sep/2015 13:33:53] ERROR [django.request:231] Internal Server Error: /copo/collection/55edacf791ccd60b090af08f/view
Traceback (most recent call last):
  File "/Users/etuka/environments/venv3.4/lib/python3.4/site-packages/django/core/handlers/base.py", line 111, in get_response
    response = wrapped_callback(request, *callback_args, **callback_kwargs)
  File "/Users/etuka/environments/venv3.4/lib/python3.4/site-packages/django/contrib/auth/decorators.py", line 21, in _wrapped_view
    return view_func(request, *args, **kwargs)
  File "/Users/etuka/Dropbox/Dev/COPO/web/apps/web_copo/views.py", line 246, in view_collection
    sample_attributes = d_utils.get_sample_attributes()
  File "/Users/etuka/Dropbox/Dev/COPO/web/apps/web_copo/copo_maps/utils/data_utils.py", line 53, in get_sample_attributes
    sample_attributes = json_to_pytype(ecc.MODEL_FILES["SAMPLE_ATTRIBUTES"])
  File "/Users/etuka/Dropbox/Dev/COPO/web/apps/web_copo/copo_maps/utils/data_utils.py", line 61, in json_to_pytype
    with open(path_to_json, encoding='utf-8') as data_file:
FileNotFoundError: [Errno 2] No such file or directory: '/Users/etuka/Dropbox/Dev/COPO/web/apps/web_copo/copo_maps1/ena/uimodels/sample_characteristics.json'
[15/Sep/2015 13:34:07] DEBUG [web_copo.views:22] ['/Users/etuka/Dropbox/Dev/COPO/web', '/Applications/PyCharm.app/Contents/helpers/pydev', '/Users/etuka/environments/venv3.4/lib/python3.4/site-packages/setuptools-15.1-py3.4.egg', '/Users/etuka/Dropbox/Dev/COPO/web/project_copo', '/Users/etuka/Dropbox/Dev/COPO', '/Users/etuka/Dropbox/Dev/COPO/dal', '/Users/etuka/Dropbox/Dev/COPO/api', '/Users/etuka/Dropbox/Dev/COPO/web/project_copo/settings', '/Users/etuka/environments/venv3.4/lib/python34.zip', '/Users/etuka/environments/venv3.4/lib/python3.4', '/Users/etuka/environments/venv3.4/lib/python3.4/plat-darwin', '/Users/etuka/environments/venv3.4/lib/python3.4/lib-dynload', '/usr/local/Cellar/python3/3.4.3/Frameworks/Python.framework/Versions/3.4/lib/python3.4', '/usr/local/Cellar/python3/3.4.3/Frameworks/Python.framework/Versions/3.4/lib/python3.4/plat-darwin', '/Users/etuka/environments/venv3.4/lib/python3.4/site-packages', '/Users/etuka/Dropbox/Dev/COPO', '/Users/etuka/Dropbox/Dev/COPO/api', '/Users/etuka/Dropbox/Dev/COPO/dal', '/Users/etuka/Dropbox/Dev/COPO/web/project_copo', '/Users/etuka/Dropbox/Dev/COPO/web/project_copo/settings', '/Users/etuka/Dropbox/Dev/COPO/web/apps', '/var/www/copo_www/COPO/', '/var/www/copo_www/COPO/api', '/var/www/copo_www/COPO/dal', '/var/www/copo_www/COPO/web/project_copo', '/var/www/copo_www/COPO/web/project_copo/settings', '/var/www/copo_www/COPO/web/apps']
[15/Sep/2015 13:34:07] INFO [rdflib:81] RDFLib Version: 4.2.1
[15/Sep/2015 13:34:41] ERROR [django.request:231] Internal Server Error: /copo/collection/55edacf791ccd60b090af08f/view
Traceback (most recent call last):
  File "/Users/etuka/environments/venv3.4/lib/python3.4/site-packages/django/core/handlers/base.py", line 111, in get_response
    response = wrapped_callback(request, *callback_args, **callback_kwargs)
  File "/Users/etuka/environments/venv3.4/lib/python3.4/site-packages/django/contrib/auth/decorators.py", line 21, in _wrapped_view
    return view_func(request, *args, **kwargs)
  File "/Users/etuka/Dropbox/Dev/COPO/web/apps/web_copo/views.py", line 231, in view_collection
    ui_template = DataSchemas("ENA").get_ui_template()
  File "/Users/etuka/Dropbox/Dev/COPO/dal/copo_base_da.py", line 195, in get_ui_template
    temp_dict = DataFormats(self.schema).generate_ui_template()
  File "/Users/etuka/Dropbox/Dev/COPO/web/apps/web_copo/copo_maps/utils/data_formats.py", line 23, in generate_ui_template
    new_list = list(itertools.chain(self.do_mapping_ena("INVESTIGATION_FILE"),
  File "/Users/etuka/Dropbox/Dev/COPO/web/apps/web_copo/copo_maps/utils/data_formats.py", line 63, in do_mapping_ena
    attr = lkup.SCHEMAS[self.schema]['ATTRIBUTE_MAPPINGS']
KeyError: 'ATTRIBUTE_MAPPINGS'
[15/Sep/2015 13:38:37] DEBUG [web_copo.views:22] ['/Users/etuka/Dropbox/Dev/COPO/web', '/Applications/PyCharm.app/Contents/helpers/pydev', '/Users/etuka/environments/venv3.4/lib/python3.4/site-packages/setuptools-15.1-py3.4.egg', '/Users/etuka/Dropbox/Dev/COPO/web/project_copo', '/Users/etuka/Dropbox/Dev/COPO', '/Users/etuka/Dropbox/Dev/COPO/dal', '/Users/etuka/Dropbox/Dev/COPO/api', '/Users/etuka/Dropbox/Dev/COPO/web/project_copo/settings', '/Users/etuka/environments/venv3.4/lib/python34.zip', '/Users/etuka/environments/venv3.4/lib/python3.4', '/Users/etuka/environments/venv3.4/lib/python3.4/plat-darwin', '/Users/etuka/environments/venv3.4/lib/python3.4/lib-dynload', '/usr/local/Cellar/python3/3.4.3/Frameworks/Python.framework/Versions/3.4/lib/python3.4', '/usr/local/Cellar/python3/3.4.3/Frameworks/Python.framework/Versions/3.4/lib/python3.4/plat-darwin', '/Users/etuka/environments/venv3.4/lib/python3.4/site-packages', '/Users/etuka/Dropbox/Dev/COPO', '/Users/etuka/Dropbox/Dev/COPO/api', '/Users/etuka/Dropbox/Dev/COPO/dal', '/Users/etuka/Dropbox/Dev/COPO/web/project_copo', '/Users/etuka/Dropbox/Dev/COPO/web/project_copo/settings', '/Users/etuka/Dropbox/Dev/COPO/web/apps', '/var/www/copo_www/COPO/', '/var/www/copo_www/COPO/api', '/var/www/copo_www/COPO/dal', '/var/www/copo_www/COPO/web/project_copo', '/var/www/copo_www/COPO/web/project_copo/settings', '/var/www/copo_www/COPO/web/apps']
[15/Sep/2015 13:38:37] INFO [rdflib:81] RDFLib Version: 4.2.1
