[12/Aug/2015 09:43:46] DEBUG [requests.packages.urllib3.connectionpool:383] "GET /v1.2/0000-0001-9649-5906/orcid-profile HTTP/1.1" 200 None
[12/Aug/2015 11:01:41] DEBUG [web_copo.views:19] ['/Users/fshaw/Dropbox/tgac_dev/prototypes/COPO/web', '/Users/fshaw/Dropbox/tgac_dev/prototypes/COPO/web/project_copo/settings', '/Users/fshaw/Dropbox/tgac_dev/prototypes/COPO', '/Users/fshaw/Dropbox/tgac_dev/prototypes/COPO/dal', '/Users/fshaw/Dropbox/tgac_dev/prototypes/COPO/web/apps', '/Users/fshaw/Dropbox/tgac_dev/prototypes/COPO/api', '/Users/fshaw/Dropbox/tgac_dev/prototypes/COPO/web/project_copo', '/Users/fshaw/Documents/dev/environments/copo_python3.4/lib/python34.zip', '/Users/fshaw/Documents/dev/environments/copo_python3.4/lib/python3.4', '/Users/fshaw/Documents/dev/environments/copo_python3.4/lib/python3.4/plat-darwin', '/Users/fshaw/Documents/dev/environments/copo_python3.4/lib/python3.4/lib-dynload', '/Library/Frameworks/Python.framework/Versions/3.4/lib/python3.4', '/Library/Frameworks/Python.framework/Versions/3.4/lib/python3.4/plat-darwin', '/Users/fshaw/Documents/dev/environments/copo_python3.4/lib/python3.4/site-packages', '/Users/fshaw/Dropbox/tgac_dev/prototypes/COPO', '/Users/fshaw/Dropbox/tgac_dev/prototypes/COPO/api', '/Users/fshaw/Dropbox/tgac_dev/prototypes/COPO/dal', '/Users/fshaw/Dropbox/tgac_dev/prototypes/COPO/web/project_copo', '/Users/fshaw/Dropbox/tgac_dev/prototypes/COPO/web/project_copo/settings', '/Users/fshaw/Dropbox/tgac_dev/prototypes/COPO/web/apps', '/var/www/copo_www/COPO/', '/var/www/copo_www/COPO/api', '/var/www/copo_www/COPO/dal', '/var/www/copo_www/COPO/web/project_copo', '/var/www/copo_www/COPO/web/project_copo/settings', '/var/www/copo_www/COPO/web/apps']
[12/Aug/2015 13:46:25] DEBUG [web_copo.views:19] ['/Users/fshaw/Dropbox/tgac_dev/prototypes/COPO/web', '/Users/fshaw/Dropbox/tgac_dev/prototypes/COPO/web/project_copo/settings', '/Users/fshaw/Dropbox/tgac_dev/prototypes/COPO', '/Users/fshaw/Dropbox/tgac_dev/prototypes/COPO/dal', '/Users/fshaw/Dropbox/tgac_dev/prototypes/COPO/web/apps', '/Users/fshaw/Dropbox/tgac_dev/prototypes/COPO/api', '/Users/fshaw/Dropbox/tgac_dev/prototypes/COPO/web/project_copo', '/Users/fshaw/Documents/dev/environments/copo_python3.4/lib/python34.zip', '/Users/fshaw/Documents/dev/environments/copo_python3.4/lib/python3.4', '/Users/fshaw/Documents/dev/environments/copo_python3.4/lib/python3.4/plat-darwin', '/Users/fshaw/Documents/dev/environments/copo_python3.4/lib/python3.4/lib-dynload', '/Library/Frameworks/Python.framework/Versions/3.4/lib/python3.4', '/Library/Frameworks/Python.framework/Versions/3.4/lib/python3.4/plat-darwin', '/Users/fshaw/Documents/dev/environments/copo_python3.4/lib/python3.4/site-packages', '/Users/fshaw/Dropbox/tgac_dev/prototypes/COPO', '/Users/fshaw/Dropbox/tgac_dev/prototypes/COPO/api', '/Users/fshaw/Dropbox/tgac_dev/prototypes/COPO/dal', '/Users/fshaw/Dropbox/tgac_dev/prototypes/COPO/web/project_copo', '/Users/fshaw/Dropbox/tgac_dev/prototypes/COPO/web/project_copo/settings', '/Users/fshaw/Dropbox/tgac_dev/prototypes/COPO/web/apps', '/var/www/copo_www/COPO/', '/var/www/copo_www/COPO/api', '/var/www/copo_www/COPO/dal', '/var/www/copo_www/COPO/web/project_copo', '/var/www/copo_www/COPO/web/project_copo/settings', '/var/www/copo_www/COPO/web/apps']
[12/Aug/2015 13:46:42] INFO [requests.packages.urllib3.connectionpool:735] Starting new HTTPS connection (1): pub.orcid.org
[12/Aug/2015 13:46:44] DEBUG [requests.packages.urllib3.connectionpool:383] "POST /oauth/token HTTP/1.1" 200 None
[12/Aug/2015 13:46:44] INFO [requests.packages.urllib3.connectionpool:203] Starting new HTTP connection (1): pub.orcid.org
[12/Aug/2015 13:46:44] DEBUG [requests.packages.urllib3.connectionpool:383] "GET /v1.2/0000-0001-9649-5906/orcid-profile HTTP/1.1" 200 None
[12/Aug/2015 13:47:02] INFO [requests.packages.urllib3.connectionpool:203] Starting new HTTP connection (1): v0514.nbi.ac.uk
[12/Aug/2015 13:47:02] DEBUG [requests.packages.urllib3.connectionpool:383] "GET /id/ HTTP/1.1" 200 None
[12/Aug/2015 13:47:25] ERROR [django.request:231] Internal Server Error: /copo/new_collection/
Traceback (most recent call last):
  File "/Users/fshaw/Documents/dev/environments/copo_python3.4/lib/python3.4/site-packages/django/core/handlers/base.py", line 111, in get_response
    response = wrapped_callback(request, *callback_args, **callback_kwargs)
  File "/Users/fshaw/Documents/dev/environments/copo_python3.4/lib/python3.4/site-packages/django/contrib/auth/decorators.py", line 21, in _wrapped_view
    return view_func(request, *args, **kwargs)
  File "/Users/fshaw/Dropbox/tgac_dev/prototypes/COPO/web/apps/web_copo/views.py", line 174, in new_collection_head
    Collection_Head().update(collection_head_id, collection_head_dc)
  File "/Users/fshaw/Dropbox/tgac_dev/prototypes/COPO/dal/copo_base_da.py", line 104, in update
    Collection_Heads().update(
  File "/Users/fshaw/Documents/dev/environments/copo_python3.4/lib/python3.4/site-packages/pymongo/collection.py", line 2066, in __call__
    self.__name)
TypeError: 'Collection' object is not callable. If you meant to call the 'CollectionHeads' method on a 'Database' object it is failing because no such method exists.
[12/Aug/2015 13:47:25] WARNING [django.request:143] Not Found: /favicon.ico
[12/Aug/2015 13:48:34] ERROR [django.request:231] Internal Server Error: /copo/new_collection/
Traceback (most recent call last):
  File "/Users/fshaw/Documents/dev/environments/copo_python3.4/lib/python3.4/site-packages/django/core/handlers/base.py", line 111, in get_response
    response = wrapped_callback(request, *callback_args, **callback_kwargs)
  File "/Users/fshaw/Documents/dev/environments/copo_python3.4/lib/python3.4/site-packages/django/contrib/auth/decorators.py", line 21, in _wrapped_view
    return view_func(request, *args, **kwargs)
  File "/Users/fshaw/Dropbox/tgac_dev/prototypes/COPO/web/apps/web_copo/views.py", line 174, in new_collection_head
    Collection_Head().update(collection_head_id, collection_head_dc)
  File "/Users/fshaw/Dropbox/tgac_dev/prototypes/COPO/dal/copo_base_da.py", line 104, in update
    Collection_Heads().update(
  File "/Users/fshaw/Documents/dev/environments/copo_python3.4/lib/python3.4/site-packages/pymongo/collection.py", line 2066, in __call__
    self.__name)
TypeError: 'Collection' object is not callable. If you meant to call the 'CollectionHeads' method on a 'Database' object it is failing because no such method exists.
[12/Aug/2015 13:50:52] DEBUG [web_copo.views:19] ['/Users/fshaw/Dropbox/tgac_dev/prototypes/COPO/web', '/Applications/PyCharm.app/Contents/helpers/pydev', '/Users/fshaw/Dropbox/tgac_dev/prototypes/COPO/web/project_copo/settings', '/Users/fshaw/Dropbox/tgac_dev/prototypes/COPO', '/Users/fshaw/Dropbox/tgac_dev/prototypes/COPO/dal', '/Users/fshaw/Dropbox/tgac_dev/prototypes/COPO/web/apps', '/Users/fshaw/Dropbox/tgac_dev/prototypes/COPO/api', '/Users/fshaw/Dropbox/tgac_dev/prototypes/COPO/web/project_copo', '/Users/fshaw/Documents/dev/environments/copo_python3.4/lib/python34.zip', '/Users/fshaw/Documents/dev/environments/copo_python3.4/lib/python3.4', '/Users/fshaw/Documents/dev/environments/copo_python3.4/lib/python3.4/plat-darwin', '/Users/fshaw/Documents/dev/environments/copo_python3.4/lib/python3.4/lib-dynload', '/Library/Frameworks/Python.framework/Versions/3.4/lib/python3.4', '/Library/Frameworks/Python.framework/Versions/3.4/lib/python3.4/plat-darwin', '/Users/fshaw/Documents/dev/environments/copo_python3.4/lib/python3.4/site-packages', '/Users/fshaw/Dropbox/tgac_dev/prototypes/COPO', '/Users/fshaw/Dropbox/tgac_dev/prototypes/COPO/api', '/Users/fshaw/Dropbox/tgac_dev/prototypes/COPO/dal', '/Users/fshaw/Dropbox/tgac_dev/prototypes/COPO/web/project_copo', '/Users/fshaw/Dropbox/tgac_dev/prototypes/COPO/web/project_copo/settings', '/Users/fshaw/Dropbox/tgac_dev/prototypes/COPO/web/apps', '/var/www/copo_www/COPO/', '/var/www/copo_www/COPO/api', '/var/www/copo_www/COPO/dal', '/var/www/copo_www/COPO/web/project_copo', '/var/www/copo_www/COPO/web/project_copo/settings', '/var/www/copo_www/COPO/web/apps']
[12/Aug/2015 13:57:48] DEBUG [web_copo.views:19] ['/Users/fshaw/Dropbox/tgac_dev/prototypes/COPO/web', '/Applications/PyCharm.app/Contents/helpers/pydev', '/Users/fshaw/Dropbox/tgac_dev/prototypes/COPO/web/project_copo/settings', '/Users/fshaw/Dropbox/tgac_dev/prototypes/COPO', '/Users/fshaw/Dropbox/tgac_dev/prototypes/COPO/dal', '/Users/fshaw/Dropbox/tgac_dev/prototypes/COPO/web/apps', '/Users/fshaw/Dropbox/tgac_dev/prototypes/COPO/api', '/Users/fshaw/Dropbox/tgac_dev/prototypes/COPO/web/project_copo', '/Users/fshaw/Documents/dev/environments/copo_python3.4/lib/python34.zip', '/Users/fshaw/Documents/dev/environments/copo_python3.4/lib/python3.4', '/Users/fshaw/Documents/dev/environments/copo_python3.4/lib/python3.4/plat-darwin', '/Users/fshaw/Documents/dev/environments/copo_python3.4/lib/python3.4/lib-dynload', '/Library/Frameworks/Python.framework/Versions/3.4/lib/python3.4', '/Library/Frameworks/Python.framework/Versions/3.4/lib/python3.4/plat-darwin', '/Users/fshaw/Documents/dev/environments/copo_python3.4/lib/python3.4/site-packages', '/Users/fshaw/Dropbox/tgac_dev/prototypes/COPO', '/Users/fshaw/Dropbox/tgac_dev/prototypes/COPO/api', '/Users/fshaw/Dropbox/tgac_dev/prototypes/COPO/dal', '/Users/fshaw/Dropbox/tgac_dev/prototypes/COPO/web/project_copo', '/Users/fshaw/Dropbox/tgac_dev/prototypes/COPO/web/project_copo/settings', '/Users/fshaw/Dropbox/tgac_dev/prototypes/COPO/web/apps', '/var/www/copo_www/COPO/', '/var/www/copo_www/COPO/api', '/var/www/copo_www/COPO/dal', '/var/www/copo_www/COPO/web/project_copo', '/var/www/copo_www/COPO/web/project_copo/settings', '/var/www/copo_www/COPO/web/apps']
[12/Aug/2015 13:59:21] DEBUG [web_copo.views:19] ['/Users/fshaw/Dropbox/tgac_dev/prototypes/COPO/web', '/Applications/PyCharm.app/Contents/helpers/pydev', '/Users/fshaw/Dropbox/tgac_dev/prototypes/COPO/web/project_copo/settings', '/Users/fshaw/Dropbox/tgac_dev/prototypes/COPO', '/Users/fshaw/Dropbox/tgac_dev/prototypes/COPO/dal', '/Users/fshaw/Dropbox/tgac_dev/prototypes/COPO/web/apps', '/Users/fshaw/Dropbox/tgac_dev/prototypes/COPO/api', '/Users/fshaw/Dropbox/tgac_dev/prototypes/COPO/web/project_copo', '/Users/fshaw/Documents/dev/environments/copo_python3.4/lib/python34.zip', '/Users/fshaw/Documents/dev/environments/copo_python3.4/lib/python3.4', '/Users/fshaw/Documents/dev/environments/copo_python3.4/lib/python3.4/plat-darwin', '/Users/fshaw/Documents/dev/environments/copo_python3.4/lib/python3.4/lib-dynload', '/Library/Frameworks/Python.framework/Versions/3.4/lib/python3.4', '/Library/Frameworks/Python.framework/Versions/3.4/lib/python3.4/plat-darwin', '/Users/fshaw/Documents/dev/environments/copo_python3.4/lib/python3.4/site-packages', '/Users/fshaw/Dropbox/tgac_dev/prototypes/COPO', '/Users/fshaw/Dropbox/tgac_dev/prototypes/COPO/api', '/Users/fshaw/Dropbox/tgac_dev/prototypes/COPO/dal', '/Users/fshaw/Dropbox/tgac_dev/prototypes/COPO/web/project_copo', '/Users/fshaw/Dropbox/tgac_dev/prototypes/COPO/web/project_copo/settings', '/Users/fshaw/Dropbox/tgac_dev/prototypes/COPO/web/apps', '/var/www/copo_www/COPO/', '/var/www/copo_www/COPO/api', '/var/www/copo_www/COPO/dal', '/var/www/copo_www/COPO/web/project_copo', '/var/www/copo_www/COPO/web/project_copo/settings', '/var/www/copo_www/COPO/web/apps']
[12/Aug/2015 13:59:22] ERROR [django.request:231] Internal Server Error: /copo/new_collection/
Traceback (most recent call last):
  File "/Users/fshaw/Documents/dev/environments/copo_python3.4/lib/python3.4/site-packages/django/utils/datastructures.py", line 317, in __getitem__
    list_ = super(MultiValueDict, self).__getitem__(key)
KeyError: 'collection_type'

During handling of the above exception, another exception occurred:

Traceback (most recent call last):
  File "/Users/fshaw/Documents/dev/environments/copo_python3.4/lib/python3.4/site-packages/django/core/handlers/base.py", line 111, in get_response
    response = wrapped_callback(request, *callback_args, **callback_kwargs)
  File "/Users/fshaw/Documents/dev/environments/copo_python3.4/lib/python3.4/site-packages/django/contrib/auth/decorators.py", line 21, in _wrapped_view
    return view_func(request, *args, **kwargs)
  File "/Users/fshaw/Dropbox/tgac_dev/prototypes/COPO/web/apps/web_copo/views.py", line 170, in new_collection_head
    c_type = request.POST['collection_type']
  File "/Users/fshaw/Documents/dev/environments/copo_python3.4/lib/python3.4/site-packages/django/utils/datastructures.py", line 319, in __getitem__
    raise MultiValueDictKeyError(repr(key))
django.utils.datastructures.MultiValueDictKeyError: "'collection_type'"
[12/Aug/2015 13:59:47] ERROR [django.request:231] Internal Server Error: /copo/new_collection/
Traceback (most recent call last):
  File "/Users/fshaw/Documents/dev/environments/copo_python3.4/lib/python3.4/site-packages/django/utils/datastructures.py", line 317, in __getitem__
    list_ = super(MultiValueDict, self).__getitem__(key)
KeyError: 'collection_type'

During handling of the above exception, another exception occurred:

Traceback (most recent call last):
  File "/Users/fshaw/Documents/dev/environments/copo_python3.4/lib/python3.4/site-packages/django/core/handlers/base.py", line 111, in get_response
    response = wrapped_callback(request, *callback_args, **callback_kwargs)
  File "/Users/fshaw/Documents/dev/environments/copo_python3.4/lib/python3.4/site-packages/django/contrib/auth/decorators.py", line 21, in _wrapped_view
    return view_func(request, *args, **kwargs)
  File "/Users/fshaw/Dropbox/tgac_dev/prototypes/COPO/web/apps/web_copo/views.py", line 170, in new_collection_head
    c_type = request.POST['collection_type']
  File "/Users/fshaw/Documents/dev/environments/copo_python3.4/lib/python3.4/site-packages/django/utils/datastructures.py", line 319, in __getitem__
    raise MultiValueDictKeyError(repr(key))
django.utils.datastructures.MultiValueDictKeyError: "'collection_type'"
[12/Aug/2015 14:00:07] ERROR [django.request:231] Internal Server Error: /copo/new_collection/
Traceback (most recent call last):
  File "/Users/fshaw/Documents/dev/environments/copo_python3.4/lib/python3.4/site-packages/django/core/handlers/base.py", line 111, in get_response
    response = wrapped_callback(request, *callback_args, **callback_kwargs)
  File "/Users/fshaw/Documents/dev/environments/copo_python3.4/lib/python3.4/site-packages/django/contrib/auth/decorators.py", line 21, in _wrapped_view
    return view_func(request, *args, **kwargs)
  File "/Users/fshaw/Dropbox/tgac_dev/prototypes/COPO/web/apps/web_copo/views.py", line 174, in new_collection_head
    Collection_Head().update(collection_head_id, collection_head_dc)
  File "/Users/fshaw/Dropbox/tgac_dev/prototypes/COPO/dal/copo_base_da.py", line 104, in update
    Collection_Heads().update(
  File "/Users/fshaw/Documents/dev/environments/copo_python3.4/lib/python3.4/site-packages/pymongo/collection.py", line 2066, in __call__
    self.__name)
TypeError: 'Collection' object is not callable. If you meant to call the 'CollectionHeads' method on a 'Database' object it is failing because no such method exists.
[12/Aug/2015 14:01:50] ERROR [django.request:231] Internal Server Error: /copo/new_collection/
Traceback (most recent call last):
  File "/Users/fshaw/Documents/dev/environments/copo_python3.4/lib/python3.4/site-packages/django/core/handlers/base.py", line 111, in get_response
    response = wrapped_callback(request, *callback_args, **callback_kwargs)
  File "/Users/fshaw/Documents/dev/environments/copo_python3.4/lib/python3.4/site-packages/django/contrib/auth/decorators.py", line 21, in _wrapped_view
    return view_func(request, *args, **kwargs)
  File "/Users/fshaw/Dropbox/tgac_dev/prototypes/COPO/web/apps/web_copo/views.py", line 174, in new_collection_head
    Collection_Head().update(collection_head_id, collection_head_dc)
  File "/Users/fshaw/Dropbox/tgac_dev/prototypes/COPO/dal/copo_base_da.py", line 104, in update
    Collection_Heads().update(
  File "/Users/fshaw/Documents/dev/environments/copo_python3.4/lib/python3.4/site-packages/pymongo/collection.py", line 2066, in __call__
    self.__name)
TypeError: 'Collection' object is not callable. If you meant to call the 'CollectionHeads' method on a 'Database' object it is failing because no such method exists.
[12/Aug/2015 14:02:15] DEBUG [web_copo.views:19] ['/Users/fshaw/Dropbox/tgac_dev/prototypes/COPO/web', '/Applications/PyCharm.app/Contents/helpers/pydev', '/Users/fshaw/Dropbox/tgac_dev/prototypes/COPO/web/project_copo/settings', '/Users/fshaw/Dropbox/tgac_dev/prototypes/COPO', '/Users/fshaw/Dropbox/tgac_dev/prototypes/COPO/dal', '/Users/fshaw/Dropbox/tgac_dev/prototypes/COPO/web/apps', '/Users/fshaw/Dropbox/tgac_dev/prototypes/COPO/api', '/Users/fshaw/Dropbox/tgac_dev/prototypes/COPO/web/project_copo', '/Users/fshaw/Documents/dev/environments/copo_python3.4/lib/python34.zip', '/Users/fshaw/Documents/dev/environments/copo_python3.4/lib/python3.4', '/Users/fshaw/Documents/dev/environments/copo_python3.4/lib/python3.4/plat-darwin', '/Users/fshaw/Documents/dev/environments/copo_python3.4/lib/python3.4/lib-dynload', '/Library/Frameworks/Python.framework/Versions/3.4/lib/python3.4', '/Library/Frameworks/Python.framework/Versions/3.4/lib/python3.4/plat-darwin', '/Users/fshaw/Documents/dev/environments/copo_python3.4/lib/python3.4/site-packages', '/Users/fshaw/Dropbox/tgac_dev/prototypes/COPO', '/Users/fshaw/Dropbox/tgac_dev/prototypes/COPO/api', '/Users/fshaw/Dropbox/tgac_dev/prototypes/COPO/dal', '/Users/fshaw/Dropbox/tgac_dev/prototypes/COPO/web/project_copo', '/Users/fshaw/Dropbox/tgac_dev/prototypes/COPO/web/project_copo/settings', '/Users/fshaw/Dropbox/tgac_dev/prototypes/COPO/web/apps', '/var/www/copo_www/COPO/', '/var/www/copo_www/COPO/api', '/var/www/copo_www/COPO/dal', '/var/www/copo_www/COPO/web/project_copo', '/var/www/copo_www/COPO/web/project_copo/settings', '/var/www/copo_www/COPO/web/apps']
[12/Aug/2015 14:02:21] ERROR [django.request:231] Internal Server Error: /copo/new_collection/
Traceback (most recent call last):
  File "/Users/fshaw/Documents/dev/environments/copo_python3.4/lib/python3.4/site-packages/django/core/handlers/base.py", line 111, in get_response
    response = wrapped_callback(request, *callback_args, **callback_kwargs)
  File "/Users/fshaw/Documents/dev/environments/copo_python3.4/lib/python3.4/site-packages/django/contrib/auth/decorators.py", line 21, in _wrapped_view
    return view_func(request, *args, **kwargs)
  File "/Users/fshaw/Dropbox/tgac_dev/prototypes/COPO/web/apps/web_copo/views.py", line 174, in new_collection_head
    Collection_Head().update(collection_head_id, collection_head_dc)
  File "/Users/fshaw/Dropbox/tgac_dev/prototypes/COPO/dal/copo_base_da.py", line 104, in update
    Collections().update(
  File "/Users/fshaw/Documents/dev/environments/copo_python3.4/lib/python3.4/site-packages/pymongo/collection.py", line 2066, in __call__
    self.__name)
TypeError: 'Collection' object is not callable. If you meant to call the 'CollectionHeads' method on a 'Database' object it is failing because no such method exists.
[12/Aug/2015 14:02:39] DEBUG [web_copo.views:19] ['/Users/fshaw/Dropbox/tgac_dev/prototypes/COPO/web', '/Applications/PyCharm.app/Contents/helpers/pydev', '/Users/fshaw/Dropbox/tgac_dev/prototypes/COPO/web/project_copo/settings', '/Users/fshaw/Dropbox/tgac_dev/prototypes/COPO', '/Users/fshaw/Dropbox/tgac_dev/prototypes/COPO/dal', '/Users/fshaw/Dropbox/tgac_dev/prototypes/COPO/web/apps', '/Users/fshaw/Dropbox/tgac_dev/prototypes/COPO/api', '/Users/fshaw/Dropbox/tgac_dev/prototypes/COPO/web/project_copo', '/Users/fshaw/Documents/dev/environments/copo_python3.4/lib/python34.zip', '/Users/fshaw/Documents/dev/environments/copo_python3.4/lib/python3.4', '/Users/fshaw/Documents/dev/environments/copo_python3.4/lib/python3.4/plat-darwin', '/Users/fshaw/Documents/dev/environments/copo_python3.4/lib/python3.4/lib-dynload', '/Library/Frameworks/Python.framework/Versions/3.4/lib/python3.4', '/Library/Frameworks/Python.framework/Versions/3.4/lib/python3.4/plat-darwin', '/Users/fshaw/Documents/dev/environments/copo_python3.4/lib/python3.4/site-packages', '/Users/fshaw/Dropbox/tgac_dev/prototypes/COPO', '/Users/fshaw/Dropbox/tgac_dev/prototypes/COPO/api', '/Users/fshaw/Dropbox/tgac_dev/prototypes/COPO/dal', '/Users/fshaw/Dropbox/tgac_dev/prototypes/COPO/web/project_copo', '/Users/fshaw/Dropbox/tgac_dev/prototypes/COPO/web/project_copo/settings', '/Users/fshaw/Dropbox/tgac_dev/prototypes/COPO/web/apps', '/var/www/copo_www/COPO/', '/var/www/copo_www/COPO/api', '/var/www/copo_www/COPO/dal', '/var/www/copo_www/COPO/web/project_copo', '/var/www/copo_www/COPO/web/project_copo/settings', '/var/www/copo_www/COPO/web/apps']
[12/Aug/2015 14:02:40] ERROR [django.request:231] Internal Server Error: /copo/new_collection/
Traceback (most recent call last):
  File "/Users/fshaw/Documents/dev/environments/copo_python3.4/lib/python3.4/site-packages/django/core/handlers/base.py", line 111, in get_response
    response = wrapped_callback(request, *callback_args, **callback_kwargs)
  File "/Users/fshaw/Documents/dev/environments/copo_python3.4/lib/python3.4/site-packages/django/contrib/auth/decorators.py", line 21, in _wrapped_view
    return view_func(request, *args, **kwargs)
  File "/Users/fshaw/Dropbox/tgac_dev/prototypes/COPO/web/apps/web_copo/views.py", line 174, in new_collection_head
    Collection_Head().update(collection_head_id, collection_head_dc)
  File "/Users/fshaw/Dropbox/tgac_dev/prototypes/COPO/dal/copo_base_da.py", line 104, in update
    Collections().update(
  File "/Users/fshaw/Documents/dev/environments/copo_python3.4/lib/python3.4/site-packages/pymongo/collection.py", line 2066, in __call__
    self.__name)
TypeError: 'Collection' object is not callable. If you meant to call the 'CollectionHeads' method on a 'Database' object it is failing because no such method exists.
[12/Aug/2015 14:04:40] DEBUG [web_copo.views:19] ['/Users/fshaw/Dropbox/tgac_dev/prototypes/COPO/web', '/Applications/PyCharm.app/Contents/helpers/pydev', '/Users/fshaw/Dropbox/tgac_dev/prototypes/COPO/web/project_copo/settings', '/Users/fshaw/Dropbox/tgac_dev/prototypes/COPO', '/Users/fshaw/Dropbox/tgac_dev/prototypes/COPO/dal', '/Users/fshaw/Dropbox/tgac_dev/prototypes/COPO/web/apps', '/Users/fshaw/Dropbox/tgac_dev/prototypes/COPO/api', '/Users/fshaw/Dropbox/tgac_dev/prototypes/COPO/web/project_copo', '/Users/fshaw/Documents/dev/environments/copo_python3.4/lib/python34.zip', '/Users/fshaw/Documents/dev/environments/copo_python3.4/lib/python3.4', '/Users/fshaw/Documents/dev/environments/copo_python3.4/lib/python3.4/plat-darwin', '/Users/fshaw/Documents/dev/environments/copo_python3.4/lib/python3.4/lib-dynload', '/Library/Frameworks/Python.framework/Versions/3.4/lib/python3.4', '/Library/Frameworks/Python.framework/Versions/3.4/lib/python3.4/plat-darwin', '/Users/fshaw/Documents/dev/environments/copo_python3.4/lib/python3.4/site-packages', '/Users/fshaw/Dropbox/tgac_dev/prototypes/COPO', '/Users/fshaw/Dropbox/tgac_dev/prototypes/COPO/api', '/Users/fshaw/Dropbox/tgac_dev/prototypes/COPO/dal', '/Users/fshaw/Dropbox/tgac_dev/prototypes/COPO/web/project_copo', '/Users/fshaw/Dropbox/tgac_dev/prototypes/COPO/web/project_copo/settings', '/Users/fshaw/Dropbox/tgac_dev/prototypes/COPO/web/apps', '/var/www/copo_www/COPO/', '/var/www/copo_www/COPO/api', '/var/www/copo_www/COPO/dal', '/var/www/copo_www/COPO/web/project_copo', '/var/www/copo_www/COPO/web/project_copo/settings', '/var/www/copo_www/COPO/web/apps']
[12/Aug/2015 14:04:41] ERROR [django.request:231] Internal Server Error: /copo/new_collection/
Traceback (most recent call last):
  File "/Users/fshaw/Documents/dev/environments/copo_python3.4/lib/python3.4/site-packages/django/core/handlers/base.py", line 111, in get_response
    response = wrapped_callback(request, *callback_args, **callback_kwargs)
  File "/Users/fshaw/Documents/dev/environments/copo_python3.4/lib/python3.4/site-packages/django/contrib/auth/decorators.py", line 21, in _wrapped_view
    return view_func(request, *args, **kwargs)
  File "/Users/fshaw/Dropbox/tgac_dev/prototypes/COPO/web/apps/web_copo/views.py", line 172, in new_collection_head
    collection_head_id = Collection_Head().PUT(c_type, c_name)
  File "/Users/fshaw/Dropbox/tgac_dev/prototypes/COPO/dal/copo_base_da.py", line 100, in PUT
    return Collections().insert(spec)
  File "/Users/fshaw/Documents/dev/environments/copo_python3.4/lib/python3.4/site-packages/pymongo/collection.py", line 2066, in __call__
    self.__name)
TypeError: 'Collection' object is not callable. If you meant to call the 'CollectionHeads' method on a 'Database' object it is failing because no such method exists.
[12/Aug/2015 14:06:20] DEBUG [web_copo.views:19] ['/Users/fshaw/Dropbox/tgac_dev/prototypes/COPO/web', '/Applications/PyCharm.app/Contents/helpers/pydev', '/Users/fshaw/Dropbox/tgac_dev/prototypes/COPO/web/project_copo/settings', '/Users/fshaw/Dropbox/tgac_dev/prototypes/COPO', '/Users/fshaw/Dropbox/tgac_dev/prototypes/COPO/dal', '/Users/fshaw/Dropbox/tgac_dev/prototypes/COPO/web/apps', '/Users/fshaw/Dropbox/tgac_dev/prototypes/COPO/api', '/Users/fshaw/Dropbox/tgac_dev/prototypes/COPO/web/project_copo', '/Users/fshaw/Documents/dev/environments/copo_python3.4/lib/python34.zip', '/Users/fshaw/Documents/dev/environments/copo_python3.4/lib/python3.4', '/Users/fshaw/Documents/dev/environments/copo_python3.4/lib/python3.4/plat-darwin', '/Users/fshaw/Documents/dev/environments/copo_python3.4/lib/python3.4/lib-dynload', '/Library/Frameworks/Python.framework/Versions/3.4/lib/python3.4', '/Library/Frameworks/Python.framework/Versions/3.4/lib/python3.4/plat-darwin', '/Users/fshaw/Documents/dev/environments/copo_python3.4/lib/python3.4/site-packages', '/Users/fshaw/Dropbox/tgac_dev/prototypes/COPO', '/Users/fshaw/Dropbox/tgac_dev/prototypes/COPO/api', '/Users/fshaw/Dropbox/tgac_dev/prototypes/COPO/dal', '/Users/fshaw/Dropbox/tgac_dev/prototypes/COPO/web/project_copo', '/Users/fshaw/Dropbox/tgac_dev/prototypes/COPO/web/project_copo/settings', '/Users/fshaw/Dropbox/tgac_dev/prototypes/COPO/web/apps', '/var/www/copo_www/COPO/', '/var/www/copo_www/COPO/api', '/var/www/copo_www/COPO/dal', '/var/www/copo_www/COPO/web/project_copo', '/var/www/copo_www/COPO/web/project_copo/settings', '/var/www/copo_www/COPO/web/apps']
[12/Aug/2015 14:06:21] ERROR [django.request:231] Internal Server Error: /copo/new_collection/
Traceback (most recent call last):
  File "/Users/fshaw/Documents/dev/environments/copo_python3.4/lib/python3.4/site-packages/django/utils/datastructures.py", line 317, in __getitem__
    list_ = super(MultiValueDict, self).__getitem__(key)
KeyError: 'collection_type'

During handling of the above exception, another exception occurred:

Traceback (most recent call last):
  File "/Users/fshaw/Documents/dev/environments/copo_python3.4/lib/python3.4/site-packages/django/core/handlers/base.py", line 111, in get_response
    response = wrapped_callback(request, *callback_args, **callback_kwargs)
  File "/Users/fshaw/Documents/dev/environments/copo_python3.4/lib/python3.4/site-packages/django/contrib/auth/decorators.py", line 21, in _wrapped_view
    return view_func(request, *args, **kwargs)
  File "/Users/fshaw/Dropbox/tgac_dev/prototypes/COPO/web/apps/web_copo/views.py", line 170, in new_collection_head
    c_type = request.POST['collection_type']
  File "/Users/fshaw/Documents/dev/environments/copo_python3.4/lib/python3.4/site-packages/django/utils/datastructures.py", line 319, in __getitem__
    raise MultiValueDictKeyError(repr(key))
django.utils.datastructures.MultiValueDictKeyError: "'collection_type'"
[12/Aug/2015 14:06:29] ERROR [django.request:231] Internal Server Error: /copo/new_collection/
Traceback (most recent call last):
  File "/Users/fshaw/Documents/dev/environments/copo_python3.4/lib/python3.4/site-packages/django/utils/datastructures.py", line 317, in __getitem__
    list_ = super(MultiValueDict, self).__getitem__(key)
KeyError: 'collection_type'

During handling of the above exception, another exception occurred:

Traceback (most recent call last):
  File "/Users/fshaw/Documents/dev/environments/copo_python3.4/lib/python3.4/site-packages/django/core/handlers/base.py", line 111, in get_response
    response = wrapped_callback(request, *callback_args, **callback_kwargs)
  File "/Users/fshaw/Documents/dev/environments/copo_python3.4/lib/python3.4/site-packages/django/contrib/auth/decorators.py", line 21, in _wrapped_view
    return view_func(request, *args, **kwargs)
  File "/Users/fshaw/Dropbox/tgac_dev/prototypes/COPO/web/apps/web_copo/views.py", line 170, in new_collection_head
    c_type = request.POST['collection_type']
  File "/Users/fshaw/Documents/dev/environments/copo_python3.4/lib/python3.4/site-packages/django/utils/datastructures.py", line 319, in __getitem__
    raise MultiValueDictKeyError(repr(key))
django.utils.datastructures.MultiValueDictKeyError: "'collection_type'"
[12/Aug/2015 14:06:38] ERROR [django.request:231] Internal Server Error: /copo/new_collection/
Traceback (most recent call last):
  File "/Users/fshaw/Documents/dev/environments/copo_python3.4/lib/python3.4/site-packages/django/utils/datastructures.py", line 317, in __getitem__
    list_ = super(MultiValueDict, self).__getitem__(key)
KeyError: 'collection_type'

During handling of the above exception, another exception occurred:

Traceback (most recent call last):
  File "/Users/fshaw/Documents/dev/environments/copo_python3.4/lib/python3.4/site-packages/django/core/handlers/base.py", line 111, in get_response
    response = wrapped_callback(request, *callback_args, **callback_kwargs)
  File "/Users/fshaw/Documents/dev/environments/copo_python3.4/lib/python3.4/site-packages/django/contrib/auth/decorators.py", line 21, in _wrapped_view
    return view_func(request, *args, **kwargs)
  File "/Users/fshaw/Dropbox/tgac_dev/prototypes/COPO/web/apps/web_copo/views.py", line 170, in new_collection_head
    c_type = request.POST['collection_type']
  File "/Users/fshaw/Documents/dev/environments/copo_python3.4/lib/python3.4/site-packages/django/utils/datastructures.py", line 319, in __getitem__
    raise MultiValueDictKeyError(repr(key))
django.utils.datastructures.MultiValueDictKeyError: "'collection_type'"
[12/Aug/2015 14:07:07] ERROR [django.request:231] Internal Server Error: /copo/profile/55cb4e56453d9a037223f012/view
Traceback (most recent call last):
  File "/Users/fshaw/Dropbox/tgac_dev/prototypes/COPO/web/apps/web_copo/templatetags/web_tags.py", line 10, in mongo_id
    return str(value['_id']['$oid'])
TypeError: 'NoneType' object is not subscriptable

During handling of the above exception, another exception occurred:

Traceback (most recent call last):
  File "/Users/fshaw/Documents/dev/environments/copo_python3.4/lib/python3.4/site-packages/django/core/handlers/base.py", line 111, in get_response
    response = wrapped_callback(request, *callback_args, **callback_kwargs)
  File "/Users/fshaw/Documents/dev/environments/copo_python3.4/lib/python3.4/site-packages/django/contrib/auth/decorators.py", line 21, in _wrapped_view
    return view_func(request, *args, **kwargs)
  File "/Users/fshaw/Dropbox/tgac_dev/prototypes/COPO/web/apps/web_copo/views.py", line 164, in view_profile
    return render(request, 'copo/profile.html', context)
  File "/Users/fshaw/Documents/dev/environments/copo_python3.4/lib/python3.4/site-packages/django/shortcuts.py", line 50, in render
    return HttpResponse(loader.render_to_string(*args, **kwargs),
  File "/Users/fshaw/Documents/dev/environments/copo_python3.4/lib/python3.4/site-packages/django/template/loader.py", line 178, in render_to_string
    return t.render(context_instance)
  File "/Users/fshaw/Documents/dev/environments/copo_python3.4/lib/python3.4/site-packages/django/template/base.py", line 148, in render
    return self._render(context)
  File "/Users/fshaw/Documents/dev/environments/copo_python3.4/lib/python3.4/site-packages/django/template/base.py", line 142, in _render
    return self.nodelist.render(context)
  File "/Users/fshaw/Documents/dev/environments/copo_python3.4/lib/python3.4/site-packages/django/template/base.py", line 844, in render
    bit = self.render_node(node, context)
  File "/Users/fshaw/Documents/dev/environments/copo_python3.4/lib/python3.4/site-packages/django/template/debug.py", line 80, in render_node
    return node.render(context)
  File "/Users/fshaw/Documents/dev/environments/copo_python3.4/lib/python3.4/site-packages/django/template/loader_tags.py", line 126, in render
    return compiled_parent._render(context)
  File "/Users/fshaw/Documents/dev/environments/copo_python3.4/lib/python3.4/site-packages/django/template/base.py", line 142, in _render
    return self.nodelist.render(context)
  File "/Users/fshaw/Documents/dev/environments/copo_python3.4/lib/python3.4/site-packages/django/template/base.py", line 844, in render
    bit = self.render_node(node, context)
  File "/Users/fshaw/Documents/dev/environments/copo_python3.4/lib/python3.4/site-packages/django/template/debug.py", line 80, in render_node
    return node.render(context)
  File "/Users/fshaw/Documents/dev/environments/copo_python3.4/lib/python3.4/site-packages/django/template/loader_tags.py", line 65, in render
    result = block.nodelist.render(context)
  File "/Users/fshaw/Documents/dev/environments/copo_python3.4/lib/python3.4/site-packages/django/template/base.py", line 844, in render
    bit = self.render_node(node, context)
  File "/Users/fshaw/Documents/dev/environments/copo_python3.4/lib/python3.4/site-packages/django/template/debug.py", line 80, in render_node
    return node.render(context)
  File "/Users/fshaw/Documents/dev/environments/copo_python3.4/lib/python3.4/site-packages/django/template/defaulttags.py", line 312, in render
    return nodelist.render(context)
  File "/Users/fshaw/Documents/dev/environments/copo_python3.4/lib/python3.4/site-packages/django/template/base.py", line 844, in render
    bit = self.render_node(node, context)
  File "/Users/fshaw/Documents/dev/environments/copo_python3.4/lib/python3.4/site-packages/django/template/debug.py", line 80, in render_node
    return node.render(context)
  File "/Users/fshaw/Documents/dev/environments/copo_python3.4/lib/python3.4/site-packages/django/template/defaulttags.py", line 201, in render
    nodelist.append(node.render(context))
  File "/Users/fshaw/Documents/dev/environments/copo_python3.4/lib/python3.4/site-packages/django/template/debug.py", line 90, in render
    output = self.filter_expression.resolve(context)
  File "/Users/fshaw/Documents/dev/environments/copo_python3.4/lib/python3.4/site-packages/django/template/base.py", line 624, in resolve
    new_obj = func(obj, *arg_vals)
  File "/Users/fshaw/Dropbox/tgac_dev/prototypes/COPO/web/apps/web_copo/templatetags/web_tags.py", line 12, in mongo_id
    return str(value['_id'])
TypeError: 'NoneType' object is not subscriptable
