[06/Aug/2015 15:09:58] ERROR [django.request:231] Internal Server Error: /rest/check_figshare_credentials/
Traceback (most recent call last):
  File "/Users/fshaw/Documents/dev/environments/copo_python3.4/lib/python3.4/site-packages/django/core/handlers/base.py", line 111, in get_response
    response = wrapped_callback(request, *callback_args, **callback_kwargs)
  File "/Users/fshaw/Dropbox/tgac_dev/prototypes/COPO/web/apps/web_copo/repos/figshare.py", line 103, in check_figshare_credentials
    if (Figshare_token().token_exists()):
NameError: name 'Figshare_token' is not defined
[06/Aug/2015 15:10:06] ERROR [django.request:231] Internal Server Error: /rest/check_figshare_credentials/
Traceback (most recent call last):
  File "/Users/fshaw/Documents/dev/environments/copo_python3.4/lib/python3.4/site-packages/django/core/handlers/base.py", line 111, in get_response
    response = wrapped_callback(request, *callback_args, **callback_kwargs)
  File "/Users/fshaw/Dropbox/tgac_dev/prototypes/COPO/web/apps/web_copo/repos/figshare.py", line 103, in check_figshare_credentials
    if (Figshare_token().token_exists()):
NameError: name 'Figshare_token' is not defined
[06/Aug/2015 15:10:17] ERROR [django.request:231] Internal Server Error: /rest/check_figshare_credentials/
Traceback (most recent call last):
  File "/Users/fshaw/Documents/dev/environments/copo_python3.4/lib/python3.4/site-packages/django/core/handlers/base.py", line 111, in get_response
    response = wrapped_callback(request, *callback_args, **callback_kwargs)
  File "/Users/fshaw/Dropbox/tgac_dev/prototypes/COPO/web/apps/web_copo/repos/figshare.py", line 103, in check_figshare_credentials
    if (Figshare_token().token_exists()):
NameError: name 'Figshare_token' is not defined
