[04/Aug/2015 15:19:32] ERROR [django.request:231] Internal Server Error: /accounts/email/
Traceback (most recent call last):
  File "/Users/fshaw/Dropbox/tgac_dev/prototypes/COPO/web/apps/allauth/account/managers.py", line 15, in add_email
    email_address = self.get(user=user, email__iexact=email)
  File "/Users/fshaw/Documents/dev/environments/copo_python3.4/lib/python3.4/site-packages/django/db/models/manager.py", line 92, in manager_method
    return getattr(self.get_queryset(), name)(*args, **kwargs)
  File "/Users/fshaw/Documents/dev/environments/copo_python3.4/lib/python3.4/site-packages/django/db/models/query.py", line 357, in get
    self.model._meta.object_name)
allauth.account.models.DoesNotExist: EmailAddress matching query does not exist.

During handling of the above exception, another exception occurred:

Traceback (most recent call last):
  File "/Users/fshaw/Documents/dev/environments/copo_python3.4/lib/python3.4/site-packages/django/contrib/sites/models.py", line 52, in get_current
    current_site = SITE_CACHE[sid]
KeyError: 2

During handling of the above exception, another exception occurred:

Traceback (most recent call last):
  File "/Users/fshaw/Documents/dev/environments/copo_python3.4/lib/python3.4/site-packages/django/core/handlers/base.py", line 111, in get_response
    response = wrapped_callback(request, *callback_args, **callback_kwargs)
  File "/Users/fshaw/Documents/dev/environments/copo_python3.4/lib/python3.4/site-packages/django/contrib/auth/decorators.py", line 21, in _wrapped_view
    return view_func(request, *args, **kwargs)
  File "/Users/fshaw/Documents/dev/environments/copo_python3.4/lib/python3.4/site-packages/django/views/generic/base.py", line 69, in view
    return self.dispatch(request, *args, **kwargs)
  File "/Users/fshaw/Dropbox/tgac_dev/prototypes/COPO/web/apps/allauth/account/views.py", line 311, in dispatch
    return super(EmailView, self).dispatch(request, *args, **kwargs)
  File "/Users/fshaw/Documents/dev/environments/copo_python3.4/lib/python3.4/site-packages/django/views/generic/base.py", line 87, in dispatch
    return handler(request, *args, **kwargs)
  File "/Users/fshaw/Dropbox/tgac_dev/prototypes/COPO/web/apps/allauth/account/views.py", line 334, in post
    res = super(EmailView, self).post(request, *args, **kwargs)
  File "/Users/fshaw/Dropbox/tgac_dev/prototypes/COPO/web/apps/allauth/account/views.py", line 78, in post
    response = self.form_valid(form)
  File "/Users/fshaw/Dropbox/tgac_dev/prototypes/COPO/web/apps/allauth/account/views.py", line 319, in form_valid
    email_address = form.save(self.request)
  File "/Users/fshaw/Dropbox/tgac_dev/prototypes/COPO/web/apps/allauth/account/forms.py", line 357, in save
    confirm=True)
  File "/Users/fshaw/Dropbox/tgac_dev/prototypes/COPO/web/apps/allauth/account/managers.py", line 20, in add_email
    signup=signup)
  File "/Users/fshaw/Dropbox/tgac_dev/prototypes/COPO/web/apps/allauth/account/models.py", line 61, in send_confirmation
    confirmation.send(request, signup=signup)
  File "/Users/fshaw/Dropbox/tgac_dev/prototypes/COPO/web/apps/allauth/account/models.py", line 121, in send
    else Site.objects.get_current()
  File "/Users/fshaw/Documents/dev/environments/copo_python3.4/lib/python3.4/site-packages/django/contrib/sites/models.py", line 54, in get_current
    current_site = self.get(pk=sid)
  File "/Users/fshaw/Documents/dev/environments/copo_python3.4/lib/python3.4/site-packages/django/db/models/manager.py", line 92, in manager_method
    return getattr(self.get_queryset(), name)(*args, **kwargs)
  File "/Users/fshaw/Documents/dev/environments/copo_python3.4/lib/python3.4/site-packages/django/db/models/query.py", line 357, in get
    self.model._meta.object_name)
django.contrib.sites.models.DoesNotExist: Site matching query does not exist.
[04/Aug/2015 15:19:33] ERROR [django.request:231] Internal Server Error: /accounts/email/
Traceback (most recent call last):
  File "/Users/fshaw/Documents/dev/environments/copo_python3.4/lib/python3.4/site-packages/django/contrib/sites/models.py", line 52, in get_current
    current_site = SITE_CACHE[sid]
KeyError: 2

During handling of the above exception, another exception occurred:

Traceback (most recent call last):
  File "/Users/fshaw/Documents/dev/environments/copo_python3.4/lib/python3.4/site-packages/django/core/handlers/base.py", line 111, in get_response
    response = wrapped_callback(request, *callback_args, **callback_kwargs)
  File "/Users/fshaw/Documents/dev/environments/copo_python3.4/lib/python3.4/site-packages/django/contrib/auth/decorators.py", line 21, in _wrapped_view
    return view_func(request, *args, **kwargs)
  File "/Users/fshaw/Documents/dev/environments/copo_python3.4/lib/python3.4/site-packages/django/views/generic/base.py", line 69, in view
    return self.dispatch(request, *args, **kwargs)
  File "/Users/fshaw/Dropbox/tgac_dev/prototypes/COPO/web/apps/allauth/account/views.py", line 311, in dispatch
    return super(EmailView, self).dispatch(request, *args, **kwargs)
  File "/Users/fshaw/Documents/dev/environments/copo_python3.4/lib/python3.4/site-packages/django/views/generic/base.py", line 87, in dispatch
    return handler(request, *args, **kwargs)
  File "/Users/fshaw/Dropbox/tgac_dev/prototypes/COPO/web/apps/allauth/account/views.py", line 337, in post
    res = self._action_send(request)
  File "/Users/fshaw/Dropbox/tgac_dev/prototypes/COPO/web/apps/allauth/account/views.py", line 360, in _action_send
    email_address.send_confirmation(request)
  File "/Users/fshaw/Dropbox/tgac_dev/prototypes/COPO/web/apps/allauth/account/models.py", line 61, in send_confirmation
    confirmation.send(request, signup=signup)
  File "/Users/fshaw/Dropbox/tgac_dev/prototypes/COPO/web/apps/allauth/account/models.py", line 121, in send
    else Site.objects.get_current()
  File "/Users/fshaw/Documents/dev/environments/copo_python3.4/lib/python3.4/site-packages/django/contrib/sites/models.py", line 54, in get_current
    current_site = self.get(pk=sid)
  File "/Users/fshaw/Documents/dev/environments/copo_python3.4/lib/python3.4/site-packages/django/db/models/manager.py", line 92, in manager_method
    return getattr(self.get_queryset(), name)(*args, **kwargs)
  File "/Users/fshaw/Documents/dev/environments/copo_python3.4/lib/python3.4/site-packages/django/db/models/query.py", line 357, in get
    self.model._meta.object_name)
django.contrib.sites.models.DoesNotExist: Site matching query does not exist.
[04/Aug/2015 15:19:34] INFO [requests.packages.urllib3.connectionpool:203] Starting new HTTP connection (1): v0514.nbi.ac.uk
[04/Aug/2015 15:19:34] DEBUG [requests.packages.urllib3.connectionpool:383] "GET /id/ HTTP/1.1" 200 None
[04/Aug/2015 15:21:08] DEBUG [web_copo.views:16] ['--pattern=tests_copo_*.py', '/Users/fshaw/Dropbox/tgac_dev/prototypes/COPO/web', '/Users/fshaw/Dropbox/tgac_dev/prototypes/COPO/web/project_copo/settings', '/Users/fshaw/Dropbox/tgac_dev/prototypes/COPO', '/Users/fshaw/Dropbox/tgac_dev/prototypes/COPO/dal', '/Users/fshaw/Dropbox/tgac_dev/prototypes/COPO/web/apps', '/Users/fshaw/Dropbox/tgac_dev/prototypes/COPO/api', '/Users/fshaw/Dropbox/tgac_dev/prototypes/COPO/web/project_copo', '/Users/fshaw/Documents/dev/environments/copo_python3.4/lib/python34.zip', '/Users/fshaw/Documents/dev/environments/copo_python3.4/lib/python3.4', '/Users/fshaw/Documents/dev/environments/copo_python3.4/lib/python3.4/plat-darwin', '/Users/fshaw/Documents/dev/environments/copo_python3.4/lib/python3.4/lib-dynload', '/Library/Frameworks/Python.framework/Versions/3.4/lib/python3.4', '/Library/Frameworks/Python.framework/Versions/3.4/lib/python3.4/plat-darwin', '/Users/fshaw/Documents/dev/environments/copo_python3.4/lib/python3.4/site-packages', '/Applications/PyCharm.app/Contents/helpers/pycharm']
[04/Aug/2015 15:21:09] ERROR [django.request:231] Internal Server Error: /accounts/email/
Traceback (most recent call last):
  File "/Users/fshaw/Dropbox/tgac_dev/prototypes/COPO/web/apps/allauth/account/managers.py", line 15, in add_email
    email_address = self.get(user=user, email__iexact=email)
  File "/Users/fshaw/Documents/dev/environments/copo_python3.4/lib/python3.4/site-packages/django/db/models/manager.py", line 92, in manager_method
    return getattr(self.get_queryset(), name)(*args, **kwargs)
  File "/Users/fshaw/Documents/dev/environments/copo_python3.4/lib/python3.4/site-packages/django/db/models/query.py", line 357, in get
    self.model._meta.object_name)
allauth.account.models.DoesNotExist: EmailAddress matching query does not exist.

During handling of the above exception, another exception occurred:

Traceback (most recent call last):
  File "/Users/fshaw/Documents/dev/environments/copo_python3.4/lib/python3.4/site-packages/django/contrib/sites/models.py", line 52, in get_current
    current_site = SITE_CACHE[sid]
KeyError: 2

During handling of the above exception, another exception occurred:

Traceback (most recent call last):
  File "/Users/fshaw/Documents/dev/environments/copo_python3.4/lib/python3.4/site-packages/django/core/handlers/base.py", line 111, in get_response
    response = wrapped_callback(request, *callback_args, **callback_kwargs)
  File "/Users/fshaw/Documents/dev/environments/copo_python3.4/lib/python3.4/site-packages/django/contrib/auth/decorators.py", line 21, in _wrapped_view
    return view_func(request, *args, **kwargs)
  File "/Users/fshaw/Documents/dev/environments/copo_python3.4/lib/python3.4/site-packages/django/views/generic/base.py", line 69, in view
    return self.dispatch(request, *args, **kwargs)
  File "/Users/fshaw/Dropbox/tgac_dev/prototypes/COPO/web/apps/allauth/account/views.py", line 311, in dispatch
    return super(EmailView, self).dispatch(request, *args, **kwargs)
  File "/Users/fshaw/Documents/dev/environments/copo_python3.4/lib/python3.4/site-packages/django/views/generic/base.py", line 87, in dispatch
    return handler(request, *args, **kwargs)
  File "/Users/fshaw/Dropbox/tgac_dev/prototypes/COPO/web/apps/allauth/account/views.py", line 334, in post
    res = super(EmailView, self).post(request, *args, **kwargs)
  File "/Users/fshaw/Dropbox/tgac_dev/prototypes/COPO/web/apps/allauth/account/views.py", line 78, in post
    response = self.form_valid(form)
  File "/Users/fshaw/Dropbox/tgac_dev/prototypes/COPO/web/apps/allauth/account/views.py", line 319, in form_valid
    email_address = form.save(self.request)
  File "/Users/fshaw/Dropbox/tgac_dev/prototypes/COPO/web/apps/allauth/account/forms.py", line 357, in save
    confirm=True)
  File "/Users/fshaw/Dropbox/tgac_dev/prototypes/COPO/web/apps/allauth/account/managers.py", line 20, in add_email
    signup=signup)
  File "/Users/fshaw/Dropbox/tgac_dev/prototypes/COPO/web/apps/allauth/account/models.py", line 61, in send_confirmation
    confirmation.send(request, signup=signup)
  File "/Users/fshaw/Dropbox/tgac_dev/prototypes/COPO/web/apps/allauth/account/models.py", line 121, in send
    else Site.objects.get_current()
  File "/Users/fshaw/Documents/dev/environments/copo_python3.4/lib/python3.4/site-packages/django/contrib/sites/models.py", line 54, in get_current
    current_site = self.get(pk=sid)
  File "/Users/fshaw/Documents/dev/environments/copo_python3.4/lib/python3.4/site-packages/django/db/models/manager.py", line 92, in manager_method
    return getattr(self.get_queryset(), name)(*args, **kwargs)
  File "/Users/fshaw/Documents/dev/environments/copo_python3.4/lib/python3.4/site-packages/django/db/models/query.py", line 357, in get
    self.model._meta.object_name)
django.contrib.sites.models.DoesNotExist: Site matching query does not exist.
[04/Aug/2015 15:21:09] ERROR [django.request:231] Internal Server Error: /accounts/email/
Traceback (most recent call last):
  File "/Users/fshaw/Dropbox/tgac_dev/prototypes/COPO/web/apps/allauth/account/managers.py", line 15, in add_email
    email_address = self.get(user=user, email__iexact=email)
  File "/Users/fshaw/Documents/dev/environments/copo_python3.4/lib/python3.4/site-packages/django/db/models/manager.py", line 92, in manager_method
    return getattr(self.get_queryset(), name)(*args, **kwargs)
  File "/Users/fshaw/Documents/dev/environments/copo_python3.4/lib/python3.4/site-packages/django/db/models/query.py", line 357, in get
    self.model._meta.object_name)
allauth.account.models.DoesNotExist: EmailAddress matching query does not exist.

During handling of the above exception, another exception occurred:

Traceback (most recent call last):
  File "/Users/fshaw/Documents/dev/environments/copo_python3.4/lib/python3.4/site-packages/django/contrib/sites/models.py", line 52, in get_current
    current_site = SITE_CACHE[sid]
KeyError: 2

During handling of the above exception, another exception occurred:

Traceback (most recent call last):
  File "/Users/fshaw/Documents/dev/environments/copo_python3.4/lib/python3.4/site-packages/django/core/handlers/base.py", line 111, in get_response
    response = wrapped_callback(request, *callback_args, **callback_kwargs)
  File "/Users/fshaw/Documents/dev/environments/copo_python3.4/lib/python3.4/site-packages/django/contrib/auth/decorators.py", line 21, in _wrapped_view
    return view_func(request, *args, **kwargs)
  File "/Users/fshaw/Documents/dev/environments/copo_python3.4/lib/python3.4/site-packages/django/views/generic/base.py", line 69, in view
    return self.dispatch(request, *args, **kwargs)
  File "/Users/fshaw/Dropbox/tgac_dev/prototypes/COPO/web/apps/allauth/account/views.py", line 311, in dispatch
    return super(EmailView, self).dispatch(request, *args, **kwargs)
  File "/Users/fshaw/Documents/dev/environments/copo_python3.4/lib/python3.4/site-packages/django/views/generic/base.py", line 87, in dispatch
    return handler(request, *args, **kwargs)
  File "/Users/fshaw/Dropbox/tgac_dev/prototypes/COPO/web/apps/allauth/account/views.py", line 334, in post
    res = super(EmailView, self).post(request, *args, **kwargs)
  File "/Users/fshaw/Dropbox/tgac_dev/prototypes/COPO/web/apps/allauth/account/views.py", line 78, in post
    response = self.form_valid(form)
  File "/Users/fshaw/Dropbox/tgac_dev/prototypes/COPO/web/apps/allauth/account/views.py", line 319, in form_valid
    email_address = form.save(self.request)
  File "/Users/fshaw/Dropbox/tgac_dev/prototypes/COPO/web/apps/allauth/account/forms.py", line 357, in save
    confirm=True)
  File "/Users/fshaw/Dropbox/tgac_dev/prototypes/COPO/web/apps/allauth/account/managers.py", line 20, in add_email
    signup=signup)
  File "/Users/fshaw/Dropbox/tgac_dev/prototypes/COPO/web/apps/allauth/account/models.py", line 61, in send_confirmation
    confirmation.send(request, signup=signup)
  File "/Users/fshaw/Dropbox/tgac_dev/prototypes/COPO/web/apps/allauth/account/models.py", line 121, in send
    else Site.objects.get_current()
  File "/Users/fshaw/Documents/dev/environments/copo_python3.4/lib/python3.4/site-packages/django/contrib/sites/models.py", line 54, in get_current
    current_site = self.get(pk=sid)
  File "/Users/fshaw/Documents/dev/environments/copo_python3.4/lib/python3.4/site-packages/django/db/models/manager.py", line 92, in manager_method
    return getattr(self.get_queryset(), name)(*args, **kwargs)
  File "/Users/fshaw/Documents/dev/environments/copo_python3.4/lib/python3.4/site-packages/django/db/models/query.py", line 357, in get
    self.model._meta.object_name)
django.contrib.sites.models.DoesNotExist: Site matching query does not exist.
[04/Aug/2015 15:21:10] ERROR [django.request:231] Internal Server Error: /accounts/email/
Traceback (most recent call last):
  File "/Users/fshaw/Documents/dev/environments/copo_python3.4/lib/python3.4/site-packages/django/contrib/sites/models.py", line 52, in get_current
    current_site = SITE_CACHE[sid]
KeyError: 2

During handling of the above exception, another exception occurred:

Traceback (most recent call last):
  File "/Users/fshaw/Documents/dev/environments/copo_python3.4/lib/python3.4/site-packages/django/core/handlers/base.py", line 111, in get_response
    response = wrapped_callback(request, *callback_args, **callback_kwargs)
  File "/Users/fshaw/Documents/dev/environments/copo_python3.4/lib/python3.4/site-packages/django/contrib/auth/decorators.py", line 21, in _wrapped_view
    return view_func(request, *args, **kwargs)
  File "/Users/fshaw/Documents/dev/environments/copo_python3.4/lib/python3.4/site-packages/django/views/generic/base.py", line 69, in view
    return self.dispatch(request, *args, **kwargs)
  File "/Users/fshaw/Dropbox/tgac_dev/prototypes/COPO/web/apps/allauth/account/views.py", line 311, in dispatch
    return super(EmailView, self).dispatch(request, *args, **kwargs)
  File "/Users/fshaw/Documents/dev/environments/copo_python3.4/lib/python3.4/site-packages/django/views/generic/base.py", line 87, in dispatch
    return handler(request, *args, **kwargs)
  File "/Users/fshaw/Dropbox/tgac_dev/prototypes/COPO/web/apps/allauth/account/views.py", line 337, in post
    res = self._action_send(request)
  File "/Users/fshaw/Dropbox/tgac_dev/prototypes/COPO/web/apps/allauth/account/views.py", line 360, in _action_send
    email_address.send_confirmation(request)
  File "/Users/fshaw/Dropbox/tgac_dev/prototypes/COPO/web/apps/allauth/account/models.py", line 61, in send_confirmation
    confirmation.send(request, signup=signup)
  File "/Users/fshaw/Dropbox/tgac_dev/prototypes/COPO/web/apps/allauth/account/models.py", line 121, in send
    else Site.objects.get_current()
  File "/Users/fshaw/Documents/dev/environments/copo_python3.4/lib/python3.4/site-packages/django/contrib/sites/models.py", line 54, in get_current
    current_site = self.get(pk=sid)
  File "/Users/fshaw/Documents/dev/environments/copo_python3.4/lib/python3.4/site-packages/django/db/models/manager.py", line 92, in manager_method
    return getattr(self.get_queryset(), name)(*args, **kwargs)
  File "/Users/fshaw/Documents/dev/environments/copo_python3.4/lib/python3.4/site-packages/django/db/models/query.py", line 357, in get
    self.model._meta.object_name)
django.contrib.sites.models.DoesNotExist: Site matching query does not exist.
[04/Aug/2015 15:21:10] INFO [requests.packages.urllib3.connectionpool:203] Starting new HTTP connection (1): v0514.nbi.ac.uk
[04/Aug/2015 15:21:11] DEBUG [requests.packages.urllib3.connectionpool:383] "GET /id/ HTTP/1.1" 200 None
[04/Aug/2015 15:23:50] INFO [requests.packages.urllib3.connectionpool:203] Starting new HTTP connection (1): v0514.nbi.ac.uk
[04/Aug/2015 15:23:50] DEBUG [requests.packages.urllib3.connectionpool:383] "GET /id/ HTTP/1.1" 200 None
[04/Aug/2015 15:31:29] INFO [requests.packages.urllib3.connectionpool:203] Starting new HTTP connection (1): v0514.nbi.ac.uk
[04/Aug/2015 15:31:29] DEBUG [requests.packages.urllib3.connectionpool:383] "GET /id/ HTTP/1.1" 200 None
[06/Aug/2015 14:06:00] DEBUG [web_copo.views:18] ['/Users/fshaw/Dropbox/tgac_dev/prototypes/COPO/web', '/Users/fshaw/Dropbox/tgac_dev/prototypes/COPO/web/project_copo/settings', '/Users/fshaw/Dropbox/tgac_dev/prototypes/COPO', '/Users/fshaw/Dropbox/tgac_dev/prototypes/COPO/dal', '/Users/fshaw/Dropbox/tgac_dev/prototypes/COPO/web/apps', '/Users/fshaw/Dropbox/tgac_dev/prototypes/COPO/api', '/Users/fshaw/Dropbox/tgac_dev/prototypes/COPO/web/project_copo', '/Users/fshaw/Documents/dev/environments/copo_python3.4/lib/python34.zip', '/Users/fshaw/Documents/dev/environments/copo_python3.4/lib/python3.4', '/Users/fshaw/Documents/dev/environments/copo_python3.4/lib/python3.4/plat-darwin', '/Users/fshaw/Documents/dev/environments/copo_python3.4/lib/python3.4/lib-dynload', '/Library/Frameworks/Python.framework/Versions/3.4/lib/python3.4', '/Library/Frameworks/Python.framework/Versions/3.4/lib/python3.4/plat-darwin', '/Users/fshaw/Documents/dev/environments/copo_python3.4/lib/python3.4/site-packages', '/Users/fshaw/Dropbox/tgac_dev/prototypes/COPO', '/Users/fshaw/Dropbox/tgac_dev/prototypes/COPO/api', '/Users/fshaw/Dropbox/tgac_dev/prototypes/COPO/dal', '/Users/fshaw/Dropbox/tgac_dev/prototypes/COPO/web/project_copo', '/Users/fshaw/Dropbox/tgac_dev/prototypes/COPO/web/project_copo/settings', '/Users/fshaw/Dropbox/tgac_dev/prototypes/COPO/web/apps', '/var/www/copo_www/COPO/', '/var/www/copo_www/COPO/api', '/var/www/copo_www/COPO/dal', '/var/www/copo_www/COPO/web/project_copo', '/var/www/copo_www/COPO/web/project_copo/settings', '/var/www/copo_www/COPO/web/apps']
[06/Aug/2015 14:06:00] ERROR [django.request:231] Internal Server Error: /copo/profile/55c34079453d9ad3b96e331b/view
Traceback (most recent call last):
  File "/Users/fshaw/Documents/dev/environments/copo_python3.4/lib/python3.4/site-packages/django/core/urlresolvers.py", line 364, in urlconf_module
    return self._urlconf_module
AttributeError: 'RegexURLResolver' object has no attribute '_urlconf_module'

During handling of the above exception, another exception occurred:

Traceback (most recent call last):
  File "/Users/fshaw/Documents/dev/environments/copo_python3.4/lib/python3.4/site-packages/django/core/handlers/base.py", line 87, in get_response
    response = middleware_method(request)
  File "/Users/fshaw/Documents/dev/environments/copo_python3.4/lib/python3.4/site-packages/django/middleware/common.py", line 72, in process_request
    if (not urlresolvers.is_valid_path(request.path_info, urlconf) and
  File "/Users/fshaw/Documents/dev/environments/copo_python3.4/lib/python3.4/site-packages/django/core/urlresolvers.py", line 619, in is_valid_path
    resolve(path, urlconf)
  File "/Users/fshaw/Documents/dev/environments/copo_python3.4/lib/python3.4/site-packages/django/core/urlresolvers.py", line 494, in resolve
    return get_resolver(urlconf).resolve(path)
  File "/Users/fshaw/Documents/dev/environments/copo_python3.4/lib/python3.4/site-packages/django/core/urlresolvers.py", line 343, in resolve
    for pattern in self.url_patterns:
  File "/Users/fshaw/Documents/dev/environments/copo_python3.4/lib/python3.4/site-packages/django/core/urlresolvers.py", line 372, in url_patterns
    patterns = getattr(self.urlconf_module, "urlpatterns", self.urlconf_module)
  File "/Users/fshaw/Documents/dev/environments/copo_python3.4/lib/python3.4/site-packages/django/core/urlresolvers.py", line 366, in urlconf_module
    self._urlconf_module = import_module(self.urlconf_name)
  File "/Users/fshaw/Documents/dev/environments/copo_python3.4/lib/python3.4/importlib/__init__.py", line 109, in import_module
    return _bootstrap._gcd_import(name[level:], package, level)
  File "<frozen importlib._bootstrap>", line 2254, in _gcd_import
  File "<frozen importlib._bootstrap>", line 2237, in _find_and_load
  File "<frozen importlib._bootstrap>", line 2226, in _find_and_load_unlocked
  File "<frozen importlib._bootstrap>", line 1200, in _load_unlocked
  File "<frozen importlib._bootstrap>", line 1129, in _exec
  File "<frozen importlib._bootstrap>", line 1471, in exec_module
  File "<frozen importlib._bootstrap>", line 321, in _call_with_frames_removed
  File "/Users/fshaw/Dropbox/tgac_dev/prototypes/COPO/web/project_copo/urls.py", line 4, in <module>
    import web_copo.views as views
  File "/Users/fshaw/Dropbox/tgac_dev/prototypes/COPO/web/apps/web_copo/views.py", line 21, in <module>
    from dal.copo_base_da import Profile, Collection_Head, ObjectId
  File "/Users/fshaw/Dropbox/tgac_dev/prototypes/COPO/dal/__init__.py", line 10, in <module>
    from ena_da import EnaCollection
  File "/Users/fshaw/Dropbox/tgac_dev/prototypes/COPO/dal/ena_da.py", line 8, in <module>
    import web_copo.mongo.mongo_util as mutil
ImportError: No module named 'web_copo.mongo'
[06/Aug/2015 14:17:53] INFO [requests.packages.urllib3.connectionpool:203] Starting new HTTP connection (1): v0514.nbi.ac.uk
[06/Aug/2015 14:17:53] DEBUG [requests.packages.urllib3.connectionpool:383] "GET /id/ HTTP/1.1" 200 None
[06/Aug/2015 14:20:43] INFO [requests.packages.urllib3.connectionpool:203] Starting new HTTP connection (1): v0514.nbi.ac.uk
[06/Aug/2015 14:20:44] DEBUG [requests.packages.urllib3.connectionpool:383] "GET /id/ HTTP/1.1" 200 None
[06/Aug/2015 14:22:34] DEBUG [web_copo.views:18] ['/Users/fshaw/Dropbox/tgac_dev/prototypes/COPO/web', '/Users/fshaw/Dropbox/tgac_dev/prototypes/COPO/web/project_copo/settings', '/Users/fshaw/Dropbox/tgac_dev/prototypes/COPO', '/Users/fshaw/Dropbox/tgac_dev/prototypes/COPO/dal', '/Users/fshaw/Dropbox/tgac_dev/prototypes/COPO/web/apps', '/Users/fshaw/Dropbox/tgac_dev/prototypes/COPO/api', '/Users/fshaw/Dropbox/tgac_dev/prototypes/COPO/web/project_copo', '/Users/fshaw/Documents/dev/environments/copo_python3.4/lib/python34.zip', '/Users/fshaw/Documents/dev/environments/copo_python3.4/lib/python3.4', '/Users/fshaw/Documents/dev/environments/copo_python3.4/lib/python3.4/plat-darwin', '/Users/fshaw/Documents/dev/environments/copo_python3.4/lib/python3.4/lib-dynload', '/Library/Frameworks/Python.framework/Versions/3.4/lib/python3.4', '/Library/Frameworks/Python.framework/Versions/3.4/lib/python3.4/plat-darwin', '/Users/fshaw/Documents/dev/environments/copo_python3.4/lib/python3.4/site-packages', '/Users/fshaw/Dropbox/tgac_dev/prototypes/COPO', '/Users/fshaw/Dropbox/tgac_dev/prototypes/COPO/api', '/Users/fshaw/Dropbox/tgac_dev/prototypes/COPO/dal', '/Users/fshaw/Dropbox/tgac_dev/prototypes/COPO/web/project_copo', '/Users/fshaw/Dropbox/tgac_dev/prototypes/COPO/web/project_copo/settings', '/Users/fshaw/Dropbox/tgac_dev/prototypes/COPO/web/apps', '/var/www/copo_www/COPO/', '/var/www/copo_www/COPO/api', '/var/www/copo_www/COPO/dal', '/var/www/copo_www/COPO/web/project_copo', '/var/www/copo_www/COPO/web/project_copo/settings', '/var/www/copo_www/COPO/web/apps']
[06/Aug/2015 14:22:34] ERROR [django.request:231] Internal Server Error: /copo
Traceback (most recent call last):
  File "/Users/fshaw/Documents/dev/environments/copo_python3.4/lib/python3.4/site-packages/django/core/urlresolvers.py", line 364, in urlconf_module
    return self._urlconf_module
AttributeError: 'RegexURLResolver' object has no attribute '_urlconf_module'

During handling of the above exception, another exception occurred:

Traceback (most recent call last):
  File "/Users/fshaw/Documents/dev/environments/copo_python3.4/lib/python3.4/site-packages/django/core/handlers/base.py", line 87, in get_response
    response = middleware_method(request)
  File "/Users/fshaw/Documents/dev/environments/copo_python3.4/lib/python3.4/site-packages/django/middleware/common.py", line 72, in process_request
    if (not urlresolvers.is_valid_path(request.path_info, urlconf) and
  File "/Users/fshaw/Documents/dev/environments/copo_python3.4/lib/python3.4/site-packages/django/core/urlresolvers.py", line 619, in is_valid_path
    resolve(path, urlconf)
  File "/Users/fshaw/Documents/dev/environments/copo_python3.4/lib/python3.4/site-packages/django/core/urlresolvers.py", line 494, in resolve
    return get_resolver(urlconf).resolve(path)
  File "/Users/fshaw/Documents/dev/environments/copo_python3.4/lib/python3.4/site-packages/django/core/urlresolvers.py", line 343, in resolve
    for pattern in self.url_patterns:
  File "/Users/fshaw/Documents/dev/environments/copo_python3.4/lib/python3.4/site-packages/django/core/urlresolvers.py", line 372, in url_patterns
    patterns = getattr(self.urlconf_module, "urlpatterns", self.urlconf_module)
  File "/Users/fshaw/Documents/dev/environments/copo_python3.4/lib/python3.4/site-packages/django/core/urlresolvers.py", line 366, in urlconf_module
    self._urlconf_module = import_module(self.urlconf_name)
  File "/Users/fshaw/Documents/dev/environments/copo_python3.4/lib/python3.4/importlib/__init__.py", line 109, in import_module
    return _bootstrap._gcd_import(name[level:], package, level)
  File "<frozen importlib._bootstrap>", line 2254, in _gcd_import
  File "<frozen importlib._bootstrap>", line 2237, in _find_and_load
  File "<frozen importlib._bootstrap>", line 2226, in _find_and_load_unlocked
  File "<frozen importlib._bootstrap>", line 1200, in _load_unlocked
  File "<frozen importlib._bootstrap>", line 1129, in _exec
  File "<frozen importlib._bootstrap>", line 1471, in exec_module
  File "<frozen importlib._bootstrap>", line 321, in _call_with_frames_removed
  File "/Users/fshaw/Dropbox/tgac_dev/prototypes/COPO/web/project_copo/urls.py", line 4, in <module>
    import web_copo.views as views
  File "/Users/fshaw/Dropbox/tgac_dev/prototypes/COPO/web/apps/web_copo/views.py", line 21, in <module>
    from dal.copo_base_da import Profile, Collection_Head, ObjectId
  File "/Users/fshaw/Dropbox/tgac_dev/prototypes/COPO/dal/__init__.py", line 10, in <module>
    from ena_da import EnaCollection
  File "/Users/fshaw/Dropbox/tgac_dev/prototypes/COPO/dal/ena_da.py", line 11, in <module>
    import web_copo.uiconfigs.utils.data_utils as d_utils
  File "/Users/fshaw/Dropbox/tgac_dev/prototypes/COPO/web/apps/web_copo/uiconfigs/utils/data_utils.py", line 6, in <module>
    from dal import DataSchemas
ImportError: cannot import name 'DataSchemas'
[06/Aug/2015 14:25:45] DEBUG [web_copo.views:18] ['/Users/fshaw/Dropbox/tgac_dev/prototypes/COPO/web', '/Users/fshaw/Dropbox/tgac_dev/prototypes/COPO/web/project_copo/settings', '/Users/fshaw/Dropbox/tgac_dev/prototypes/COPO', '/Users/fshaw/Dropbox/tgac_dev/prototypes/COPO/dal', '/Users/fshaw/Dropbox/tgac_dev/prototypes/COPO/web/apps', '/Users/fshaw/Dropbox/tgac_dev/prototypes/COPO/api', '/Users/fshaw/Dropbox/tgac_dev/prototypes/COPO/web/project_copo', '/Users/fshaw/Documents/dev/environments/copo_python3.4/lib/python34.zip', '/Users/fshaw/Documents/dev/environments/copo_python3.4/lib/python3.4', '/Users/fshaw/Documents/dev/environments/copo_python3.4/lib/python3.4/plat-darwin', '/Users/fshaw/Documents/dev/environments/copo_python3.4/lib/python3.4/lib-dynload', '/Library/Frameworks/Python.framework/Versions/3.4/lib/python3.4', '/Library/Frameworks/Python.framework/Versions/3.4/lib/python3.4/plat-darwin', '/Users/fshaw/Documents/dev/environments/copo_python3.4/lib/python3.4/site-packages', '/Users/fshaw/Dropbox/tgac_dev/prototypes/COPO', '/Users/fshaw/Dropbox/tgac_dev/prototypes/COPO/api', '/Users/fshaw/Dropbox/tgac_dev/prototypes/COPO/dal', '/Users/fshaw/Dropbox/tgac_dev/prototypes/COPO/web/project_copo', '/Users/fshaw/Dropbox/tgac_dev/prototypes/COPO/web/project_copo/settings', '/Users/fshaw/Dropbox/tgac_dev/prototypes/COPO/web/apps', '/var/www/copo_www/COPO/', '/var/www/copo_www/COPO/api', '/var/www/copo_www/COPO/dal', '/var/www/copo_www/COPO/web/project_copo', '/var/www/copo_www/COPO/web/project_copo/settings', '/var/www/copo_www/COPO/web/apps']
[06/Aug/2015 14:25:45] ERROR [django.request:231] Internal Server Error: /copo
Traceback (most recent call last):
  File "/Users/fshaw/Documents/dev/environments/copo_python3.4/lib/python3.4/site-packages/django/core/urlresolvers.py", line 364, in urlconf_module
    return self._urlconf_module
AttributeError: 'RegexURLResolver' object has no attribute '_urlconf_module'

During handling of the above exception, another exception occurred:

Traceback (most recent call last):
  File "/Users/fshaw/Documents/dev/environments/copo_python3.4/lib/python3.4/site-packages/django/core/handlers/base.py", line 87, in get_response
    response = middleware_method(request)
  File "/Users/fshaw/Documents/dev/environments/copo_python3.4/lib/python3.4/site-packages/django/middleware/common.py", line 72, in process_request
    if (not urlresolvers.is_valid_path(request.path_info, urlconf) and
  File "/Users/fshaw/Documents/dev/environments/copo_python3.4/lib/python3.4/site-packages/django/core/urlresolvers.py", line 619, in is_valid_path
    resolve(path, urlconf)
  File "/Users/fshaw/Documents/dev/environments/copo_python3.4/lib/python3.4/site-packages/django/core/urlresolvers.py", line 494, in resolve
    return get_resolver(urlconf).resolve(path)
  File "/Users/fshaw/Documents/dev/environments/copo_python3.4/lib/python3.4/site-packages/django/core/urlresolvers.py", line 343, in resolve
    for pattern in self.url_patterns:
  File "/Users/fshaw/Documents/dev/environments/copo_python3.4/lib/python3.4/site-packages/django/core/urlresolvers.py", line 372, in url_patterns
    patterns = getattr(self.urlconf_module, "urlpatterns", self.urlconf_module)
  File "/Users/fshaw/Documents/dev/environments/copo_python3.4/lib/python3.4/site-packages/django/core/urlresolvers.py", line 366, in urlconf_module
    self._urlconf_module = import_module(self.urlconf_name)
  File "/Users/fshaw/Documents/dev/environments/copo_python3.4/lib/python3.4/importlib/__init__.py", line 109, in import_module
    return _bootstrap._gcd_import(name[level:], package, level)
  File "<frozen importlib._bootstrap>", line 2254, in _gcd_import
  File "<frozen importlib._bootstrap>", line 2237, in _find_and_load
  File "<frozen importlib._bootstrap>", line 2226, in _find_and_load_unlocked
  File "<frozen importlib._bootstrap>", line 1200, in _load_unlocked
  File "<frozen importlib._bootstrap>", line 1129, in _exec
  File "<frozen importlib._bootstrap>", line 1471, in exec_module
  File "<frozen importlib._bootstrap>", line 321, in _call_with_frames_removed
  File "/Users/fshaw/Dropbox/tgac_dev/prototypes/COPO/web/project_copo/urls.py", line 4, in <module>
    import web_copo.views as views
  File "/Users/fshaw/Dropbox/tgac_dev/prototypes/COPO/web/apps/web_copo/views.py", line 27, in <module>
    from web_copo.repos.aspera import *
  File "/Users/fshaw/Dropbox/tgac_dev/prototypes/COPO/web/apps/web_copo/repos/aspera.py", line 9, in <module>
    from settings.settings import *
ImportError: No module named 'settings.settings'
[06/Aug/2015 14:26:09] INFO [requests.packages.urllib3.connectionpool:203] Starting new HTTP connection (1): v0514.nbi.ac.uk
[06/Aug/2015 14:26:09] DEBUG [requests.packages.urllib3.connectionpool:383] "GET /id/ HTTP/1.1" 200 None
[06/Aug/2015 14:26:09] INFO [requests.packages.urllib3.connectionpool:203] Starting new HTTP connection (1): v0514.nbi.ac.uk
[06/Aug/2015 14:26:09] DEBUG [requests.packages.urllib3.connectionpool:383] "GET /id/ HTTP/1.1" 200 None
[06/Aug/2015 14:26:09] INFO [requests.packages.urllib3.connectionpool:203] Starting new HTTP connection (1): v0514.nbi.ac.uk
[06/Aug/2015 14:26:09] DEBUG [requests.packages.urllib3.connectionpool:383] "GET /id/ HTTP/1.1" 200 None
[06/Aug/2015 14:26:09] INFO [requests.packages.urllib3.connectionpool:203] Starting new HTTP connection (1): v0514.nbi.ac.uk
[06/Aug/2015 14:26:09] DEBUG [requests.packages.urllib3.connectionpool:383] "GET /id/ HTTP/1.1" 200 None
[06/Aug/2015 14:26:09] INFO [requests.packages.urllib3.connectionpool:203] Starting new HTTP connection (1): v0514.nbi.ac.uk
[06/Aug/2015 14:26:09] DEBUG [requests.packages.urllib3.connectionpool:383] "GET /id/ HTTP/1.1" 200 None
[06/Aug/2015 14:26:09] INFO [requests.packages.urllib3.connectionpool:203] Starting new HTTP connection (1): v0514.nbi.ac.uk
[06/Aug/2015 14:26:09] DEBUG [requests.packages.urllib3.connectionpool:383] "GET /id/ HTTP/1.1" 200 None
[06/Aug/2015 14:26:09] INFO [requests.packages.urllib3.connectionpool:203] Starting new HTTP connection (1): v0514.nbi.ac.uk
[06/Aug/2015 14:26:09] DEBUG [requests.packages.urllib3.connectionpool:383] "GET /id/ HTTP/1.1" 200 None
[06/Aug/2015 14:26:09] INFO [requests.packages.urllib3.connectionpool:203] Starting new HTTP connection (1): v0514.nbi.ac.uk
[06/Aug/2015 14:26:09] DEBUG [requests.packages.urllib3.connectionpool:383] "GET /id/ HTTP/1.1" 200 None
[06/Aug/2015 14:26:09] INFO [requests.packages.urllib3.connectionpool:203] Starting new HTTP connection (1): v0514.nbi.ac.uk
[06/Aug/2015 14:26:09] DEBUG [requests.packages.urllib3.connectionpool:383] "GET /id/ HTTP/1.1" 200 None
[06/Aug/2015 14:26:09] INFO [requests.packages.urllib3.connectionpool:203] Starting new HTTP connection (1): v0514.nbi.ac.uk
[06/Aug/2015 14:26:09] DEBUG [requests.packages.urllib3.connectionpool:383] "GET /id/ HTTP/1.1" 200 None
[06/Aug/2015 14:26:09] INFO [requests.packages.urllib3.connectionpool:203] Starting new HTTP connection (1): v0514.nbi.ac.uk
[06/Aug/2015 14:26:09] DEBUG [requests.packages.urllib3.connectionpool:383] "GET /id/ HTTP/1.1" 200 None
[06/Aug/2015 14:28:59] INFO [requests.packages.urllib3.connectionpool:203] Starting new HTTP connection (1): v0514.nbi.ac.uk
[06/Aug/2015 14:28:59] DEBUG [requests.packages.urllib3.connectionpool:383] "GET /id/ HTTP/1.1" 200 None
[06/Aug/2015 14:28:59] INFO [requests.packages.urllib3.connectionpool:203] Starting new HTTP connection (1): v0514.nbi.ac.uk
[06/Aug/2015 14:28:59] DEBUG [requests.packages.urllib3.connectionpool:383] "GET /id/ HTTP/1.1" 200 None
[06/Aug/2015 14:28:59] INFO [requests.packages.urllib3.connectionpool:203] Starting new HTTP connection (1): v0514.nbi.ac.uk
[06/Aug/2015 14:28:59] DEBUG [requests.packages.urllib3.connectionpool:383] "GET /id/ HTTP/1.1" 200 None
[06/Aug/2015 14:28:59] INFO [requests.packages.urllib3.connectionpool:203] Starting new HTTP connection (1): v0514.nbi.ac.uk
[06/Aug/2015 14:28:59] DEBUG [requests.packages.urllib3.connectionpool:383] "GET /id/ HTTP/1.1" 200 None
[06/Aug/2015 14:28:59] INFO [requests.packages.urllib3.connectionpool:203] Starting new HTTP connection (1): v0514.nbi.ac.uk
[06/Aug/2015 14:28:59] DEBUG [requests.packages.urllib3.connectionpool:383] "GET /id/ HTTP/1.1" 200 None
[06/Aug/2015 14:28:59] INFO [requests.packages.urllib3.connectionpool:203] Starting new HTTP connection (1): v0514.nbi.ac.uk
[06/Aug/2015 14:28:59] DEBUG [requests.packages.urllib3.connectionpool:383] "GET /id/ HTTP/1.1" 200 None
[06/Aug/2015 14:28:59] INFO [requests.packages.urllib3.connectionpool:203] Starting new HTTP connection (1): v0514.nbi.ac.uk
[06/Aug/2015 14:28:59] DEBUG [requests.packages.urllib3.connectionpool:383] "GET /id/ HTTP/1.1" 200 None
[06/Aug/2015 14:28:59] INFO [requests.packages.urllib3.connectionpool:203] Starting new HTTP connection (1): v0514.nbi.ac.uk
[06/Aug/2015 14:28:59] DEBUG [requests.packages.urllib3.connectionpool:383] "GET /id/ HTTP/1.1" 200 None
[06/Aug/2015 14:28:59] INFO [requests.packages.urllib3.connectionpool:203] Starting new HTTP connection (1): v0514.nbi.ac.uk
[06/Aug/2015 14:28:59] DEBUG [requests.packages.urllib3.connectionpool:383] "GET /id/ HTTP/1.1" 200 None
[06/Aug/2015 14:28:59] INFO [requests.packages.urllib3.connectionpool:203] Starting new HTTP connection (1): v0514.nbi.ac.uk
[06/Aug/2015 14:28:59] DEBUG [requests.packages.urllib3.connectionpool:383] "GET /id/ HTTP/1.1" 200 None
[06/Aug/2015 14:28:59] INFO [requests.packages.urllib3.connectionpool:203] Starting new HTTP connection (1): v0514.nbi.ac.uk
[06/Aug/2015 14:28:59] DEBUG [requests.packages.urllib3.connectionpool:383] "GET /id/ HTTP/1.1" 200 None
[06/Aug/2015 15:02:59] INFO [requests.packages.urllib3.connectionpool:203] Starting new HTTP connection (1): v0514.nbi.ac.uk
[06/Aug/2015 15:03:00] DEBUG [requests.packages.urllib3.connectionpool:383] "GET /id/ HTTP/1.1" 200 None
[06/Aug/2015 15:04:15] INFO [requests.packages.urllib3.connectionpool:203] Starting new HTTP connection (1): v0514.nbi.ac.uk
[06/Aug/2015 15:04:15] DEBUG [requests.packages.urllib3.connectionpool:383] "GET /id/ HTTP/1.1" 200 None
[06/Aug/2015 15:04:15] INFO [requests.packages.urllib3.connectionpool:203] Starting new HTTP connection (1): v0514.nbi.ac.uk
[06/Aug/2015 15:04:15] DEBUG [requests.packages.urllib3.connectionpool:383] "GET /id/ HTTP/1.1" 200 None
[06/Aug/2015 15:04:15] INFO [requests.packages.urllib3.connectionpool:203] Starting new HTTP connection (1): v0514.nbi.ac.uk
[06/Aug/2015 15:04:15] DEBUG [requests.packages.urllib3.connectionpool:383] "GET /id/ HTTP/1.1" 200 None
[06/Aug/2015 15:04:15] INFO [requests.packages.urllib3.connectionpool:203] Starting new HTTP connection (1): v0514.nbi.ac.uk
[06/Aug/2015 15:04:15] DEBUG [requests.packages.urllib3.connectionpool:383] "GET /id/ HTTP/1.1" 200 None
[06/Aug/2015 15:04:15] INFO [requests.packages.urllib3.connectionpool:203] Starting new HTTP connection (1): v0514.nbi.ac.uk
[06/Aug/2015 15:04:15] DEBUG [requests.packages.urllib3.connectionpool:383] "GET /id/ HTTP/1.1" 200 None
[06/Aug/2015 15:04:15] INFO [requests.packages.urllib3.connectionpool:203] Starting new HTTP connection (1): v0514.nbi.ac.uk
[06/Aug/2015 15:04:15] DEBUG [requests.packages.urllib3.connectionpool:383] "GET /id/ HTTP/1.1" 200 None
[06/Aug/2015 15:04:15] INFO [requests.packages.urllib3.connectionpool:203] Starting new HTTP connection (1): v0514.nbi.ac.uk
[06/Aug/2015 15:04:15] DEBUG [requests.packages.urllib3.connectionpool:383] "GET /id/ HTTP/1.1" 200 None
[06/Aug/2015 15:04:15] INFO [requests.packages.urllib3.connectionpool:203] Starting new HTTP connection (1): v0514.nbi.ac.uk
[06/Aug/2015 15:04:15] DEBUG [requests.packages.urllib3.connectionpool:383] "GET /id/ HTTP/1.1" 200 None
[06/Aug/2015 15:04:15] INFO [requests.packages.urllib3.connectionpool:203] Starting new HTTP connection (1): v0514.nbi.ac.uk
[06/Aug/2015 15:04:15] DEBUG [requests.packages.urllib3.connectionpool:383] "GET /id/ HTTP/1.1" 200 None
[06/Aug/2015 15:04:15] INFO [requests.packages.urllib3.connectionpool:203] Starting new HTTP connection (1): v0514.nbi.ac.uk
[06/Aug/2015 15:04:15] DEBUG [requests.packages.urllib3.connectionpool:383] "GET /id/ HTTP/1.1" 200 None
[06/Aug/2015 15:04:15] INFO [requests.packages.urllib3.connectionpool:203] Starting new HTTP connection (1): v0514.nbi.ac.uk
[06/Aug/2015 15:04:15] DEBUG [requests.packages.urllib3.connectionpool:383] "GET /id/ HTTP/1.1" 200 None
[06/Aug/2015 15:04:37] DEBUG [web_copo.views:18] ['/Users/fshaw/Dropbox/tgac_dev/prototypes/COPO/web', '/Users/fshaw/Dropbox/tgac_dev/prototypes/COPO/web/project_copo/settings', '/Users/fshaw/Dropbox/tgac_dev/prototypes/COPO', '/Users/fshaw/Dropbox/tgac_dev/prototypes/COPO/dal', '/Users/fshaw/Dropbox/tgac_dev/prototypes/COPO/web/apps', '/Users/fshaw/Dropbox/tgac_dev/prototypes/COPO/api', '/Users/fshaw/Dropbox/tgac_dev/prototypes/COPO/web/project_copo', '/Users/fshaw/Documents/dev/environments/copo_python3.4/lib/python34.zip', '/Users/fshaw/Documents/dev/environments/copo_python3.4/lib/python3.4', '/Users/fshaw/Documents/dev/environments/copo_python3.4/lib/python3.4/plat-darwin', '/Users/fshaw/Documents/dev/environments/copo_python3.4/lib/python3.4/lib-dynload', '/Library/Frameworks/Python.framework/Versions/3.4/lib/python3.4', '/Library/Frameworks/Python.framework/Versions/3.4/lib/python3.4/plat-darwin', '/Users/fshaw/Documents/dev/environments/copo_python3.4/lib/python3.4/site-packages', '/Users/fshaw/Dropbox/tgac_dev/prototypes/COPO', '/Users/fshaw/Dropbox/tgac_dev/prototypes/COPO/api', '/Users/fshaw/Dropbox/tgac_dev/prototypes/COPO/dal', '/Users/fshaw/Dropbox/tgac_dev/prototypes/COPO/web/project_copo', '/Users/fshaw/Dropbox/tgac_dev/prototypes/COPO/web/project_copo/settings', '/Users/fshaw/Dropbox/tgac_dev/prototypes/COPO/web/apps', '/var/www/copo_www/COPO/', '/var/www/copo_www/COPO/api', '/var/www/copo_www/COPO/dal', '/var/www/copo_www/COPO/web/project_copo', '/var/www/copo_www/COPO/web/project_copo/settings', '/var/www/copo_www/COPO/web/apps']
[06/Aug/2015 15:04:37] ERROR [django.request:231] Internal Server Error: /copo/profile/55c34079453d9ad3b96e331b/view
Traceback (most recent call last):
  File "/Users/fshaw/Documents/dev/environments/copo_python3.4/lib/python3.4/site-packages/django/core/urlresolvers.py", line 364, in urlconf_module
    return self._urlconf_module
AttributeError: 'RegexURLResolver' object has no attribute '_urlconf_module'

During handling of the above exception, another exception occurred:

Traceback (most recent call last):
  File "/Users/fshaw/Documents/dev/environments/copo_python3.4/lib/python3.4/site-packages/django/core/handlers/base.py", line 87, in get_response
    response = middleware_method(request)
  File "/Users/fshaw/Documents/dev/environments/copo_python3.4/lib/python3.4/site-packages/django/middleware/common.py", line 72, in process_request
    if (not urlresolvers.is_valid_path(request.path_info, urlconf) and
  File "/Users/fshaw/Documents/dev/environments/copo_python3.4/lib/python3.4/site-packages/django/core/urlresolvers.py", line 619, in is_valid_path
    resolve(path, urlconf)
  File "/Users/fshaw/Documents/dev/environments/copo_python3.4/lib/python3.4/site-packages/django/core/urlresolvers.py", line 494, in resolve
    return get_resolver(urlconf).resolve(path)
  File "/Users/fshaw/Documents/dev/environments/copo_python3.4/lib/python3.4/site-packages/django/core/urlresolvers.py", line 343, in resolve
    for pattern in self.url_patterns:
  File "/Users/fshaw/Documents/dev/environments/copo_python3.4/lib/python3.4/site-packages/django/core/urlresolvers.py", line 372, in url_patterns
    patterns = getattr(self.urlconf_module, "urlpatterns", self.urlconf_module)
  File "/Users/fshaw/Documents/dev/environments/copo_python3.4/lib/python3.4/site-packages/django/core/urlresolvers.py", line 366, in urlconf_module
    self._urlconf_module = import_module(self.urlconf_name)
  File "/Users/fshaw/Documents/dev/environments/copo_python3.4/lib/python3.4/importlib/__init__.py", line 109, in import_module
    return _bootstrap._gcd_import(name[level:], package, level)
  File "<frozen importlib._bootstrap>", line 2254, in _gcd_import
  File "<frozen importlib._bootstrap>", line 2237, in _find_and_load
  File "<frozen importlib._bootstrap>", line 2226, in _find_and_load_unlocked
  File "<frozen importlib._bootstrap>", line 1200, in _load_unlocked
  File "<frozen importlib._bootstrap>", line 1129, in _exec
  File "<frozen importlib._bootstrap>", line 1471, in exec_module
  File "<frozen importlib._bootstrap>", line 321, in _call_with_frames_removed
  File "/Users/fshaw/Dropbox/tgac_dev/prototypes/COPO/web/project_copo/urls.py", line 4, in <module>
    import web_copo.views as views
  File "/Users/fshaw/Dropbox/tgac_dev/prototypes/COPO/web/apps/web_copo/views.py", line 27, in <module>
    from web_copo.repos.aspera import *
  File "/Users/fshaw/Dropbox/tgac_dev/prototypes/COPO/web/apps/web_copo/repos/aspera.py", line 9, in <module>
    from settings.settings import *
ImportError: No module named 'settings.settings'
[06/Aug/2015 15:07:52] DEBUG [web_copo.views:18] ['/Users/fshaw/Dropbox/tgac_dev/prototypes/COPO/web', '/Users/fshaw/Dropbox/tgac_dev/prototypes/COPO/web/project_copo/settings', '/Users/fshaw/Dropbox/tgac_dev/prototypes/COPO', '/Users/fshaw/Dropbox/tgac_dev/prototypes/COPO/dal', '/Users/fshaw/Dropbox/tgac_dev/prototypes/COPO/web/apps', '/Users/fshaw/Dropbox/tgac_dev/prototypes/COPO/api', '/Users/fshaw/Dropbox/tgac_dev/prototypes/COPO/web/project_copo', '/Users/fshaw/Documents/dev/environments/copo_python3.4/lib/python34.zip', '/Users/fshaw/Documents/dev/environments/copo_python3.4/lib/python3.4', '/Users/fshaw/Documents/dev/environments/copo_python3.4/lib/python3.4/plat-darwin', '/Users/fshaw/Documents/dev/environments/copo_python3.4/lib/python3.4/lib-dynload', '/Library/Frameworks/Python.framework/Versions/3.4/lib/python3.4', '/Library/Frameworks/Python.framework/Versions/3.4/lib/python3.4/plat-darwin', '/Users/fshaw/Documents/dev/environments/copo_python3.4/lib/python3.4/site-packages', '/Users/fshaw/Dropbox/tgac_dev/prototypes/COPO', '/Users/fshaw/Dropbox/tgac_dev/prototypes/COPO/api', '/Users/fshaw/Dropbox/tgac_dev/prototypes/COPO/dal', '/Users/fshaw/Dropbox/tgac_dev/prototypes/COPO/web/project_copo', '/Users/fshaw/Dropbox/tgac_dev/prototypes/COPO/web/project_copo/settings', '/Users/fshaw/Dropbox/tgac_dev/prototypes/COPO/web/apps', '/var/www/copo_www/COPO/', '/var/www/copo_www/COPO/api', '/var/www/copo_www/COPO/dal', '/var/www/copo_www/COPO/web/project_copo', '/var/www/copo_www/COPO/web/project_copo/settings', '/var/www/copo_www/COPO/web/apps']
[06/Aug/2015 15:07:56] ERROR [django.request:231] Internal Server Error: /copo/collection/55c340e2453d9ad3b96e331c/view
Traceback (most recent call last):
  File "/Users/fshaw/Documents/dev/environments/copo_python3.4/lib/python3.4/site-packages/django/core/handlers/base.py", line 111, in get_response
    response = wrapped_callback(request, *callback_args, **callback_kwargs)
  File "/Users/fshaw/Documents/dev/environments/copo_python3.4/lib/python3.4/site-packages/django/contrib/auth/decorators.py", line 21, in _wrapped_view
    return view_func(request, *args, **kwargs)
  File "/Users/fshaw/Dropbox/tgac_dev/prototypes/COPO/web/apps/web_copo/views.py", line 218, in view_collection
    ui_template = DataSchemas("ENA").get_ui_template()
  File "/Users/fshaw/Dropbox/tgac_dev/prototypes/COPO/dal/copo_base_da.py", line 198, in get_ui_template
    Schemas(self.schema).add_template(temp_dict["data"])
  File "/Users/fshaw/Documents/dev/environments/copo_python3.4/lib/python3.4/site-packages/pymongo/collection.py", line 2066, in __call__
    self.__name)
TypeError: 'Collection' object is not callable. If you meant to call the 'Schemas' method on a 'Database' object it is failing because no such method exists.
[06/Aug/2015 15:09:16] INFO [requests.packages.urllib3.connectionpool:203] Starting new HTTP connection (1): v0514.nbi.ac.uk
[06/Aug/2015 15:09:16] DEBUG [requests.packages.urllib3.connectionpool:383] "GET /id/ HTTP/1.1" 200 None
[06/Aug/2015 15:09:54] ERROR [django.request:231] Internal Server Error: /rest/check_figshare_credentials/
Traceback (most recent call last):
  File "/Users/fshaw/Documents/dev/environments/copo_python3.4/lib/python3.4/site-packages/django/core/handlers/base.py", line 111, in get_response
    response = wrapped_callback(request, *callback_args, **callback_kwargs)
  File "/Users/fshaw/Dropbox/tgac_dev/prototypes/COPO/web/apps/web_copo/repos/figshare.py", line 103, in check_figshare_credentials
    if (Figshare_token().token_exists()):
NameError: name 'Figshare_token' is not defined
