[22/Oct/2015 16:06:20] ERROR [django.request:231] Internal Server Error: /copo/copo_publications/5616733191aaa91fc57df44a/view
Traceback (most recent call last):
  File "/Users/fshaw/Documents/dev/environments/copo_python3.4/lib/python3.4/site-packages/django/core/urlresolvers.py", line 364, in urlconf_module
    return self._urlconf_module
AttributeError: 'RegexURLResolver' object has no attribute '_urlconf_module'

During handling of the above exception, another exception occurred:

Traceback (most recent call last):
  File "/Users/fshaw/Documents/dev/environments/copo_python3.4/lib/python3.4/site-packages/django/core/handlers/base.py", line 87, in get_response
    response = middleware_method(request)
  File "/Users/fshaw/Documents/dev/environments/copo_python3.4/lib/python3.4/site-packages/django/middleware/common.py", line 72, in process_request
    if (not urlresolvers.is_valid_path(request.path_info, urlconf) and
  File "/Users/fshaw/Documents/dev/environments/copo_python3.4/lib/python3.4/site-packages/django/core/urlresolvers.py", line 619, in is_valid_path
    resolve(path, urlconf)
  File "/Users/fshaw/Documents/dev/environments/copo_python3.4/lib/python3.4/site-packages/django/core/urlresolvers.py", line 494, in resolve
    return get_resolver(urlconf).resolve(path)
  File "/Users/fshaw/Documents/dev/environments/copo_python3.4/lib/python3.4/site-packages/django/core/urlresolvers.py", line 343, in resolve
    for pattern in self.url_patterns:
  File "/Users/fshaw/Documents/dev/environments/copo_python3.4/lib/python3.4/site-packages/django/core/urlresolvers.py", line 372, in url_patterns
    patterns = getattr(self.urlconf_module, "urlpatterns", self.urlconf_module)
  File "/Users/fshaw/Documents/dev/environments/copo_python3.4/lib/python3.4/site-packages/django/core/urlresolvers.py", line 366, in urlconf_module
    self._urlconf_module = import_module(self.urlconf_name)
  File "/Users/fshaw/Documents/dev/environments/copo_python3.4/lib/python3.4/importlib/__init__.py", line 109, in import_module
    return _bootstrap._gcd_import(name[level:], package, level)
  File "<frozen importlib._bootstrap>", line 2254, in _gcd_import
  File "<frozen importlib._bootstrap>", line 2237, in _find_and_load
  File "<frozen importlib._bootstrap>", line 2226, in _find_and_load_unlocked
  File "<frozen importlib._bootstrap>", line 1200, in _load_unlocked
  File "<frozen importlib._bootstrap>", line 1129, in _exec
  File "<frozen importlib._bootstrap>", line 1471, in exec_module
  File "<frozen importlib._bootstrap>", line 321, in _call_with_frames_removed
  File "/Users/fshaw/Dropbox/tgac_dev/prototypes/COPO/web/project_copo/urls.py", line 5, in <module>
    import web_copo.views as views
  File "/Users/fshaw/Dropbox/tgac_dev/prototypes/COPO/web/apps/web_copo/views.py", line 18, in <module>
    from web.apps.web_copo.repos.aspera import AsperaTransfer
  File "/Users/fshaw/Dropbox/tgac_dev/prototypes/COPO/web/apps/web_copo/repos/aspera.py", line 11, in <module>
    from dal import ObjectId
  File "/Users/fshaw/Dropbox/tgac_dev/prototypes/COPO/dal/__init__.py", line 11, in <module>
    from .ena_da import EnaCollection
  File "/Users/fshaw/Dropbox/tgac_dev/prototypes/COPO/dal/ena_da.py", line 12, in <module>
    import dal.mongo_util as mutil
AttributeError: 'module' object has no attribute 'mongo_util'
[22/Oct/2015 16:06:43] ERROR [django.request:231] Internal Server Error: /copo/copo_publications/5616733191aaa91fc57df44a/view
Traceback (most recent call last):
  File "/Users/fshaw/Documents/dev/environments/copo_python3.4/lib/python3.4/site-packages/django/core/urlresolvers.py", line 364, in urlconf_module
    return self._urlconf_module
AttributeError: 'RegexURLResolver' object has no attribute '_urlconf_module'

During handling of the above exception, another exception occurred:

Traceback (most recent call last):
  File "/Users/fshaw/Documents/dev/environments/copo_python3.4/lib/python3.4/site-packages/django/core/handlers/base.py", line 87, in get_response
    response = middleware_method(request)
  File "/Users/fshaw/Documents/dev/environments/copo_python3.4/lib/python3.4/site-packages/django/middleware/common.py", line 72, in process_request
    if (not urlresolvers.is_valid_path(request.path_info, urlconf) and
  File "/Users/fshaw/Documents/dev/environments/copo_python3.4/lib/python3.4/site-packages/django/core/urlresolvers.py", line 619, in is_valid_path
    resolve(path, urlconf)
  File "/Users/fshaw/Documents/dev/environments/copo_python3.4/lib/python3.4/site-packages/django/core/urlresolvers.py", line 494, in resolve
    return get_resolver(urlconf).resolve(path)
  File "/Users/fshaw/Documents/dev/environments/copo_python3.4/lib/python3.4/site-packages/django/core/urlresolvers.py", line 343, in resolve
    for pattern in self.url_patterns:
  File "/Users/fshaw/Documents/dev/environments/copo_python3.4/lib/python3.4/site-packages/django/core/urlresolvers.py", line 372, in url_patterns
    patterns = getattr(self.urlconf_module, "urlpatterns", self.urlconf_module)
  File "/Users/fshaw/Documents/dev/environments/copo_python3.4/lib/python3.4/site-packages/django/core/urlresolvers.py", line 366, in urlconf_module
    self._urlconf_module = import_module(self.urlconf_name)
  File "/Users/fshaw/Documents/dev/environments/copo_python3.4/lib/python3.4/importlib/__init__.py", line 109, in import_module
    return _bootstrap._gcd_import(name[level:], package, level)
  File "<frozen importlib._bootstrap>", line 2254, in _gcd_import
  File "<frozen importlib._bootstrap>", line 2237, in _find_and_load
  File "<frozen importlib._bootstrap>", line 2226, in _find_and_load_unlocked
  File "<frozen importlib._bootstrap>", line 1200, in _load_unlocked
  File "<frozen importlib._bootstrap>", line 1129, in _exec
  File "<frozen importlib._bootstrap>", line 1471, in exec_module
  File "<frozen importlib._bootstrap>", line 321, in _call_with_frames_removed
  File "/Users/fshaw/Dropbox/tgac_dev/prototypes/COPO/web/project_copo/urls.py", line 5, in <module>
    import web_copo.views as views
  File "/Users/fshaw/Dropbox/tgac_dev/prototypes/COPO/web/apps/web_copo/views.py", line 18, in <module>
    from web.apps.web_copo.repos.aspera import AsperaTransfer
  File "/Users/fshaw/Dropbox/tgac_dev/prototypes/COPO/web/apps/web_copo/repos/aspera.py", line 11, in <module>
    from dal import ObjectId
  File "/Users/fshaw/Dropbox/tgac_dev/prototypes/COPO/dal/__init__.py", line 11, in <module>
    from .ena_da import EnaCollection
  File "/Users/fshaw/Dropbox/tgac_dev/prototypes/COPO/dal/ena_da.py", line 12, in <module>
    import dal.mongo_util as mutil
AttributeError: 'module' object has no attribute 'mongo_util'
[22/Oct/2015 16:09:56] ERROR [django.request:231] Internal Server Error: /copo/copo_publications/5616733191aaa91fc57df44a/view
Traceback (most recent call last):
  File "/Users/fshaw/Documents/dev/environments/copo_python3.4/lib/python3.4/site-packages/django/core/urlresolvers.py", line 364, in urlconf_module
    return self._urlconf_module
AttributeError: 'RegexURLResolver' object has no attribute '_urlconf_module'

During handling of the above exception, another exception occurred:

Traceback (most recent call last):
  File "/Users/fshaw/Documents/dev/environments/copo_python3.4/lib/python3.4/site-packages/django/core/handlers/base.py", line 87, in get_response
    response = middleware_method(request)
  File "/Users/fshaw/Documents/dev/environments/copo_python3.4/lib/python3.4/site-packages/django/middleware/common.py", line 72, in process_request
    if (not urlresolvers.is_valid_path(request.path_info, urlconf) and
  File "/Users/fshaw/Documents/dev/environments/copo_python3.4/lib/python3.4/site-packages/django/core/urlresolvers.py", line 619, in is_valid_path
    resolve(path, urlconf)
  File "/Users/fshaw/Documents/dev/environments/copo_python3.4/lib/python3.4/site-packages/django/core/urlresolvers.py", line 494, in resolve
    return get_resolver(urlconf).resolve(path)
  File "/Users/fshaw/Documents/dev/environments/copo_python3.4/lib/python3.4/site-packages/django/core/urlresolvers.py", line 343, in resolve
    for pattern in self.url_patterns:
  File "/Users/fshaw/Documents/dev/environments/copo_python3.4/lib/python3.4/site-packages/django/core/urlresolvers.py", line 372, in url_patterns
    patterns = getattr(self.urlconf_module, "urlpatterns", self.urlconf_module)
  File "/Users/fshaw/Documents/dev/environments/copo_python3.4/lib/python3.4/site-packages/django/core/urlresolvers.py", line 366, in urlconf_module
    self._urlconf_module = import_module(self.urlconf_name)
  File "/Users/fshaw/Documents/dev/environments/copo_python3.4/lib/python3.4/importlib/__init__.py", line 109, in import_module
    return _bootstrap._gcd_import(name[level:], package, level)
  File "<frozen importlib._bootstrap>", line 2254, in _gcd_import
  File "<frozen importlib._bootstrap>", line 2237, in _find_and_load
  File "<frozen importlib._bootstrap>", line 2226, in _find_and_load_unlocked
  File "<frozen importlib._bootstrap>", line 1200, in _load_unlocked
  File "<frozen importlib._bootstrap>", line 1129, in _exec
  File "<frozen importlib._bootstrap>", line 1471, in exec_module
  File "<frozen importlib._bootstrap>", line 321, in _call_with_frames_removed
  File "/Users/fshaw/Dropbox/tgac_dev/prototypes/COPO/web/project_copo/urls.py", line 5, in <module>
    import web_copo.views as views
  File "/Users/fshaw/Dropbox/tgac_dev/prototypes/COPO/web/apps/web_copo/views.py", line 18, in <module>
    from web.apps.web_copo.repos.aspera import AsperaTransfer
  File "/Users/fshaw/Dropbox/tgac_dev/prototypes/COPO/web/apps/web_copo/repos/aspera.py", line 11, in <module>
    from dal import ObjectId
  File "/Users/fshaw/Dropbox/tgac_dev/prototypes/COPO/dal/__init__.py", line 15, in <module>
    Profile_Status_Info, mongo_util, DataSchemas]
NameError: name 'mongo_util' is not defined
[22/Oct/2015 16:10:40] DEBUG [web_copo.views:21] ['/Users/fshaw/Dropbox/tgac_dev/prototypes/COPO/web', '/Applications/PyCharm.app/Contents/helpers/pydev', '/Users/fshaw/Dropbox/tgac_dev/prototypes/COPO', '/Users/fshaw/Documents/dev/environments/copo_python3.4/lib/python34.zip', '/Users/fshaw/Documents/dev/environments/copo_python3.4/lib/python3.4', '/Users/fshaw/Documents/dev/environments/copo_python3.4/lib/python3.4/plat-darwin', '/Users/fshaw/Documents/dev/environments/copo_python3.4/lib/python3.4/lib-dynload', '/Library/Frameworks/Python.framework/Versions/3.4/lib/python3.4', '/Library/Frameworks/Python.framework/Versions/3.4/lib/python3.4/plat-darwin', '/Users/fshaw/Documents/dev/environments/copo_python3.4/lib/python3.4/site-packages', '/Users/fshaw/Dropbox/tgac_dev/prototypes/COPO', '/Users/fshaw/Dropbox/tgac_dev/prototypes/COPO/api', '/Users/fshaw/Dropbox/tgac_dev/prototypes/COPO/dal', '/Users/fshaw/Dropbox/tgac_dev/prototypes/COPO/web/project_copo', '/Users/fshaw/Dropbox/tgac_dev/prototypes/COPO/web/project_copo/settings', '/Users/fshaw/Dropbox/tgac_dev/prototypes/COPO/web/apps', '/var/www/copo_www/COPO/', '/var/www/copo_www/COPO/api', '/var/www/copo_www/COPO/dal', '/var/www/copo_www/COPO/web/project_copo', '/var/www/copo_www/COPO/web/project_copo/settings', '/var/www/copo_www/COPO/web/apps']
[22/Oct/2015 16:10:41] ERROR [django.request:231] Internal Server Error: /copo/copo_publications/5616733191aaa91fc57df44a/view
Traceback (most recent call last):
  File "/Users/fshaw/Documents/dev/environments/copo_python3.4/lib/python3.4/site-packages/django/core/urlresolvers.py", line 364, in urlconf_module
    return self._urlconf_module
AttributeError: 'RegexURLResolver' object has no attribute '_urlconf_module'

During handling of the above exception, another exception occurred:

Traceback (most recent call last):
  File "/Users/fshaw/Documents/dev/environments/copo_python3.4/lib/python3.4/site-packages/django/core/handlers/base.py", line 87, in get_response
    response = middleware_method(request)
  File "/Users/fshaw/Documents/dev/environments/copo_python3.4/lib/python3.4/site-packages/django/middleware/common.py", line 72, in process_request
    if (not urlresolvers.is_valid_path(request.path_info, urlconf) and
  File "/Users/fshaw/Documents/dev/environments/copo_python3.4/lib/python3.4/site-packages/django/core/urlresolvers.py", line 619, in is_valid_path
    resolve(path, urlconf)
  File "/Users/fshaw/Documents/dev/environments/copo_python3.4/lib/python3.4/site-packages/django/core/urlresolvers.py", line 494, in resolve
    return get_resolver(urlconf).resolve(path)
  File "/Users/fshaw/Documents/dev/environments/copo_python3.4/lib/python3.4/site-packages/django/core/urlresolvers.py", line 343, in resolve
    for pattern in self.url_patterns:
  File "/Users/fshaw/Documents/dev/environments/copo_python3.4/lib/python3.4/site-packages/django/core/urlresolvers.py", line 372, in url_patterns
    patterns = getattr(self.urlconf_module, "urlpatterns", self.urlconf_module)
  File "/Users/fshaw/Documents/dev/environments/copo_python3.4/lib/python3.4/site-packages/django/core/urlresolvers.py", line 366, in urlconf_module
    self._urlconf_module = import_module(self.urlconf_name)
  File "/Users/fshaw/Documents/dev/environments/copo_python3.4/lib/python3.4/importlib/__init__.py", line 109, in import_module
    return _bootstrap._gcd_import(name[level:], package, level)
  File "<frozen importlib._bootstrap>", line 2254, in _gcd_import
  File "<frozen importlib._bootstrap>", line 2237, in _find_and_load
  File "<frozen importlib._bootstrap>", line 2226, in _find_and_load_unlocked
  File "<frozen importlib._bootstrap>", line 1200, in _load_unlocked
  File "<frozen importlib._bootstrap>", line 1129, in _exec
  File "<frozen importlib._bootstrap>", line 1471, in exec_module
  File "<frozen importlib._bootstrap>", line 321, in _call_with_frames_removed
  File "/Users/fshaw/Dropbox/tgac_dev/prototypes/COPO/web/project_copo/urls.py", line 5, in <module>
    import web_copo.views as views
  File "/Users/fshaw/Dropbox/tgac_dev/prototypes/COPO/web/apps/web_copo/views.py", line 30, in <module>
    from web.apps.web_copo.api.views import *
  File "/Users/fshaw/Dropbox/tgac_dev/prototypes/COPO/web/apps/web_copo/api/views.py", line 9, in <module>
    import dal.figshare_da as fs
AttributeError: 'module' object has no attribute 'figshare_da'
[22/Oct/2015 16:11:32] DEBUG [web_copo.views:21] ['/Users/fshaw/Dropbox/tgac_dev/prototypes/COPO/web', '/Applications/PyCharm.app/Contents/helpers/pydev', '/Users/fshaw/Dropbox/tgac_dev/prototypes/COPO', '/Users/fshaw/Documents/dev/environments/copo_python3.4/lib/python34.zip', '/Users/fshaw/Documents/dev/environments/copo_python3.4/lib/python3.4', '/Users/fshaw/Documents/dev/environments/copo_python3.4/lib/python3.4/plat-darwin', '/Users/fshaw/Documents/dev/environments/copo_python3.4/lib/python3.4/lib-dynload', '/Library/Frameworks/Python.framework/Versions/3.4/lib/python3.4', '/Library/Frameworks/Python.framework/Versions/3.4/lib/python3.4/plat-darwin', '/Users/fshaw/Documents/dev/environments/copo_python3.4/lib/python3.4/site-packages', '/Users/fshaw/Dropbox/tgac_dev/prototypes/COPO', '/Users/fshaw/Dropbox/tgac_dev/prototypes/COPO/api', '/Users/fshaw/Dropbox/tgac_dev/prototypes/COPO/dal', '/Users/fshaw/Dropbox/tgac_dev/prototypes/COPO/web/project_copo', '/Users/fshaw/Dropbox/tgac_dev/prototypes/COPO/web/project_copo/settings', '/Users/fshaw/Dropbox/tgac_dev/prototypes/COPO/web/apps', '/var/www/copo_www/COPO/', '/var/www/copo_www/COPO/api', '/var/www/copo_www/COPO/dal', '/var/www/copo_www/COPO/web/project_copo', '/var/www/copo_www/COPO/web/project_copo/settings', '/var/www/copo_www/COPO/web/apps']
[22/Oct/2015 16:11:32] INFO [rdflib:81] RDFLib Version: 4.2.1
[22/Oct/2015 16:11:33] DEBUG [web.apps.web_copo.views:21] ['/Users/fshaw/Dropbox/tgac_dev/prototypes/COPO/web', '/Applications/PyCharm.app/Contents/helpers/pydev', '/Users/fshaw/Dropbox/tgac_dev/prototypes/COPO', '/Users/fshaw/Documents/dev/environments/copo_python3.4/lib/python34.zip', '/Users/fshaw/Documents/dev/environments/copo_python3.4/lib/python3.4', '/Users/fshaw/Documents/dev/environments/copo_python3.4/lib/python3.4/plat-darwin', '/Users/fshaw/Documents/dev/environments/copo_python3.4/lib/python3.4/lib-dynload', '/Library/Frameworks/Python.framework/Versions/3.4/lib/python3.4', '/Library/Frameworks/Python.framework/Versions/3.4/lib/python3.4/plat-darwin', '/Users/fshaw/Documents/dev/environments/copo_python3.4/lib/python3.4/site-packages', '/Users/fshaw/Dropbox/tgac_dev/prototypes/COPO', '/Users/fshaw/Dropbox/tgac_dev/prototypes/COPO/api', '/Users/fshaw/Dropbox/tgac_dev/prototypes/COPO/dal', '/Users/fshaw/Dropbox/tgac_dev/prototypes/COPO/web/project_copo', '/Users/fshaw/Dropbox/tgac_dev/prototypes/COPO/web/project_copo/settings', '/Users/fshaw/Dropbox/tgac_dev/prototypes/COPO/web/apps', '/var/www/copo_www/COPO/', '/var/www/copo_www/COPO/api', '/var/www/copo_www/COPO/dal', '/var/www/copo_www/COPO/web/project_copo', '/var/www/copo_www/COPO/web/project_copo/settings', '/var/www/copo_www/COPO/web/apps']
[22/Oct/2015 16:12:18] ERROR [django.request:231] Internal Server Error: /copo/edit_publication/
Traceback (most recent call last):
  File "/Users/fshaw/Documents/dev/environments/copo_python3.4/lib/python3.4/site-packages/django/utils/datastructures.py", line 317, in __getitem__
    list_ = super(MultiValueDict, self).__getitem__(key)
KeyError: 'autofields'

During handling of the above exception, another exception occurred:

Traceback (most recent call last):
  File "/Users/fshaw/Documents/dev/environments/copo_python3.4/lib/python3.4/site-packages/django/core/handlers/base.py", line 111, in get_response
    response = wrapped_callback(request, *callback_args, **callback_kwargs)
  File "/Users/fshaw/Dropbox/tgac_dev/prototypes/COPO/web/apps/web_copo/views.py", line 68, in edit_publication
    Publication().save_publication(request.POST['autofields'])
  File "/Users/fshaw/Documents/dev/environments/copo_python3.4/lib/python3.4/site-packages/django/utils/datastructures.py", line 319, in __getitem__
    raise MultiValueDictKeyError(repr(key))
django.utils.datastructures.MultiValueDictKeyError: "'autofields'"
[22/Oct/2015 16:13:26] ERROR [django.request:231] Internal Server Error: /copo/edit_publication/
Traceback (most recent call last):
  File "/Users/fshaw/Documents/dev/environments/copo_python3.4/lib/python3.4/site-packages/django/utils/datastructures.py", line 317, in __getitem__
    list_ = super(MultiValueDict, self).__getitem__(key)
KeyError: 'autofields'

During handling of the above exception, another exception occurred:

Traceback (most recent call last):
  File "/Users/fshaw/Documents/dev/environments/copo_python3.4/lib/python3.4/site-packages/django/core/handlers/base.py", line 111, in get_response
    response = wrapped_callback(request, *callback_args, **callback_kwargs)
  File "/Users/fshaw/Dropbox/tgac_dev/prototypes/COPO/web/apps/web_copo/views.py", line 68, in edit_publication
    Publication().save_publication(request.POST['autofields'])
  File "/Users/fshaw/Documents/dev/environments/copo_python3.4/lib/python3.4/site-packages/django/utils/datastructures.py", line 319, in __getitem__
    raise MultiValueDictKeyError(repr(key))
django.utils.datastructures.MultiValueDictKeyError: "'autofields'"
[22/Oct/2015 16:14:08] DEBUG [web_copo.views:21] ['/Users/fshaw/Dropbox/tgac_dev/prototypes/COPO/web', '/Applications/PyCharm.app/Contents/helpers/pydev', '/Users/fshaw/Dropbox/tgac_dev/prototypes/COPO', '/Users/fshaw/Documents/dev/environments/copo_python3.4/lib/python34.zip', '/Users/fshaw/Documents/dev/environments/copo_python3.4/lib/python3.4', '/Users/fshaw/Documents/dev/environments/copo_python3.4/lib/python3.4/plat-darwin', '/Users/fshaw/Documents/dev/environments/copo_python3.4/lib/python3.4/lib-dynload', '/Library/Frameworks/Python.framework/Versions/3.4/lib/python3.4', '/Library/Frameworks/Python.framework/Versions/3.4/lib/python3.4/plat-darwin', '/Users/fshaw/Documents/dev/environments/copo_python3.4/lib/python3.4/site-packages', '/Users/fshaw/Dropbox/tgac_dev/prototypes/COPO', '/Users/fshaw/Dropbox/tgac_dev/prototypes/COPO/api', '/Users/fshaw/Dropbox/tgac_dev/prototypes/COPO/dal', '/Users/fshaw/Dropbox/tgac_dev/prototypes/COPO/web/project_copo', '/Users/fshaw/Dropbox/tgac_dev/prototypes/COPO/web/project_copo/settings', '/Users/fshaw/Dropbox/tgac_dev/prototypes/COPO/web/apps', '/var/www/copo_www/COPO/', '/var/www/copo_www/COPO/api', '/var/www/copo_www/COPO/dal', '/var/www/copo_www/COPO/web/project_copo', '/var/www/copo_www/COPO/web/project_copo/settings', '/var/www/copo_www/COPO/web/apps']
[22/Oct/2015 16:14:08] INFO [rdflib:81] RDFLib Version: 4.2.1
[22/Oct/2015 16:14:09] DEBUG [web.apps.web_copo.views:21] ['/Users/fshaw/Dropbox/tgac_dev/prototypes/COPO/web', '/Applications/PyCharm.app/Contents/helpers/pydev', '/Users/fshaw/Dropbox/tgac_dev/prototypes/COPO', '/Users/fshaw/Documents/dev/environments/copo_python3.4/lib/python34.zip', '/Users/fshaw/Documents/dev/environments/copo_python3.4/lib/python3.4', '/Users/fshaw/Documents/dev/environments/copo_python3.4/lib/python3.4/plat-darwin', '/Users/fshaw/Documents/dev/environments/copo_python3.4/lib/python3.4/lib-dynload', '/Library/Frameworks/Python.framework/Versions/3.4/lib/python3.4', '/Library/Frameworks/Python.framework/Versions/3.4/lib/python3.4/plat-darwin', '/Users/fshaw/Documents/dev/environments/copo_python3.4/lib/python3.4/site-packages', '/Users/fshaw/Dropbox/tgac_dev/prototypes/COPO', '/Users/fshaw/Dropbox/tgac_dev/prototypes/COPO/api', '/Users/fshaw/Dropbox/tgac_dev/prototypes/COPO/dal', '/Users/fshaw/Dropbox/tgac_dev/prototypes/COPO/web/project_copo', '/Users/fshaw/Dropbox/tgac_dev/prototypes/COPO/web/project_copo/settings', '/Users/fshaw/Dropbox/tgac_dev/prototypes/COPO/web/apps', '/var/www/copo_www/COPO/', '/var/www/copo_www/COPO/api', '/var/www/copo_www/COPO/dal', '/var/www/copo_www/COPO/web/project_copo', '/var/www/copo_www/COPO/web/project_copo/settings', '/var/www/copo_www/COPO/web/apps']
[22/Oct/2015 16:14:09] ERROR [django.request:231] Internal Server Error: /copo/edit_publication/
Traceback (most recent call last):
  File "/Users/fshaw/Documents/dev/environments/copo_python3.4/lib/python3.4/site-packages/django/core/handlers/base.py", line 111, in get_response
    response = wrapped_callback(request, *callback_args, **callback_kwargs)
  File "/Users/fshaw/Dropbox/tgac_dev/prototypes/COPO/web/apps/web_copo/views.py", line 68, in edit_publication
    Publication().save_publication(request.POST['auto_fields'])
  File "/Users/fshaw/Dropbox/tgac_dev/prototypes/COPO/dal/copo_da.py", line 10, in save_publication
    fields = data_utils.get_schema_fields(autofields, schema)
  File "/Users/fshaw/Dropbox/tgac_dev/prototypes/COPO/web/apps/web_copo/schemas/utils/data_utils.py", line 101, in get_schema_fields
    for f in schema.fields:
AttributeError: 'dict' object has no attribute 'fields'
[22/Oct/2015 16:14:20] ERROR [django.request:231] Internal Server Error: /copo/edit_publication/
Traceback (most recent call last):
  File "/Users/fshaw/Documents/dev/environments/copo_python3.4/lib/python3.4/site-packages/django/core/handlers/base.py", line 111, in get_response
    response = wrapped_callback(request, *callback_args, **callback_kwargs)
  File "/Users/fshaw/Dropbox/tgac_dev/prototypes/COPO/web/apps/web_copo/views.py", line 68, in edit_publication
    Publication().save_publication(request.POST['auto_fields'])
  File "/Users/fshaw/Dropbox/tgac_dev/prototypes/COPO/dal/copo_da.py", line 10, in save_publication
    fields = data_utils.get_schema_fields(autofields, schema)
  File "/Users/fshaw/Dropbox/tgac_dev/prototypes/COPO/web/apps/web_copo/schemas/utils/data_utils.py", line 101, in get_schema_fields
    for f in schema.fields:
AttributeError: 'dict' object has no attribute 'fields'
[22/Oct/2015 16:14:59] ERROR [django.request:231] Internal Server Error: /copo/edit_publication/
Traceback (most recent call last):
  File "/Users/fshaw/Documents/dev/environments/copo_python3.4/lib/python3.4/site-packages/django/core/handlers/base.py", line 111, in get_response
    response = wrapped_callback(request, *callback_args, **callback_kwargs)
  File "/Users/fshaw/Dropbox/tgac_dev/prototypes/COPO/web/apps/web_copo/views.py", line 68, in edit_publication
    Publication().save_publication(request.POST['auto_fields'])
  File "/Users/fshaw/Dropbox/tgac_dev/prototypes/COPO/dal/copo_da.py", line 10, in save_publication
    fields = data_utils.get_schema_fields(autofields, schema)
  File "/Users/fshaw/Dropbox/tgac_dev/prototypes/COPO/web/apps/web_copo/schemas/utils/data_utils.py", line 101, in get_schema_fields
    for f in schema.fields:
AttributeError: 'dict' object has no attribute 'fields'
[22/Oct/2015 16:15:15] DEBUG [web_copo.views:21] ['/Users/fshaw/Dropbox/tgac_dev/prototypes/COPO/web', '/Applications/PyCharm.app/Contents/helpers/pydev', '/Users/fshaw/Dropbox/tgac_dev/prototypes/COPO', '/Users/fshaw/Documents/dev/environments/copo_python3.4/lib/python34.zip', '/Users/fshaw/Documents/dev/environments/copo_python3.4/lib/python3.4', '/Users/fshaw/Documents/dev/environments/copo_python3.4/lib/python3.4/plat-darwin', '/Users/fshaw/Documents/dev/environments/copo_python3.4/lib/python3.4/lib-dynload', '/Library/Frameworks/Python.framework/Versions/3.4/lib/python3.4', '/Library/Frameworks/Python.framework/Versions/3.4/lib/python3.4/plat-darwin', '/Users/fshaw/Documents/dev/environments/copo_python3.4/lib/python3.4/site-packages', '/Users/fshaw/Dropbox/tgac_dev/prototypes/COPO', '/Users/fshaw/Dropbox/tgac_dev/prototypes/COPO/api', '/Users/fshaw/Dropbox/tgac_dev/prototypes/COPO/dal', '/Users/fshaw/Dropbox/tgac_dev/prototypes/COPO/web/project_copo', '/Users/fshaw/Dropbox/tgac_dev/prototypes/COPO/web/project_copo/settings', '/Users/fshaw/Dropbox/tgac_dev/prototypes/COPO/web/apps', '/var/www/copo_www/COPO/', '/var/www/copo_www/COPO/api', '/var/www/copo_www/COPO/dal', '/var/www/copo_www/COPO/web/project_copo', '/var/www/copo_www/COPO/web/project_copo/settings', '/var/www/copo_www/COPO/web/apps']
[22/Oct/2015 16:15:15] INFO [rdflib:81] RDFLib Version: 4.2.1
[22/Oct/2015 16:15:15] DEBUG [web.apps.web_copo.views:21] ['/Users/fshaw/Dropbox/tgac_dev/prototypes/COPO/web', '/Applications/PyCharm.app/Contents/helpers/pydev', '/Users/fshaw/Dropbox/tgac_dev/prototypes/COPO', '/Users/fshaw/Documents/dev/environments/copo_python3.4/lib/python34.zip', '/Users/fshaw/Documents/dev/environments/copo_python3.4/lib/python3.4', '/Users/fshaw/Documents/dev/environments/copo_python3.4/lib/python3.4/plat-darwin', '/Users/fshaw/Documents/dev/environments/copo_python3.4/lib/python3.4/lib-dynload', '/Library/Frameworks/Python.framework/Versions/3.4/lib/python3.4', '/Library/Frameworks/Python.framework/Versions/3.4/lib/python3.4/plat-darwin', '/Users/fshaw/Documents/dev/environments/copo_python3.4/lib/python3.4/site-packages', '/Users/fshaw/Dropbox/tgac_dev/prototypes/COPO', '/Users/fshaw/Dropbox/tgac_dev/prototypes/COPO/api', '/Users/fshaw/Dropbox/tgac_dev/prototypes/COPO/dal', '/Users/fshaw/Dropbox/tgac_dev/prototypes/COPO/web/project_copo', '/Users/fshaw/Dropbox/tgac_dev/prototypes/COPO/web/project_copo/settings', '/Users/fshaw/Dropbox/tgac_dev/prototypes/COPO/web/apps', '/var/www/copo_www/COPO/', '/var/www/copo_www/COPO/api', '/var/www/copo_www/COPO/dal', '/var/www/copo_www/COPO/web/project_copo', '/var/www/copo_www/COPO/web/project_copo/settings', '/var/www/copo_www/COPO/web/apps']
[22/Oct/2015 16:15:15] ERROR [django.request:231] Internal Server Error: /copo/edit_publication/
Traceback (most recent call last):
  File "/Users/fshaw/Documents/dev/environments/copo_python3.4/lib/python3.4/site-packages/django/core/handlers/base.py", line 111, in get_response
    response = wrapped_callback(request, *callback_args, **callback_kwargs)
  File "/Users/fshaw/Dropbox/tgac_dev/prototypes/COPO/web/apps/web_copo/views.py", line 68, in edit_publication
    Publication().save_publication(request.POST['auto_fields'])
  File "/Users/fshaw/Dropbox/tgac_dev/prototypes/COPO/dal/copo_da.py", line 10, in save_publication
    fields = data_utils.get_schema_fields(autofields, schema)
  File "/Users/fshaw/Dropbox/tgac_dev/prototypes/COPO/web/apps/web_copo/schemas/utils/data_utils.py", line 102, in get_schema_fields
    key_split = f.id.split(".")
AttributeError: 'dict' object has no attribute 'id'
[22/Oct/2015 16:16:56] DEBUG [web_copo.views:21] ['/Users/fshaw/Dropbox/tgac_dev/prototypes/COPO/web', '/Applications/PyCharm.app/Contents/helpers/pydev', '/Users/fshaw/Dropbox/tgac_dev/prototypes/COPO', '/Users/fshaw/Documents/dev/environments/copo_python3.4/lib/python34.zip', '/Users/fshaw/Documents/dev/environments/copo_python3.4/lib/python3.4', '/Users/fshaw/Documents/dev/environments/copo_python3.4/lib/python3.4/plat-darwin', '/Users/fshaw/Documents/dev/environments/copo_python3.4/lib/python3.4/lib-dynload', '/Library/Frameworks/Python.framework/Versions/3.4/lib/python3.4', '/Library/Frameworks/Python.framework/Versions/3.4/lib/python3.4/plat-darwin', '/Users/fshaw/Documents/dev/environments/copo_python3.4/lib/python3.4/site-packages', '/Users/fshaw/Dropbox/tgac_dev/prototypes/COPO', '/Users/fshaw/Dropbox/tgac_dev/prototypes/COPO/api', '/Users/fshaw/Dropbox/tgac_dev/prototypes/COPO/dal', '/Users/fshaw/Dropbox/tgac_dev/prototypes/COPO/web/project_copo', '/Users/fshaw/Dropbox/tgac_dev/prototypes/COPO/web/project_copo/settings', '/Users/fshaw/Dropbox/tgac_dev/prototypes/COPO/web/apps', '/var/www/copo_www/COPO/', '/var/www/copo_www/COPO/api', '/var/www/copo_www/COPO/dal', '/var/www/copo_www/COPO/web/project_copo', '/var/www/copo_www/COPO/web/project_copo/settings', '/var/www/copo_www/COPO/web/apps']
[22/Oct/2015 16:16:56] INFO [rdflib:81] RDFLib Version: 4.2.1
[22/Oct/2015 16:16:56] DEBUG [web.apps.web_copo.views:21] ['/Users/fshaw/Dropbox/tgac_dev/prototypes/COPO/web', '/Applications/PyCharm.app/Contents/helpers/pydev', '/Users/fshaw/Dropbox/tgac_dev/prototypes/COPO', '/Users/fshaw/Documents/dev/environments/copo_python3.4/lib/python34.zip', '/Users/fshaw/Documents/dev/environments/copo_python3.4/lib/python3.4', '/Users/fshaw/Documents/dev/environments/copo_python3.4/lib/python3.4/plat-darwin', '/Users/fshaw/Documents/dev/environments/copo_python3.4/lib/python3.4/lib-dynload', '/Library/Frameworks/Python.framework/Versions/3.4/lib/python3.4', '/Library/Frameworks/Python.framework/Versions/3.4/lib/python3.4/plat-darwin', '/Users/fshaw/Documents/dev/environments/copo_python3.4/lib/python3.4/site-packages', '/Users/fshaw/Dropbox/tgac_dev/prototypes/COPO', '/Users/fshaw/Dropbox/tgac_dev/prototypes/COPO/api', '/Users/fshaw/Dropbox/tgac_dev/prototypes/COPO/dal', '/Users/fshaw/Dropbox/tgac_dev/prototypes/COPO/web/project_copo', '/Users/fshaw/Dropbox/tgac_dev/prototypes/COPO/web/project_copo/settings', '/Users/fshaw/Dropbox/tgac_dev/prototypes/COPO/web/apps', '/var/www/copo_www/COPO/', '/var/www/copo_www/COPO/api', '/var/www/copo_www/COPO/dal', '/var/www/copo_www/COPO/web/project_copo', '/var/www/copo_www/COPO/web/project_copo/settings', '/var/www/copo_www/COPO/web/apps']
